# Goxel 0.11.1
# One line per voxel
# X Y Z RRGGBB
25 19 1 38281c
26 19 1 38281c
27 19 1 38281c
30 19 1 38281c
31 19 1 38281c
25 20 1 38281c
26 20 1 38281c
27 20 1 38281c
30 20 1 38281c
31 20 1 38281c
25 21 1 38281c
26 21 1 38281c
27 21 1 38281c
30 21 1 38281c
31 21 1 38281c
25 22 1 000000
26 22 1 000000
27 22 1 000000
30 22 1 000000
31 22 1 000000
25 23 1 000000
26 23 1 000000
27 23 1 000000
30 23 1 000000
31 23 1 000000
25 27 1 000000
26 27 1 000000
27 27 1 000000
30 27 1 000000
31 27 1 000000
25 28 1 000000
26 28 1 000000
27 28 1 000000
30 28 1 000000
31 28 1 000000
25 29 1 000000
26 29 1 000000
27 29 1 000000
28 29 1 000000
29 29 1 000000
30 29 1 000000
31 29 1 000000
25 30 1 000000
26 30 1 000000
27 30 1 000000
28 30 1 000000
29 30 1 000000
30 30 1 000000
31 30 1 000000
25 31 1 000000
26 31 1 000000
27 31 1 000000
28 31 1 000000
29 31 1 000000
30 31 1 000000
31 31 1 000000
25 19 2 38281c
26 19 2 38281c
27 19 2 38281c
30 19 2 38281c
31 19 2 38281c
25 20 2 38281c
26 20 2 38281c
27 20 2 38281c
30 20 2 38281c
31 20 2 38281c
25 21 2 38281c
26 21 2 38281c
27 21 2 38281c
30 21 2 38281c
31 21 2 38281c
25 22 2 000000
26 22 2 000000
27 22 2 000000
30 22 2 000000
31 22 2 000000
25 23 2 000000
26 23 2 000000
27 23 2 000000
30 23 2 000000
31 23 2 000000
25 24 2 000000
26 24 2 000000
27 24 2 000000
30 24 2 000000
31 24 2 000000
25 25 2 000000
26 25 2 000000
27 25 2 000000
30 25 2 000000
31 25 2 000000
25 26 2 000000
26 26 2 000000
27 26 2 000000
30 26 2 000000
31 26 2 000000
25 27 2 000000
26 27 2 000000
27 27 2 000000
30 27 2 000000
31 27 2 000000
25 28 2 000000
26 28 2 000000
27 28 2 000000
30 28 2 000000
31 28 2 000000
25 29 2 000000
26 29 2 000000
27 29 2 000000
28 29 2 000000
29 29 2 000000
30 29 2 000000
31 29 2 000000
25 30 2 000000
26 30 2 000000
27 30 2 000000
28 30 2 000000
29 30 2 000000
30 30 2 000000
31 30 2 000000
25 31 2 000000
26 31 2 000000
27 31 2 000000
28 31 2 000000
29 31 2 000000
30 31 2 000000
31 31 2 000000
25 19 3 38281c
26 19 3 38281c
27 19 3 38281c
30 19 3 38281c
31 19 3 38281c
25 20 3 38281c
26 20 3 38281c
27 20 3 38281c
30 20 3 38281c
31 20 3 38281c
25 21 3 38281c
26 21 3 38281c
27 21 3 38281c
30 21 3 38281c
31 21 3 38281c
25 22 3 000000
26 22 3 000000
27 22 3 000000
30 22 3 000000
31 22 3 000000
25 23 3 000000
26 23 3 000000
27 23 3 000000
30 23 3 000000
31 23 3 000000
25 24 3 000000
26 24 3 000000
27 24 3 000000
30 24 3 000000
31 24 3 000000
25 25 3 000000
26 25 3 000000
27 25 3 000000
30 25 3 000000
31 25 3 000000
25 26 3 000000
26 26 3 000000
27 26 3 000000
30 26 3 000000
31 26 3 000000
25 27 3 000000
26 27 3 000000
27 27 3 000000
30 27 3 000000
31 27 3 000000
25 28 3 000000
26 28 3 000000
27 28 3 000000
30 28 3 000000
31 28 3 000000
25 29 3 000000
26 29 3 000000
27 29 3 000000
28 29 3 000000
29 29 3 000000
30 29 3 000000
31 29 3 000000
25 30 3 000000
26 30 3 000000
27 30 3 000000
28 30 3 000000
29 30 3 000000
30 30 3 000000
31 30 3 000000
25 31 3 000000
26 31 3 000000
27 31 3 000000
28 31 3 000000
29 31 3 000000
30 31 3 000000
31 31 3 000000
25 19 4 38281c
26 19 4 38281c
27 19 4 38281c
30 19 4 38281c
31 19 4 38281c
25 20 4 38281c
26 20 4 38281c
27 20 4 38281c
30 20 4 38281c
31 20 4 38281c
25 24 4 000000
26 24 4 000000
27 24 4 000000
30 24 4 000000
31 24 4 000000
25 25 4 000000
26 25 4 000000
27 25 4 000000
30 25 4 000000
31 25 4 000000
25 26 4 000000
26 26 4 000000
27 26 4 000000
30 26 4 000000
31 26 4 000000
25 27 4 000000
26 27 4 000000
27 27 4 000000
30 27 4 000000
31 27 4 000000
25 28 4 000000
26 28 4 000000
27 28 4 000000
30 28 4 000000
31 28 4 000000
25 29 4 000000
26 29 4 000000
27 29 4 000000
28 29 4 000000
29 29 4 000000
30 29 4 000000
31 29 4 000000
25 30 4 000000
26 30 4 000000
27 30 4 000000
28 30 4 000000
29 30 4 000000
30 30 4 000000
31 30 4 000000
25 31 4 000000
26 31 4 000000
27 31 4 000000
28 31 4 000000
29 31 4 000000
30 31 4 000000
31 31 4 000000
25 19 5 38281c
26 19 5 38281c
27 19 5 38281c
30 19 5 38281c
31 19 5 38281c
25 20 5 38281c
26 20 5 38281c
27 20 5 38281c
30 20 5 38281c
31 20 5 38281c
32 19 1 38281c
32 20 1 38281c
32 21 1 38281c
32 22 1 000000
32 23 1 000000
32 27 1 000000
32 28 1 000000
32 29 1 000000
32 30 1 000000
32 31 1 000000
32 19 2 38281c
32 20 2 38281c
32 21 2 38281c
32 22 2 000000
32 23 2 000000
32 24 2 000000
32 25 2 000000
32 26 2 000000
32 27 2 000000
32 28 2 000000
32 29 2 000000
32 30 2 000000
38 30 2 d8a46c
39 30 2 d8a46c
32 31 2 000000
37 31 2 000000
38 31 2 000000
39 31 2 d8a46c
32 19 3 38281c
32 20 3 38281c
32 21 3 38281c
32 22 3 000000
32 23 3 000000
32 24 3 000000
32 25 3 000000
32 26 3 000000
32 27 3 000000
32 28 3 000000
32 29 3 000000
32 30 3 000000
38 30 3 d8a46c
39 30 3 d8a46c
32 31 3 000000
37 31 3 000000
38 31 3 000000
39 31 3 d8a46c
32 19 4 38281c
32 20 4 38281c
32 24 4 000000
32 25 4 000000
32 26 4 000000
32 27 4 000000
32 28 4 000000
32 29 4 000000
32 30 4 000000
32 31 4 000000
32 19 5 38281c
32 20 5 38281c
26 38 0 d8a46c
27 38 0 d8a46c
28 38 0 d8a46c
29 38 0 d8a46c
30 38 0 d8a46c
31 38 0 d8a46c
26 39 0 d8a46c
27 39 0 d8a46c
28 39 0 d8a46c
29 39 0 d8a46c
30 39 0 d8a46c
31 39 0 d8a46c
26 40 0 000000
27 40 0 000000
28 40 0 000000
29 40 0 000000
30 40 0 000000
31 40 0 000000
26 41 0 000000
27 41 0 000000
28 41 0 000000
29 41 0 000000
30 41 0 000000
31 41 0 000000
26 42 0 000000
27 42 0 000000
28 42 0 000000
29 42 0 000000
30 42 0 000000
31 42 0 000000
26 43 0 000000
27 43 0 000000
28 43 0 000000
29 43 0 000000
30 43 0 000000
31 43 0 000000
25 32 1 000000
26 32 1 000000
27 32 1 000000
28 32 1 000000
29 32 1 000000
30 32 1 000000
31 32 1 000000
25 33 1 000000
26 33 1 000000
27 33 1 000000
28 33 1 000000
29 33 1 000000
30 33 1 000000
31 33 1 000000
25 34 1 000000
26 34 1 000000
27 34 1 000000
28 34 1 000000
29 34 1 000000
30 34 1 000000
31 34 1 000000
25 35 1 000000
26 35 1 000000
27 35 1 000000
28 35 1 000000
29 35 1 000000
30 35 1 000000
31 35 1 000000
25 36 1 000000
26 36 1 000000
27 36 1 000000
28 36 1 000000
29 36 1 000000
30 36 1 000000
31 36 1 000000
25 37 1 000000
26 37 1 000000
27 37 1 000000
28 37 1 000000
29 37 1 000000
30 37 1 000000
31 37 1 000000
26 38 1 d8a46c
27 38 1 d8a46c
28 38 1 d8a46c
29 38 1 d8a46c
30 38 1 d8a46c
31 38 1 d8a46c
26 39 1 d8a46c
27 39 1 d8a46c
28 39 1 d8a46c
29 39 1 d8a46c
30 39 1 d8a46c
31 39 1 d8a46c
26 40 1 000000
27 40 1 080808
28 40 1 d8a46c
29 40 1 d8a46c
30 40 1 080808
31 40 1 000000
26 41 1 000000
27 41 1 000000
28 41 1 000000
29 41 1 000000
30 41 1 000000
31 41 1 000000
26 42 1 000000
27 42 1 000000
28 42 1 000000
29 42 1 000000
30 42 1 000000
31 42 1 000000
26 43 1 000000
27 43 1 000000
28 43 1 000000
29 43 1 000000
30 43 1 000000
31 43 1 000000
21 32 2 000000
25 32 2 000000
26 32 2 000000
27 32 2 000000
28 32 2 000000
29 32 2 000000
30 32 2 000000
31 32 2 000000
20 33 2 000000
21 33 2 000000
22 33 2 000000
25 33 2 000000
26 33 2 000000
27 33 2 000000
28 33 2 000000
29 33 2 000000
30 33 2 000000
31 33 2 000000
19 34 2 000000
20 34 2 000000
21 34 2 000000
22 34 2 000000
23 34 2 000000
25 34 2 000000
26 34 2 000000
27 34 2 000000
28 34 2 000000
29 34 2 000000
30 34 2 000000
31 34 2 000000
18 35 2 000000
19 35 2 000000
20 35 2 000000
22 35 2 000000
23 35 2 000000
24 35 2 000000
25 35 2 000000
26 35 2 000000
27 35 2 000000
28 35 2 000000
29 35 2 000000
30 35 2 000000
31 35 2 000000
17 36 2 d8a46c
18 36 2 000000
19 36 2 000000
23 36 2 000000
24 36 2 000000
25 36 2 000000
26 36 2 000000
27 36 2 000000
28 36 2 000000
29 36 2 000000
30 36 2 000000
31 36 2 000000
17 37 2 d8a46c
18 37 2 d8a46c
25 37 2 000000
26 37 2 000000
27 37 2 000000
28 37 2 000000
29 37 2 000000
30 37 2 000000
31 37 2 000000
26 38 2 d8a46c
27 38 2 d8a46c
28 38 2 d8a46c
29 38 2 d8a46c
30 38 2 d8a46c
31 38 2 d8a46c
26 39 2 d8a46c
27 39 2 d8a46c
28 39 2 d8a46c
29 39 2 d8a46c
30 39 2 d8a46c
31 39 2 d8a46c
26 40 2 000000
27 40 2 080808
28 40 2 d8a46c
29 40 2 d8a46c
30 40 2 080808
31 40 2 000000
26 41 2 000000
27 41 2 000000
28 41 2 000000
29 41 2 000000
30 41 2 000000
31 41 2 000000
26 42 2 000000
27 42 2 000000
28 42 2 000000
29 42 2 000000
30 42 2 000000
31 42 2 000000
26 43 2 000000
27 43 2 000000
28 43 2 000000
29 43 2 000000
30 43 2 000000
31 43 2 000000
21 32 3 000000
25 32 3 000000
26 32 3 000000
27 32 3 000000
28 32 3 000000
29 32 3 000000
30 32 3 000000
31 32 3 000000
20 33 3 000000
21 33 3 000000
22 33 3 000000
25 33 3 000000
26 33 3 000000
27 33 3 000000
28 33 3 000000
29 33 3 000000
30 33 3 000000
31 33 3 000000
19 34 3 000000
20 34 3 000000
21 34 3 000000
22 34 3 000000
23 34 3 000000
25 34 3 000000
26 34 3 000000
27 34 3 000000
28 34 3 000000
29 34 3 000000
30 34 3 000000
31 34 3 000000
18 35 3 000000
19 35 3 000000
20 35 3 000000
22 35 3 000000
23 35 3 000000
24 35 3 000000
25 35 3 000000
26 35 3 000000
27 35 3 000000
28 35 3 000000
29 35 3 000000
30 35 3 000000
31 35 3 000000
17 36 3 d8a46c
18 36 3 000000
19 36 3 000000
23 36 3 000000
24 36 3 000000
25 36 3 000000
26 36 3 000000
27 36 3 000000
28 36 3 000000
29 36 3 000000
30 36 3 000000
31 36 3 000000
17 37 3 d8a46c
18 37 3 d8a46c
25 37 3 000000
26 37 3 000000
27 37 3 000000
28 37 3 000000
29 37 3 000000
30 37 3 000000
31 37 3 000000
26 38 3 080808
27 38 3 d8a46c
28 38 3 d8a46c
29 38 3 d8a46c
30 38 3 d8a46c
31 38 3 080808
26 39 3 080808
27 39 3 d8a46c
28 39 3 d8a46c
29 39 3 d8a46c
30 39 3 d8a46c
31 39 3 080808
26 40 3 080808
27 40 3 080808
28 40 3 d8a46c
29 40 3 d8a46c
30 40 3 080808
31 40 3 080808
26 41 3 000000
27 41 3 000000
28 41 3 000000
29 41 3 000000
30 41 3 000000
31 41 3 000000
26 42 3 000000
27 42 3 000000
28 42 3 000000
29 42 3 000000
30 42 3 000000
31 42 3 000000
26 43 3 000000
27 43 3 000000
28 43 3 000000
29 43 3 000000
30 43 3 000000
31 43 3 000000
25 32 4 000000
26 32 4 000000
27 32 4 000000
28 32 4 000000
29 32 4 000000
30 32 4 000000
31 32 4 000000
25 33 4 000000
26 33 4 000000
27 33 4 000000
28 33 4 000000
29 33 4 000000
30 33 4 000000
31 33 4 000000
25 34 4 000000
26 34 4 000000
27 34 4 000000
28 34 4 000000
29 34 4 000000
30 34 4 000000
31 34 4 000000
25 35 4 000000
26 35 4 000000
27 35 4 000000
28 35 4 000000
29 35 4 000000
30 35 4 000000
31 35 4 000000
25 36 4 000000
26 36 4 000000
27 36 4 000000
28 36 4 000000
29 36 4 000000
30 36 4 000000
31 36 4 000000
25 37 4 000000
26 37 4 000000
27 37 4 000000
28 37 4 000000
29 37 4 000000
30 37 4 000000
31 37 4 000000
26 38 4 d8a46c
27 38 4 d8a46c
28 38 4 d8a46c
29 38 4 d8a46c
30 38 4 d8a46c
31 38 4 d8a46c
26 39 4 d8a46c
27 39 4 d8a46c
28 39 4 d8a46c
29 39 4 d8a46c
30 39 4 d8a46c
31 39 4 d8a46c
26 40 4 d8a46c
27 40 4 080808
28 40 4 d8a46c
29 40 4 d8a46c
30 40 4 080808
31 40 4 d8a46c
26 41 4 000000
27 41 4 000000
28 41 4 000000
29 41 4 000000
30 41 4 000000
31 41 4 000000
26 42 4 000000
27 42 4 000000
28 42 4 000000
29 42 4 000000
30 42 4 000000
31 42 4 000000
26 43 4 000000
27 43 4 000000
28 43 4 000000
29 43 4 000000
30 43 4 000000
31 43 4 000000
26 38 5 d8a46c
27 38 5 d8a46c
28 38 5 d8a46c
29 38 5 d8a46c
30 38 5 d8a46c
31 38 5 d8a46c
26 39 5 d8a46c
27 39 5 d8a46c
28 39 5 d8a46c
29 39 5 d8a46c
30 39 5 d8a46c
31 39 5 d8a46c
26 40 5 d8a46c
27 40 5 080808
28 40 5 d8a46c
29 40 5 d8a46c
30 40 5 080808
31 40 5 d8a46c
26 41 5 000000
27 41 5 000000
28 41 5 000000
29 41 5 000000
30 41 5 000000
31 41 5 000000
26 42 5 000000
27 42 5 000000
28 42 5 000000
29 42 5 000000
30 42 5 000000
31 42 5 000000
26 43 5 000000
27 43 5 000000
28 43 5 000000
29 43 5 000000
30 43 5 000000
31 43 5 000000
32 32 1 000000
32 33 1 000000
32 34 1 000000
32 35 1 000000
32 36 1 000000
32 37 1 000000
32 32 2 000000
36 32 2 000000
37 32 2 000000
38 32 2 000000
32 33 2 000000
35 33 2 000000
36 33 2 000000
37 33 2 000000
32 34 2 000000
34 34 2 000000
35 34 2 000000
36 34 2 000000
32 35 2 000000
33 35 2 000000
34 35 2 000000
35 35 2 000000
32 36 2 000000
33 36 2 000000
34 36 2 000000
32 37 2 000000
32 32 3 000000
36 32 3 000000
37 32 3 000000
38 32 3 000000
32 33 3 000000
35 33 3 000000
36 33 3 000000
37 33 3 000000
32 34 3 000000
34 34 3 000000
35 34 3 000000
36 34 3 000000
32 35 3 000000
33 35 3 000000
34 35 3 000000
35 35 3 000000
32 36 3 000000
33 36 3 000000
34 36 3 000000
32 37 3 000000
32 32 4 000000
32 33 4 000000
32 34 4 000000
32 35 4 000000
32 36 4 000000
32 37 4 000000
