# Goxel 0.11.1
# One line per voxel
# X Y Z RRGGBB
0 0 0 ffffff
1 0 0 ffffff
2 0 0 ffffff
3 0 0 ffffff
4 0 0 ffffff
5 0 0 ffffff
6 0 0 ffffff
7 0 0 ffffff
8 0 0 ffffff
9 0 0 ffffff
10 0 0 ffffff
11 0 0 ffffff
12 0 0 ffffff
13 0 0 ffffff
14 0 0 ffffff
15 0 0 ffffff
0 1 0 ffffff
1 1 0 ffffff
2 1 0 ffffff
3 1 0 ffffff
4 1 0 ffffff
5 1 0 ffffff
6 1 0 ffffff
7 1 0 ffffff
8 1 0 ffffff
9 1 0 ffffff
10 1 0 ffffff
11 1 0 ffffff
12 1 0 ffffff
13 1 0 ffffff
14 1 0 ffffff
15 1 0 ffffff
0 2 0 ffffff
1 2 0 ffffff
2 2 0 ffffff
3 2 0 ffffff
4 2 0 ffffff
5 2 0 ffffff
6 2 0 ffffff
7 2 0 ffffff
8 2 0 ffffff
9 2 0 ffffff
10 2 0 ffffff
11 2 0 ffffff
12 2 0 ffffff
13 2 0 ffffff
14 2 0 ffffff
15 2 0 ffffff
0 3 0 ffffff
1 3 0 ffffff
2 3 0 ffffff
3 3 0 ffffff
4 3 0 ffffff
5 3 0 ffffff
6 3 0 ffffff
7 3 0 ffffff
8 3 0 ffffff
9 3 0 ffffff
10 3 0 ffffff
11 3 0 ffffff
12 3 0 ffffff
13 3 0 ffffff
14 3 0 ffffff
15 3 0 ffffff
0 4 0 ffffff
1 4 0 ffffff
2 4 0 ffffff
3 4 0 ffffff
4 4 0 ffffff
5 4 0 ffffff
6 4 0 ffffff
7 4 0 ffffff
8 4 0 ffffff
9 4 0 ffffff
10 4 0 ffffff
11 4 0 ffffff
12 4 0 ffffff
13 4 0 ffffff
14 4 0 ffffff
15 4 0 ffffff
0 5 0 ffffff
1 5 0 ffffff
2 5 0 ffffff
3 5 0 ffffff
4 5 0 ffffff
5 5 0 ffffff
6 5 0 ffffff
7 5 0 ffffff
8 5 0 ffffff
9 5 0 ffffff
10 5 0 ffffff
11 5 0 ffffff
12 5 0 ffffff
13 5 0 ffffff
14 5 0 ffffff
15 5 0 ffffff
0 6 0 ffffff
1 6 0 ffffff
2 6 0 ffffff
3 6 0 ffffff
4 6 0 ffffff
5 6 0 ffffff
6 6 0 ffffff
7 6 0 ffffff
8 6 0 ffffff
9 6 0 ffffff
10 6 0 ffffff
11 6 0 ffffff
12 6 0 ffffff
13 6 0 ffffff
14 6 0 ffffff
15 6 0 ffffff
0 7 0 ffffff
1 7 0 ffffff
2 7 0 ffffff
3 7 0 ffffff
4 7 0 ffffff
5 7 0 ffffff
6 7 0 ffffff
7 7 0 ffffff
8 7 0 ffffff
9 7 0 ffffff
10 7 0 ffffff
11 7 0 ffffff
12 7 0 ffffff
13 7 0 ffffff
14 7 0 ffffff
15 7 0 ffffff
0 8 0 ffffff
1 8 0 ffffff
2 8 0 ffffff
3 8 0 ffffff
4 8 0 ffffff
5 8 0 ffffff
6 8 0 ffffff
7 8 0 ffffff
8 8 0 ffffff
9 8 0 ffffff
10 8 0 ffffff
11 8 0 ffffff
12 8 0 ffffff
13 8 0 ffffff
14 8 0 ffffff
15 8 0 ffffff
0 9 0 ffffff
1 9 0 ffffff
2 9 0 ffffff
3 9 0 ffffff
4 9 0 ffffff
5 9 0 ffffff
6 9 0 ffffff
7 9 0 ffffff
8 9 0 ffffff
9 9 0 ffffff
10 9 0 ffffff
11 9 0 ffffff
12 9 0 ffffff
13 9 0 ffffff
14 9 0 ffffff
15 9 0 ffffff
0 10 0 ffffff
1 10 0 ffffff
2 10 0 ffffff
3 10 0 ffffff
4 10 0 ffffff
5 10 0 ffffff
6 10 0 ffffff
7 10 0 ffffff
8 10 0 ffffff
9 10 0 ffffff
10 10 0 ffffff
11 10 0 ffffff
12 10 0 ffffff
13 10 0 ffffff
14 10 0 ffffff
15 10 0 ffffff
0 11 0 ffffff
1 11 0 ffffff
2 11 0 ffffff
3 11 0 ffffff
4 11 0 ffffff
5 11 0 ffffff
6 11 0 ffffff
7 11 0 ffffff
8 11 0 ffffff
9 11 0 ffffff
10 11 0 ffffff
11 11 0 ffffff
12 11 0 ffffff
13 11 0 ffffff
14 11 0 ffffff
15 11 0 ffffff
0 12 0 ffffff
1 12 0 ffffff
2 12 0 ffffff
3 12 0 ffffff
4 12 0 ffffff
5 12 0 ffffff
6 12 0 ffffff
7 12 0 ffffff
8 12 0 ffffff
9 12 0 ffffff
10 12 0 ffffff
11 12 0 ffffff
12 12 0 ffffff
13 12 0 ffffff
14 12 0 ffffff
15 12 0 ffffff
0 13 0 ffffff
1 13 0 ffffff
2 13 0 ffffff
3 13 0 ffffff
4 13 0 ffffff
5 13 0 ffffff
6 13 0 ffffff
7 13 0 ffffff
8 13 0 ffffff
9 13 0 ffffff
10 13 0 ffffff
11 13 0 ffffff
12 13 0 ffffff
13 13 0 ffffff
14 13 0 ffffff
15 13 0 ffffff
0 14 0 ffffff
1 14 0 ffffff
2 14 0 ffffff
3 14 0 ffffff
4 14 0 ffffff
5 14 0 ffffff
6 14 0 ffffff
7 14 0 ffffff
8 14 0 ffffff
9 14 0 ffffff
10 14 0 ffffff
11 14 0 ffffff
12 14 0 ffffff
13 14 0 ffffff
14 14 0 ffffff
15 14 0 ffffff
0 15 0 ffffff
1 15 0 ffffff
2 15 0 ffffff
3 15 0 ffffff
4 15 0 ffffff
5 15 0 ffffff
6 15 0 ffffff
7 15 0 ffffff
8 15 0 ffffff
9 15 0 ffffff
10 15 0 ffffff
11 15 0 ffffff
12 15 0 ffffff
13 15 0 ffffff
14 15 0 ffffff
15 15 0 ffffff
0 0 1 ffffff
1 0 1 ffffff
2 0 1 ffffff
3 0 1 ffffff
4 0 1 ffffff
5 0 1 ffffff
6 0 1 ffffff
7 0 1 ffffff
8 0 1 ffffff
9 0 1 ffffff
10 0 1 ffffff
11 0 1 ffffff
12 0 1 ffffff
13 0 1 ffffff
14 0 1 ffffff
15 0 1 ffffff
0 1 1 ffffff
1 1 1 ffffff
2 1 1 ffffff
3 1 1 ffffff
4 1 1 ffffff
5 1 1 ffffff
6 1 1 ffffff
7 1 1 ffffff
8 1 1 ffffff
9 1 1 ffffff
10 1 1 ffffff
11 1 1 ffffff
12 1 1 ffffff
13 1 1 ffffff
14 1 1 ffffff
15 1 1 ffffff
0 2 1 ffffff
1 2 1 ffffff
2 2 1 ffffff
3 2 1 ffffff
4 2 1 ffffff
5 2 1 ffffff
6 2 1 ffffff
7 2 1 ffffff
8 2 1 ffffff
9 2 1 ffffff
10 2 1 ffffff
11 2 1 ffffff
12 2 1 ffffff
13 2 1 ffffff
14 2 1 ffffff
15 2 1 ffffff
0 3 1 ffffff
1 3 1 ffffff
2 3 1 ffffff
3 3 1 ffffff
4 3 1 ffffff
5 3 1 ffffff
6 3 1 ffffff
7 3 1 ffffff
8 3 1 ffffff
9 3 1 ffffff
10 3 1 ffffff
11 3 1 ffffff
12 3 1 ffffff
13 3 1 ffffff
14 3 1 ffffff
15 3 1 ffffff
0 4 1 ffffff
1 4 1 ffffff
2 4 1 ffffff
3 4 1 ffffff
4 4 1 ffffff
5 4 1 ffffff
6 4 1 ffffff
7 4 1 ffffff
8 4 1 ffffff
9 4 1 ffffff
10 4 1 ffffff
11 4 1 ffffff
12 4 1 ffffff
13 4 1 ffffff
14 4 1 ffffff
15 4 1 ffffff
0 5 1 ffffff
1 5 1 ffffff
2 5 1 ffffff
3 5 1 ffffff
4 5 1 ffffff
5 5 1 ffffff
6 5 1 ffffff
7 5 1 ffffff
8 5 1 ffffff
9 5 1 ffffff
10 5 1 ffffff
11 5 1 ffffff
12 5 1 ffffff
13 5 1 ffffff
14 5 1 ffffff
15 5 1 ffffff
0 6 1 ffffff
1 6 1 ffffff
2 6 1 ffffff
3 6 1 ffffff
4 6 1 ffffff
5 6 1 ffffff
6 6 1 ffffff
7 6 1 ffffff
8 6 1 ffffff
9 6 1 ffffff
10 6 1 ffffff
11 6 1 ffffff
12 6 1 ffffff
13 6 1 ffffff
14 6 1 ffffff
15 6 1 ffffff
0 7 1 ffffff
1 7 1 ffffff
2 7 1 ffffff
3 7 1 ffffff
4 7 1 ffffff
5 7 1 ffffff
6 7 1 ffffff
7 7 1 ffffff
8 7 1 ffffff
9 7 1 ffffff
10 7 1 ffffff
11 7 1 ffffff
12 7 1 ffffff
13 7 1 ffffff
14 7 1 ffffff
15 7 1 ffffff
0 8 1 ffffff
1 8 1 ffffff
2 8 1 ffffff
3 8 1 ffffff
4 8 1 ffffff
5 8 1 ffffff
6 8 1 ffffff
7 8 1 ffffff
8 8 1 ffffff
9 8 1 ffffff
10 8 1 ffffff
11 8 1 ffffff
12 8 1 ffffff
13 8 1 ffffff
14 8 1 ffffff
15 8 1 ffffff
0 9 1 ffffff
1 9 1 ffffff
2 9 1 ffffff
3 9 1 ffffff
4 9 1 ffffff
5 9 1 ffffff
6 9 1 ffffff
7 9 1 ffffff
8 9 1 ffffff
9 9 1 ffffff
10 9 1 ffffff
11 9 1 ffffff
12 9 1 ffffff
13 9 1 ffffff
14 9 1 ffffff
15 9 1 ffffff
0 10 1 ffffff
1 10 1 ffffff
2 10 1 ffffff
3 10 1 ffffff
4 10 1 ffffff
5 10 1 ffffff
6 10 1 ffffff
7 10 1 ffffff
8 10 1 ffffff
9 10 1 ffffff
10 10 1 ffffff
11 10 1 ffffff
12 10 1 ffffff
13 10 1 ffffff
14 10 1 ffffff
15 10 1 ffffff
0 11 1 ffffff
1 11 1 ffffff
2 11 1 ffffff
3 11 1 ffffff
4 11 1 ffffff
5 11 1 ffffff
6 11 1 ffffff
7 11 1 ffffff
8 11 1 ffffff
9 11 1 ffffff
10 11 1 ffffff
11 11 1 ffffff
12 11 1 ffffff
13 11 1 ffffff
14 11 1 ffffff
15 11 1 ffffff
0 12 1 ffffff
1 12 1 ffffff
2 12 1 ffffff
3 12 1 ffffff
4 12 1 ffffff
5 12 1 ffffff
6 12 1 ffffff
7 12 1 ffffff
8 12 1 ffffff
9 12 1 ffffff
10 12 1 ffffff
11 12 1 ffffff
12 12 1 ffffff
13 12 1 ffffff
14 12 1 ffffff
15 12 1 ffffff
0 13 1 ffffff
1 13 1 ffffff
2 13 1 ffffff
3 13 1 ffffff
4 13 1 ffffff
5 13 1 ffffff
6 13 1 ffffff
7 13 1 ffffff
8 13 1 ffffff
9 13 1 ffffff
10 13 1 ffffff
11 13 1 ffffff
12 13 1 ffffff
13 13 1 ffffff
14 13 1 ffffff
15 13 1 ffffff
0 14 1 ffffff
1 14 1 ffffff
2 14 1 ffffff
3 14 1 ffffff
4 14 1 ffffff
5 14 1 ffffff
6 14 1 ffffff
7 14 1 ffffff
8 14 1 ffffff
9 14 1 ffffff
10 14 1 ffffff
11 14 1 ffffff
12 14 1 ffffff
13 14 1 ffffff
14 14 1 ffffff
15 14 1 ffffff
0 15 1 ffffff
1 15 1 ffffff
2 15 1 ffffff
3 15 1 ffffff
4 15 1 ffffff
5 15 1 ffffff
6 15 1 ffffff
7 15 1 ffffff
8 15 1 ffffff
9 15 1 ffffff
10 15 1 ffffff
11 15 1 ffffff
12 15 1 ffffff
13 15 1 ffffff
14 15 1 ffffff
15 15 1 ffffff
0 0 2 ffffff
1 0 2 ffffff
2 0 2 ffffff
3 0 2 ffffff
4 0 2 ffffff
5 0 2 ffffff
6 0 2 ffffff
7 0 2 ffffff
8 0 2 ffffff
9 0 2 ffffff
10 0 2 ffffff
11 0 2 ffffff
12 0 2 ffffff
13 0 2 ffffff
14 0 2 ffffff
15 0 2 ffffff
0 1 2 ffffff
1 1 2 ffffff
2 1 2 ffffff
3 1 2 ffffff
4 1 2 ffffff
5 1 2 ffffff
6 1 2 ffffff
7 1 2 ffffff
8 1 2 ffffff
9 1 2 ffffff
10 1 2 ffffff
11 1 2 ffffff
12 1 2 ffffff
13 1 2 ffffff
14 1 2 ffffff
15 1 2 ffffff
0 2 2 ffffff
1 2 2 ffffff
2 2 2 ffffff
3 2 2 ffffff
4 2 2 ffffff
5 2 2 ffffff
6 2 2 ffffff
7 2 2 ffffff
8 2 2 ffffff
9 2 2 ffffff
10 2 2 ffffff
11 2 2 ffffff
12 2 2 ffffff
13 2 2 ffffff
14 2 2 ffffff
15 2 2 ffffff
0 3 2 ffffff
1 3 2 ffffff
2 3 2 ffffff
3 3 2 ffffff
4 3 2 ffffff
5 3 2 ffffff
6 3 2 ffffff
7 3 2 ffffff
8 3 2 ffffff
9 3 2 ffffff
10 3 2 ffffff
11 3 2 ffffff
12 3 2 ffffff
13 3 2 ffffff
14 3 2 ffffff
15 3 2 ffffff
0 4 2 ffffff
1 4 2 ffffff
2 4 2 ffffff
3 4 2 ffffff
4 4 2 ffffff
5 4 2 ffffff
6 4 2 ffffff
7 4 2 ffffff
8 4 2 ffffff
9 4 2 ffffff
10 4 2 ffffff
11 4 2 ffffff
12 4 2 ffffff
13 4 2 ffffff
14 4 2 ffffff
15 4 2 ffffff
0 5 2 ffffff
1 5 2 ffffff
2 5 2 ffffff
3 5 2 ffffff
4 5 2 ffffff
5 5 2 ffffff
6 5 2 ffffff
7 5 2 ffffff
8 5 2 ffffff
9 5 2 ffffff
10 5 2 ffffff
11 5 2 ffffff
12 5 2 ffffff
13 5 2 ffffff
14 5 2 ffffff
15 5 2 ffffff
0 6 2 ffffff
1 6 2 ffffff
2 6 2 ffffff
3 6 2 ffffff
4 6 2 ffffff
5 6 2 ffffff
6 6 2 ffffff
7 6 2 ffffff
8 6 2 ffffff
9 6 2 ffffff
10 6 2 ffffff
11 6 2 ffffff
12 6 2 ffffff
13 6 2 ffffff
14 6 2 ffffff
15 6 2 ffffff
0 7 2 ffffff
1 7 2 ffffff
2 7 2 ffffff
3 7 2 ffffff
4 7 2 ffffff
5 7 2 ffffff
6 7 2 ffffff
7 7 2 ffffff
8 7 2 ffffff
9 7 2 ffffff
10 7 2 ffffff
11 7 2 ffffff
12 7 2 ffffff
13 7 2 ffffff
14 7 2 ffffff
15 7 2 ffffff
0 8 2 ffffff
1 8 2 ffffff
2 8 2 ffffff
3 8 2 ffffff
4 8 2 ffffff
5 8 2 ffffff
6 8 2 ffffff
7 8 2 ffffff
8 8 2 ffffff
9 8 2 ffffff
10 8 2 ffffff
11 8 2 ffffff
12 8 2 ffffff
13 8 2 ffffff
14 8 2 ffffff
15 8 2 ffffff
0 9 2 ffffff
1 9 2 ffffff
2 9 2 ffffff
3 9 2 ffffff
4 9 2 ffffff
5 9 2 ffffff
6 9 2 ffffff
7 9 2 ffffff
8 9 2 ffffff
9 9 2 ffffff
10 9 2 ffffff
11 9 2 ffffff
12 9 2 ffffff
13 9 2 ffffff
14 9 2 ffffff
15 9 2 ffffff
0 10 2 ffffff
1 10 2 ffffff
2 10 2 ffffff
3 10 2 ffffff
4 10 2 ffffff
5 10 2 ffffff
6 10 2 ffffff
7 10 2 ffffff
8 10 2 ffffff
9 10 2 ffffff
10 10 2 ffffff
11 10 2 ffffff
12 10 2 ffffff
13 10 2 ffffff
14 10 2 ffffff
15 10 2 ffffff
0 11 2 ffffff
1 11 2 ffffff
2 11 2 ffffff
3 11 2 ffffff
4 11 2 ffffff
5 11 2 ffffff
6 11 2 ffffff
7 11 2 ffffff
8 11 2 ffffff
9 11 2 ffffff
10 11 2 ffffff
11 11 2 ffffff
12 11 2 ffffff
13 11 2 ffffff
14 11 2 ffffff
15 11 2 ffffff
0 12 2 ffffff
1 12 2 ffffff
2 12 2 ffffff
3 12 2 ffffff
4 12 2 ffffff
5 12 2 ffffff
6 12 2 ffffff
7 12 2 ffffff
8 12 2 ffffff
9 12 2 ffffff
10 12 2 ffffff
11 12 2 ffffff
12 12 2 ffffff
13 12 2 ffffff
14 12 2 ffffff
15 12 2 ffffff
0 13 2 ffffff
1 13 2 ffffff
2 13 2 ffffff
3 13 2 ffffff
4 13 2 ffffff
5 13 2 ffffff
6 13 2 ffffff
7 13 2 ffffff
8 13 2 ffffff
9 13 2 ffffff
10 13 2 ffffff
11 13 2 ffffff
12 13 2 ffffff
13 13 2 ffffff
14 13 2 ffffff
15 13 2 ffffff
0 14 2 ffffff
1 14 2 ffffff
2 14 2 ffffff
3 14 2 ffffff
4 14 2 ffffff
5 14 2 ffffff
6 14 2 ffffff
7 14 2 ffffff
8 14 2 ffffff
9 14 2 ffffff
10 14 2 ffffff
11 14 2 ffffff
12 14 2 ffffff
13 14 2 ffffff
14 14 2 ffffff
15 14 2 ffffff
0 15 2 ffffff
1 15 2 ffffff
2 15 2 ffffff
3 15 2 ffffff
4 15 2 ffffff
5 15 2 ffffff
6 15 2 ffffff
7 15 2 ffffff
8 15 2 ffffff
9 15 2 ffffff
10 15 2 ffffff
11 15 2 ffffff
12 15 2 ffffff
13 15 2 ffffff
14 15 2 ffffff
15 15 2 ffffff
0 0 3 ffffff
1 0 3 ffffff
2 0 3 ffffff
3 0 3 ffffff
4 0 3 ffffff
5 0 3 ffffff
6 0 3 ffffff
7 0 3 ffffff
8 0 3 ffffff
9 0 3 ffffff
10 0 3 ffffff
11 0 3 ffffff
12 0 3 ffffff
13 0 3 ffffff
14 0 3 ffffff
15 0 3 ffffff
0 1 3 ffffff
1 1 3 ffffff
2 1 3 ffffff
3 1 3 ffffff
4 1 3 ffffff
5 1 3 ffffff
6 1 3 ffffff
7 1 3 ffffff
8 1 3 ffffff
9 1 3 ffffff
10 1 3 ffffff
11 1 3 ffffff
12 1 3 ffffff
13 1 3 ffffff
14 1 3 ffffff
15 1 3 ffffff
0 2 3 ffffff
1 2 3 ffffff
2 2 3 ffffff
3 2 3 ffffff
4 2 3 ffffff
5 2 3 ffffff
6 2 3 ffffff
7 2 3 ffffff
8 2 3 ffffff
9 2 3 ffffff
10 2 3 ffffff
11 2 3 ffffff
12 2 3 ffffff
13 2 3 ffffff
14 2 3 ffffff
15 2 3 ffffff
0 3 3 ffffff
1 3 3 ffffff
2 3 3 ffffff
3 3 3 ffffff
4 3 3 ffffff
5 3 3 ffffff
6 3 3 ffffff
7 3 3 ffffff
8 3 3 ffffff
9 3 3 ffffff
10 3 3 ffffff
11 3 3 ffffff
12 3 3 ffffff
13 3 3 ffffff
14 3 3 ffffff
15 3 3 ffffff
0 4 3 ffffff
1 4 3 ffffff
2 4 3 ffffff
3 4 3 ffffff
4 4 3 ffffff
5 4 3 ffffff
6 4 3 ffffff
7 4 3 ffffff
8 4 3 ffffff
9 4 3 ffffff
10 4 3 ffffff
11 4 3 ffffff
12 4 3 ffffff
13 4 3 ffffff
14 4 3 ffffff
15 4 3 ffffff
0 5 3 ffffff
1 5 3 ffffff
2 5 3 ffffff
3 5 3 ffffff
4 5 3 ffffff
5 5 3 ffffff
6 5 3 ffffff
7 5 3 ffffff
8 5 3 ffffff
9 5 3 ffffff
10 5 3 ffffff
11 5 3 ffffff
12 5 3 ffffff
13 5 3 ffffff
14 5 3 ffffff
15 5 3 ffffff
0 6 3 ffffff
1 6 3 ffffff
2 6 3 ffffff
3 6 3 ffffff
4 6 3 ffffff
5 6 3 ffffff
6 6 3 ffffff
7 6 3 ffffff
8 6 3 ffffff
9 6 3 ffffff
10 6 3 ffffff
11 6 3 ffffff
12 6 3 ffffff
13 6 3 ffffff
14 6 3 ffffff
15 6 3 ffffff
0 7 3 ffffff
1 7 3 ffffff
2 7 3 ffffff
3 7 3 ffffff
4 7 3 ffffff
5 7 3 ffffff
6 7 3 ffffff
7 7 3 ffffff
8 7 3 ffffff
9 7 3 ffffff
10 7 3 ffffff
11 7 3 ffffff
12 7 3 ffffff
13 7 3 ffffff
14 7 3 ffffff
15 7 3 ffffff
0 8 3 ffffff
1 8 3 ffffff
2 8 3 ffffff
3 8 3 ffffff
4 8 3 ffffff
5 8 3 ffffff
6 8 3 ffffff
7 8 3 ffffff
8 8 3 ffffff
9 8 3 ffffff
10 8 3 ffffff
11 8 3 ffffff
12 8 3 ffffff
13 8 3 ffffff
14 8 3 ffffff
15 8 3 ffffff
0 9 3 ffffff
1 9 3 ffffff
2 9 3 ffffff
3 9 3 ffffff
4 9 3 ffffff
5 9 3 ffffff
6 9 3 ffffff
7 9 3 ffffff
8 9 3 ffffff
9 9 3 ffffff
10 9 3 ffffff
11 9 3 ffffff
12 9 3 ffffff
13 9 3 ffffff
14 9 3 ffffff
15 9 3 ffffff
0 10 3 ffffff
1 10 3 ffffff
2 10 3 ffffff
3 10 3 ffffff
4 10 3 ffffff
5 10 3 ffffff
6 10 3 ffffff
7 10 3 ffffff
8 10 3 ffffff
9 10 3 ffffff
10 10 3 ffffff
11 10 3 ffffff
12 10 3 ffffff
13 10 3 ffffff
14 10 3 ffffff
15 10 3 ffffff
0 11 3 ffffff
1 11 3 ffffff
2 11 3 ffffff
3 11 3 ffffff
4 11 3 ffffff
5 11 3 ffffff
6 11 3 ffffff
7 11 3 ffffff
8 11 3 ffffff
9 11 3 ffffff
10 11 3 ffffff
11 11 3 ffffff
12 11 3 ffffff
13 11 3 ffffff
14 11 3 ffffff
15 11 3 ffffff
0 12 3 ffffff
1 12 3 ffffff
2 12 3 ffffff
3 12 3 ffffff
4 12 3 ffffff
5 12 3 ffffff
6 12 3 ffffff
7 12 3 ffffff
8 12 3 ffffff
9 12 3 ffffff
10 12 3 ffffff
11 12 3 ffffff
12 12 3 ffffff
13 12 3 ffffff
14 12 3 ffffff
15 12 3 ffffff
0 13 3 ffffff
1 13 3 ffffff
2 13 3 ffffff
3 13 3 ffffff
4 13 3 ffffff
5 13 3 ffffff
6 13 3 ffffff
7 13 3 ffffff
8 13 3 ffffff
9 13 3 ffffff
10 13 3 ffffff
11 13 3 ffffff
12 13 3 ffffff
13 13 3 ffffff
14 13 3 ffffff
15 13 3 ffffff
0 14 3 ffffff
1 14 3 ffffff
2 14 3 ffffff
3 14 3 ffffff
4 14 3 ffffff
5 14 3 ffffff
6 14 3 ffffff
7 14 3 ffffff
8 14 3 ffffff
9 14 3 ffffff
10 14 3 ffffff
11 14 3 ffffff
12 14 3 ffffff
13 14 3 ffffff
14 14 3 ffffff
15 14 3 ffffff
0 15 3 ffffff
1 15 3 ffffff
2 15 3 ffffff
3 15 3 ffffff
4 15 3 ffffff
5 15 3 ffffff
6 15 3 ffffff
7 15 3 ffffff
8 15 3 ffffff
9 15 3 ffffff
10 15 3 ffffff
11 15 3 ffffff
12 15 3 ffffff
13 15 3 ffffff
14 15 3 ffffff
15 15 3 ffffff
0 0 4 ffffff
1 0 4 ffffff
2 0 4 ffffff
3 0 4 ffffff
4 0 4 ffffff
5 0 4 ffffff
6 0 4 ffffff
7 0 4 ffffff
8 0 4 ffffff
9 0 4 ffffff
10 0 4 ffffff
11 0 4 ffffff
12 0 4 ffffff
13 0 4 ffffff
14 0 4 ffffff
15 0 4 ffffff
0 1 4 ffffff
1 1 4 ffffff
2 1 4 ffffff
3 1 4 ffffff
4 1 4 ffffff
5 1 4 ffffff
6 1 4 ffffff
7 1 4 ffffff
8 1 4 ffffff
9 1 4 ffffff
10 1 4 ffffff
11 1 4 ffffff
12 1 4 ffffff
13 1 4 ffffff
14 1 4 ffffff
15 1 4 ffffff
0 2 4 ffffff
1 2 4 ffffff
2 2 4 ffffff
3 2 4 ffffff
4 2 4 ffffff
5 2 4 ffffff
6 2 4 ffffff
7 2 4 ffffff
8 2 4 ffffff
9 2 4 ffffff
10 2 4 ffffff
11 2 4 ffffff
12 2 4 ffffff
13 2 4 ffffff
14 2 4 ffffff
15 2 4 ffffff
0 3 4 ffffff
1 3 4 ffffff
2 3 4 ffffff
3 3 4 ffffff
4 3 4 ffffff
5 3 4 ffffff
6 3 4 ffffff
7 3 4 ffffff
8 3 4 ffffff
9 3 4 ffffff
10 3 4 ffffff
11 3 4 ffffff
12 3 4 ffffff
13 3 4 ffffff
14 3 4 ffffff
15 3 4 ffffff
0 4 4 ffffff
1 4 4 ffffff
2 4 4 ffffff
3 4 4 ffffff
4 4 4 ffffff
5 4 4 ffffff
6 4 4 ffffff
7 4 4 ffffff
8 4 4 ffffff
9 4 4 ffffff
10 4 4 ffffff
11 4 4 ffffff
12 4 4 ffffff
13 4 4 ffffff
14 4 4 ffffff
15 4 4 ffffff
0 5 4 ffffff
1 5 4 ffffff
2 5 4 ffffff
3 5 4 ffffff
4 5 4 ffffff
5 5 4 ffffff
6 5 4 ffffff
7 5 4 ffffff
8 5 4 ffffff
9 5 4 ffffff
10 5 4 ffffff
11 5 4 ffffff
12 5 4 ffffff
13 5 4 ffffff
14 5 4 ffffff
15 5 4 ffffff
0 6 4 ffffff
1 6 4 ffffff
2 6 4 ffffff
3 6 4 ffffff
4 6 4 ffffff
5 6 4 ffffff
6 6 4 ffffff
7 6 4 ffffff
8 6 4 ffffff
9 6 4 ffffff
10 6 4 ffffff
11 6 4 ffffff
12 6 4 ffffff
13 6 4 ffffff
14 6 4 ffffff
15 6 4 ffffff
0 7 4 ffffff
1 7 4 ffffff
2 7 4 ffffff
3 7 4 ffffff
4 7 4 ffffff
5 7 4 ffffff
6 7 4 ffffff
7 7 4 ffffff
8 7 4 ffffff
9 7 4 ffffff
10 7 4 ffffff
11 7 4 ffffff
12 7 4 ffffff
13 7 4 ffffff
14 7 4 ffffff
15 7 4 ffffff
0 8 4 ffffff
1 8 4 ffffff
2 8 4 ffffff
3 8 4 ffffff
4 8 4 ffffff
5 8 4 ffffff
6 8 4 ffffff
7 8 4 ffffff
8 8 4 ffffff
9 8 4 ffffff
10 8 4 ffffff
11 8 4 ffffff
12 8 4 ffffff
13 8 4 ffffff
14 8 4 ffffff
15 8 4 ffffff
0 9 4 ffffff
1 9 4 ffffff
2 9 4 ffffff
3 9 4 ffffff
4 9 4 ffffff
5 9 4 ffffff
6 9 4 ffffff
7 9 4 ffffff
8 9 4 ffffff
9 9 4 ffffff
10 9 4 ffffff
11 9 4 ffffff
12 9 4 ffffff
13 9 4 ffffff
14 9 4 ffffff
15 9 4 ffffff
0 10 4 ffffff
1 10 4 ffffff
2 10 4 ffffff
3 10 4 ffffff
4 10 4 ffffff
5 10 4 ffffff
6 10 4 ffffff
7 10 4 ffffff
8 10 4 ffffff
9 10 4 ffffff
10 10 4 ffffff
11 10 4 ffffff
12 10 4 ffffff
13 10 4 ffffff
14 10 4 ffffff
15 10 4 ffffff
0 11 4 ffffff
1 11 4 ffffff
2 11 4 ffffff
3 11 4 ffffff
4 11 4 ffffff
5 11 4 ffffff
6 11 4 ffffff
7 11 4 ffffff
8 11 4 ffffff
9 11 4 ffffff
10 11 4 ffffff
11 11 4 ffffff
12 11 4 ffffff
13 11 4 ffffff
14 11 4 ffffff
15 11 4 ffffff
0 12 4 ffffff
1 12 4 ffffff
2 12 4 ffffff
3 12 4 ffffff
4 12 4 ffffff
5 12 4 ffffff
6 12 4 ffffff
7 12 4 ffffff
8 12 4 ffffff
9 12 4 ffffff
10 12 4 ffffff
11 12 4 ffffff
12 12 4 ffffff
13 12 4 ffffff
14 12 4 ffffff
15 12 4 ffffff
0 13 4 ffffff
1 13 4 ffffff
2 13 4 ffffff
3 13 4 ffffff
4 13 4 ffffff
5 13 4 ffffff
6 13 4 ffffff
7 13 4 ffffff
8 13 4 ffffff
9 13 4 ffffff
10 13 4 ffffff
11 13 4 ffffff
12 13 4 ffffff
13 13 4 ffffff
14 13 4 ffffff
15 13 4 ffffff
0 14 4 ffffff
1 14 4 ffffff
2 14 4 ffffff
3 14 4 ffffff
4 14 4 ffffff
5 14 4 ffffff
6 14 4 ffffff
7 14 4 ffffff
8 14 4 ffffff
9 14 4 ffffff
10 14 4 ffffff
11 14 4 ffffff
12 14 4 ffffff
13 14 4 ffffff
14 14 4 ffffff
15 14 4 ffffff
0 15 4 ffffff
1 15 4 ffffff
2 15 4 ffffff
3 15 4 ffffff
4 15 4 ffffff
5 15 4 ffffff
6 15 4 ffffff
7 15 4 ffffff
8 15 4 ffffff
9 15 4 ffffff
10 15 4 ffffff
11 15 4 ffffff
12 15 4 ffffff
13 15 4 ffffff
14 15 4 ffffff
15 15 4 ffffff
0 0 5 ffffff
1 0 5 ffffff
2 0 5 ffffff
3 0 5 ffffff
4 0 5 ffffff
5 0 5 ffffff
6 0 5 ffffff
7 0 5 ffffff
8 0 5 ffffff
9 0 5 ffffff
10 0 5 ffffff
11 0 5 ffffff
12 0 5 ffffff
13 0 5 ffffff
14 0 5 ffffff
15 0 5 ffffff
0 1 5 ffffff
1 1 5 ffffff
2 1 5 ffffff
3 1 5 ffffff
4 1 5 ffffff
5 1 5 ffffff
6 1 5 ffffff
7 1 5 ffffff
8 1 5 ffffff
9 1 5 ffffff
10 1 5 ffffff
11 1 5 ffffff
12 1 5 ffffff
13 1 5 ffffff
14 1 5 ffffff
15 1 5 ffffff
0 2 5 ffffff
1 2 5 ffffff
2 2 5 ffffff
3 2 5 ffffff
4 2 5 ffffff
5 2 5 ffffff
6 2 5 ffffff
7 2 5 ffffff
8 2 5 ffffff
9 2 5 ffffff
10 2 5 ffffff
11 2 5 ffffff
12 2 5 ffffff
13 2 5 ffffff
14 2 5 ffffff
15 2 5 ffffff
0 3 5 ffffff
1 3 5 ffffff
2 3 5 ffffff
3 3 5 ffffff
4 3 5 ffffff
5 3 5 ffffff
6 3 5 ffffff
7 3 5 ffffff
8 3 5 ffffff
9 3 5 ffffff
10 3 5 ffffff
11 3 5 ffffff
12 3 5 ffffff
13 3 5 ffffff
14 3 5 ffffff
15 3 5 ffffff
0 4 5 ffffff
1 4 5 ffffff
2 4 5 ffffff
3 4 5 ffffff
4 4 5 ffffff
5 4 5 ffffff
6 4 5 ffffff
7 4 5 ffffff
8 4 5 ffffff
9 4 5 ffffff
10 4 5 ffffff
11 4 5 ffffff
12 4 5 ffffff
13 4 5 ffffff
14 4 5 ffffff
15 4 5 ffffff
0 5 5 ffffff
1 5 5 ffffff
2 5 5 ffffff
3 5 5 ffffff
4 5 5 ffffff
5 5 5 ffffff
6 5 5 ffffff
7 5 5 ffffff
8 5 5 ffffff
9 5 5 ffffff
10 5 5 ffffff
11 5 5 ffffff
12 5 5 ffffff
13 5 5 ffffff
14 5 5 ffffff
15 5 5 ffffff
0 6 5 ffffff
1 6 5 ffffff
2 6 5 ffffff
3 6 5 ffffff
4 6 5 ffffff
5 6 5 ffffff
6 6 5 ffffff
7 6 5 ffffff
8 6 5 ffffff
9 6 5 ffffff
10 6 5 ffffff
11 6 5 ffffff
12 6 5 ffffff
13 6 5 ffffff
14 6 5 ffffff
15 6 5 ffffff
0 7 5 ffffff
1 7 5 ffffff
2 7 5 ffffff
3 7 5 ffffff
4 7 5 ffffff
5 7 5 ffffff
6 7 5 ffffff
7 7 5 ffffff
8 7 5 ffffff
9 7 5 ffffff
10 7 5 ffffff
11 7 5 ffffff
12 7 5 ffffff
13 7 5 ffffff
14 7 5 ffffff
15 7 5 ffffff
0 8 5 ffffff
1 8 5 ffffff
2 8 5 ffffff
3 8 5 ffffff
4 8 5 ffffff
5 8 5 ffffff
6 8 5 ffffff
7 8 5 ffffff
8 8 5 ffffff
9 8 5 ffffff
10 8 5 ffffff
11 8 5 ffffff
12 8 5 ffffff
13 8 5 ffffff
14 8 5 ffffff
15 8 5 ffffff
0 9 5 ffffff
1 9 5 ffffff
2 9 5 ffffff
3 9 5 ffffff
4 9 5 ffffff
5 9 5 ffffff
6 9 5 ffffff
7 9 5 ffffff
8 9 5 ffffff
9 9 5 ffffff
10 9 5 ffffff
11 9 5 ffffff
12 9 5 ffffff
13 9 5 ffffff
14 9 5 ffffff
15 9 5 ffffff
0 10 5 ffffff
1 10 5 ffffff
2 10 5 ffffff
3 10 5 ffffff
4 10 5 ffffff
5 10 5 ffffff
6 10 5 ffffff
7 10 5 ffffff
8 10 5 ffffff
9 10 5 ffffff
10 10 5 ffffff
11 10 5 ffffff
12 10 5 ffffff
13 10 5 ffffff
14 10 5 ffffff
15 10 5 ffffff
0 11 5 ffffff
1 11 5 ffffff
2 11 5 ffffff
3 11 5 ffffff
4 11 5 ffffff
5 11 5 ffffff
6 11 5 ffffff
7 11 5 ffffff
8 11 5 ffffff
9 11 5 ffffff
10 11 5 ffffff
11 11 5 ffffff
12 11 5 ffffff
13 11 5 ffffff
14 11 5 ffffff
15 11 5 ffffff
0 12 5 ffffff
1 12 5 ffffff
2 12 5 ffffff
3 12 5 ffffff
4 12 5 ffffff
5 12 5 ffffff
6 12 5 ffffff
7 12 5 ffffff
8 12 5 ffffff
9 12 5 ffffff
10 12 5 ffffff
11 12 5 ffffff
12 12 5 ffffff
13 12 5 ffffff
14 12 5 ffffff
15 12 5 ffffff
0 13 5 ffffff
1 13 5 ffffff
2 13 5 ffffff
3 13 5 ffffff
4 13 5 ffffff
5 13 5 ffffff
6 13 5 ffffff
7 13 5 ffffff
8 13 5 ffffff
9 13 5 ffffff
10 13 5 ffffff
11 13 5 ffffff
12 13 5 ffffff
13 13 5 ffffff
14 13 5 ffffff
15 13 5 ffffff
0 14 5 ffffff
1 14 5 ffffff
2 14 5 ffffff
3 14 5 ffffff
4 14 5 ffffff
5 14 5 ffffff
6 14 5 ffffff
7 14 5 ffffff
8 14 5 ffffff
9 14 5 ffffff
10 14 5 ffffff
11 14 5 ffffff
12 14 5 ffffff
13 14 5 ffffff
14 14 5 ffffff
15 14 5 ffffff
0 15 5 ffffff
1 15 5 ffffff
2 15 5 ffffff
3 15 5 ffffff
4 15 5 ffffff
5 15 5 ffffff
6 15 5 ffffff
7 15 5 ffffff
8 15 5 ffffff
9 15 5 ffffff
10 15 5 ffffff
11 15 5 ffffff
12 15 5 ffffff
13 15 5 ffffff
14 15 5 ffffff
15 15 5 ffffff
0 0 6 ffffff
1 0 6 ffffff
2 0 6 ffffff
3 0 6 ffffff
4 0 6 ffffff
5 0 6 ffffff
6 0 6 ffffff
7 0 6 ffffff
8 0 6 ffffff
9 0 6 ffffff
10 0 6 ffffff
11 0 6 ffffff
12 0 6 ffffff
13 0 6 ffffff
14 0 6 ffffff
15 0 6 ffffff
0 1 6 ffffff
1 1 6 ffffff
2 1 6 ffffff
3 1 6 ffffff
4 1 6 ffffff
5 1 6 ffffff
6 1 6 ffffff
7 1 6 ffffff
8 1 6 ffffff
9 1 6 ffffff
10 1 6 ffffff
11 1 6 ffffff
12 1 6 ffffff
13 1 6 ffffff
14 1 6 ffffff
15 1 6 ffffff
0 2 6 ffffff
1 2 6 ffffff
2 2 6 ffffff
3 2 6 ffffff
4 2 6 ffffff
5 2 6 ffffff
6 2 6 ffffff
7 2 6 ffffff
8 2 6 ffffff
9 2 6 ffffff
10 2 6 ffffff
11 2 6 ffffff
12 2 6 ffffff
13 2 6 ffffff
14 2 6 ffffff
15 2 6 ffffff
0 3 6 ffffff
1 3 6 ffffff
2 3 6 ffffff
3 3 6 ffffff
4 3 6 ffffff
5 3 6 ffffff
6 3 6 ffffff
7 3 6 ffffff
8 3 6 ffffff
9 3 6 ffffff
10 3 6 ffffff
11 3 6 ffffff
12 3 6 ffffff
13 3 6 ffffff
14 3 6 ffffff
15 3 6 ffffff
0 4 6 ffffff
1 4 6 ffffff
2 4 6 ffffff
3 4 6 ffffff
4 4 6 ffffff
5 4 6 ffffff
6 4 6 ffffff
7 4 6 ffffff
8 4 6 ffffff
9 4 6 ffffff
10 4 6 ffffff
11 4 6 ffffff
12 4 6 ffffff
13 4 6 ffffff
14 4 6 ffffff
15 4 6 ffffff
0 5 6 ffffff
1 5 6 ffffff
2 5 6 ffffff
3 5 6 ffffff
4 5 6 ffffff
5 5 6 ffffff
6 5 6 ffffff
7 5 6 ffffff
8 5 6 ffffff
9 5 6 ffffff
10 5 6 ffffff
11 5 6 ffffff
12 5 6 ffffff
13 5 6 ffffff
14 5 6 ffffff
15 5 6 ffffff
0 6 6 ffffff
1 6 6 ffffff
2 6 6 ffffff
3 6 6 ffffff
4 6 6 ffffff
5 6 6 ffffff
6 6 6 ffffff
7 6 6 ffffff
8 6 6 ffffff
9 6 6 ffffff
10 6 6 ffffff
11 6 6 ffffff
12 6 6 ffffff
13 6 6 ffffff
14 6 6 ffffff
15 6 6 ffffff
0 7 6 ffffff
1 7 6 ffffff
2 7 6 ffffff
3 7 6 ffffff
4 7 6 ffffff
5 7 6 ffffff
6 7 6 ffffff
7 7 6 ffffff
8 7 6 ffffff
9 7 6 ffffff
10 7 6 ffffff
11 7 6 ffffff
12 7 6 ffffff
13 7 6 ffffff
14 7 6 ffffff
15 7 6 ffffff
0 8 6 ffffff
1 8 6 ffffff
2 8 6 ffffff
3 8 6 ffffff
4 8 6 ffffff
5 8 6 ffffff
6 8 6 ffffff
7 8 6 ffffff
8 8 6 ffffff
9 8 6 ffffff
10 8 6 ffffff
11 8 6 ffffff
12 8 6 ffffff
13 8 6 ffffff
14 8 6 ffffff
15 8 6 ffffff
0 9 6 ffffff
1 9 6 ffffff
2 9 6 ffffff
3 9 6 ffffff
4 9 6 ffffff
5 9 6 ffffff
6 9 6 ffffff
7 9 6 ffffff
8 9 6 ffffff
9 9 6 ffffff
10 9 6 ffffff
11 9 6 ffffff
12 9 6 ffffff
13 9 6 ffffff
14 9 6 ffffff
15 9 6 ffffff
0 10 6 ffffff
1 10 6 ffffff
2 10 6 ffffff
3 10 6 ffffff
4 10 6 ffffff
5 10 6 ffffff
6 10 6 ffffff
7 10 6 ffffff
8 10 6 ffffff
9 10 6 ffffff
10 10 6 ffffff
11 10 6 ffffff
12 10 6 ffffff
13 10 6 ffffff
14 10 6 ffffff
15 10 6 ffffff
0 11 6 ffffff
1 11 6 ffffff
2 11 6 ffffff
3 11 6 ffffff
4 11 6 ffffff
5 11 6 ffffff
6 11 6 ffffff
7 11 6 ffffff
8 11 6 ffffff
9 11 6 ffffff
10 11 6 ffffff
11 11 6 ffffff
12 11 6 ffffff
13 11 6 ffffff
14 11 6 ffffff
15 11 6 ffffff
0 12 6 ffffff
1 12 6 ffffff
2 12 6 ffffff
3 12 6 ffffff
4 12 6 ffffff
5 12 6 ffffff
6 12 6 ffffff
7 12 6 ffffff
8 12 6 ffffff
9 12 6 ffffff
10 12 6 ffffff
11 12 6 ffffff
12 12 6 ffffff
13 12 6 ffffff
14 12 6 ffffff
15 12 6 ffffff
0 13 6 ffffff
1 13 6 ffffff
2 13 6 ffffff
3 13 6 ffffff
4 13 6 ffffff
5 13 6 ffffff
6 13 6 ffffff
7 13 6 ffffff
8 13 6 ffffff
9 13 6 ffffff
10 13 6 ffffff
11 13 6 ffffff
12 13 6 ffffff
13 13 6 ffffff
14 13 6 ffffff
15 13 6 ffffff
0 14 6 ffffff
1 14 6 ffffff
2 14 6 ffffff
3 14 6 ffffff
4 14 6 ffffff
5 14 6 ffffff
6 14 6 ffffff
7 14 6 ffffff
8 14 6 ffffff
9 14 6 ffffff
10 14 6 ffffff
11 14 6 ffffff
12 14 6 ffffff
13 14 6 ffffff
14 14 6 ffffff
15 14 6 ffffff
0 15 6 ffffff
1 15 6 ffffff
2 15 6 ffffff
3 15 6 ffffff
4 15 6 ffffff
5 15 6 ffffff
6 15 6 ffffff
7 15 6 ffffff
8 15 6 ffffff
9 15 6 ffffff
10 15 6 ffffff
11 15 6 ffffff
12 15 6 ffffff
13 15 6 ffffff
14 15 6 ffffff
15 15 6 ffffff
0 0 7 ffffff
1 0 7 ffffff
2 0 7 ffffff
3 0 7 ffffff
4 0 7 ffffff
5 0 7 ffffff
6 0 7 ffffff
7 0 7 ffffff
8 0 7 ffffff
9 0 7 ffffff
10 0 7 ffffff
11 0 7 ffffff
12 0 7 ffffff
13 0 7 ffffff
14 0 7 ffffff
15 0 7 ffffff
0 1 7 ffffff
1 1 7 ffffff
2 1 7 ffffff
3 1 7 ffffff
4 1 7 ffffff
5 1 7 ffffff
6 1 7 ffffff
7 1 7 ffffff
8 1 7 ffffff
9 1 7 ffffff
10 1 7 ffffff
11 1 7 ffffff
12 1 7 ffffff
13 1 7 ffffff
14 1 7 ffffff
15 1 7 ffffff
0 2 7 ffffff
1 2 7 ffffff
0 3 7 ffffff
1 3 7 ffffff
0 4 7 ffffff
1 4 7 ffffff
0 5 7 ffffff
1 5 7 ffffff
0 6 7 ffffff
1 6 7 ffffff
0 7 7 ffffff
1 7 7 ffffff
0 8 7 ffffff
1 8 7 ffffff
0 9 7 ffffff
1 9 7 ffffff
0 10 7 ffffff
1 10 7 ffffff
0 11 7 ffffff
1 11 7 ffffff
0 12 7 ffffff
1 12 7 ffffff
0 13 7 ffffff
1 13 7 ffffff
0 14 7 ffffff
1 14 7 ffffff
0 15 7 ffffff
1 15 7 ffffff
0 0 8 ffffff
1 0 8 ffffff
2 0 8 ffffff
3 0 8 ffffff
4 0 8 ffffff
5 0 8 ffffff
6 0 8 ffffff
7 0 8 ffffff
8 0 8 ffffff
9 0 8 ffffff
10 0 8 ffffff
11 0 8 ffffff
12 0 8 ffffff
13 0 8 ffffff
14 0 8 ffffff
15 0 8 ffffff
0 1 8 ffffff
1 1 8 ffffff
2 1 8 ffffff
3 1 8 ffffff
4 1 8 ffffff
5 1 8 ffffff
6 1 8 ffffff
7 1 8 ffffff
8 1 8 ffffff
9 1 8 ffffff
10 1 8 ffffff
11 1 8 ffffff
12 1 8 ffffff
13 1 8 ffffff
14 1 8 ffffff
15 1 8 ffffff
0 2 8 ffffff
1 2 8 ffffff
0 3 8 ffffff
1 3 8 ffffff
0 4 8 ffffff
1 4 8 ffffff
0 5 8 ffffff
1 5 8 ffffff
0 6 8 ffffff
1 6 8 ffffff
0 7 8 ffffff
1 7 8 ffffff
0 8 8 ffffff
1 8 8 ffffff
0 9 8 ffffff
1 9 8 ffffff
0 10 8 ffffff
1 10 8 ffffff
0 11 8 ffffff
1 11 8 ffffff
0 12 8 ffffff
1 12 8 ffffff
0 13 8 ffffff
1 13 8 ffffff
0 14 8 ffffff
1 14 8 ffffff
0 15 8 ffffff
1 15 8 ffffff
0 0 9 ffffff
1 0 9 ffffff
2 0 9 ffffff
3 0 9 ffffff
4 0 9 ffffff
5 0 9 ffffff
6 0 9 ffffff
7 0 9 ffffff
8 0 9 ffffff
9 0 9 ffffff
10 0 9 ffffff
11 0 9 ffffff
12 0 9 ffffff
13 0 9 ffffff
14 0 9 ffffff
15 0 9 ffffff
0 1 9 ffffff
1 1 9 ffffff
2 1 9 ffffff
3 1 9 ffffff
4 1 9 ffffff
5 1 9 ffffff
6 1 9 ffffff
7 1 9 ffffff
8 1 9 ffffff
9 1 9 ffffff
10 1 9 ffffff
11 1 9 ffffff
12 1 9 ffffff
13 1 9 ffffff
14 1 9 ffffff
15 1 9 ffffff
0 2 9 ffffff
1 2 9 ffffff
0 3 9 ffffff
1 3 9 ffffff
0 4 9 ffffff
1 4 9 ffffff
0 5 9 ffffff
1 5 9 ffffff
0 6 9 ffffff
1 6 9 ffffff
0 7 9 ffffff
1 7 9 ffffff
0 8 9 ffffff
1 8 9 ffffff
0 9 9 ffffff
1 9 9 ffffff
0 10 9 ffffff
1 10 9 ffffff
0 11 9 ffffff
1 11 9 ffffff
0 12 9 ffffff
1 12 9 ffffff
0 13 9 ffffff
1 13 9 ffffff
0 14 9 ffffff
1 14 9 ffffff
0 15 9 ffffff
1 15 9 ffffff
0 0 10 ffffff
1 0 10 ffffff
2 0 10 ffffff
3 0 10 ffffff
4 0 10 ffffff
5 0 10 ffffff
6 0 10 ffffff
7 0 10 ffffff
8 0 10 ffffff
9 0 10 ffffff
10 0 10 ffffff
11 0 10 ffffff
12 0 10 ffffff
13 0 10 ffffff
14 0 10 ffffff
15 0 10 ffffff
0 1 10 ffffff
1 1 10 ffffff
2 1 10 ffffff
3 1 10 ffffff
4 1 10 ffffff
5 1 10 ffffff
6 1 10 ffffff
7 1 10 ffffff
8 1 10 ffffff
9 1 10 ffffff
10 1 10 ffffff
11 1 10 ffffff
12 1 10 ffffff
13 1 10 ffffff
14 1 10 ffffff
15 1 10 ffffff
0 2 10 ffffff
1 2 10 ffffff
0 3 10 ffffff
1 3 10 ffffff
0 4 10 ffffff
1 4 10 ffffff
0 5 10 ffffff
1 5 10 ffffff
0 6 10 ffffff
1 6 10 ffffff
0 7 10 ffffff
1 7 10 ffffff
0 8 10 ffffff
1 8 10 ffffff
0 9 10 ffffff
1 9 10 ffffff
0 10 10 ffffff
1 10 10 ffffff
0 11 10 ffffff
1 11 10 ffffff
0 12 10 ffffff
1 12 10 ffffff
0 13 10 ffffff
1 13 10 ffffff
0 14 10 ffffff
1 14 10 ffffff
0 15 10 ffffff
1 15 10 ffffff
0 0 11 ffffff
1 0 11 ffffff
2 0 11 ffffff
3 0 11 ffffff
4 0 11 ffffff
5 0 11 ffffff
6 0 11 ffffff
7 0 11 ffffff
8 0 11 ffffff
9 0 11 ffffff
10 0 11 ffffff
11 0 11 ffffff
12 0 11 ffffff
13 0 11 ffffff
14 0 11 ffffff
15 0 11 ffffff
0 1 11 ffffff
1 1 11 ffffff
2 1 11 ffffff
3 1 11 ffffff
4 1 11 ffffff
5 1 11 ffffff
6 1 11 ffffff
7 1 11 ffffff
8 1 11 ffffff
9 1 11 ffffff
10 1 11 ffffff
11 1 11 ffffff
12 1 11 ffffff
13 1 11 ffffff
14 1 11 ffffff
15 1 11 ffffff
0 2 11 ffffff
1 2 11 ffffff
0 3 11 ffffff
1 3 11 ffffff
0 4 11 ffffff
1 4 11 ffffff
0 5 11 ffffff
1 5 11 ffffff
0 6 11 ffffff
1 6 11 ffffff
0 7 11 ffffff
1 7 11 ffffff
0 8 11 ffffff
1 8 11 ffffff
0 9 11 ffffff
1 9 11 ffffff
0 10 11 ffffff
1 10 11 ffffff
0 11 11 ffffff
1 11 11 ffffff
0 12 11 ffffff
1 12 11 ffffff
0 13 11 ffffff
1 13 11 ffffff
0 14 11 ffffff
1 14 11 ffffff
0 15 11 ffffff
1 15 11 ffffff
0 0 12 ffffff
1 0 12 ffffff
2 0 12 ffffff
3 0 12 ffffff
4 0 12 ffffff
5 0 12 ffffff
6 0 12 ffffff
7 0 12 ffffff
8 0 12 ffffff
9 0 12 ffffff
10 0 12 ffffff
11 0 12 ffffff
12 0 12 ffffff
13 0 12 ffffff
14 0 12 ffffff
15 0 12 ffffff
0 1 12 ffffff
1 1 12 ffffff
2 1 12 ffffff
3 1 12 ffffff
4 1 12 ffffff
5 1 12 ffffff
6 1 12 ffffff
7 1 12 ffffff
8 1 12 ffffff
9 1 12 ffffff
10 1 12 ffffff
11 1 12 ffffff
12 1 12 ffffff
13 1 12 ffffff
14 1 12 ffffff
15 1 12 ffffff
0 2 12 ffffff
1 2 12 ffffff
0 3 12 ffffff
1 3 12 ffffff
0 4 12 ffffff
1 4 12 ffffff
0 5 12 ffffff
1 5 12 ffffff
0 6 12 ffffff
1 6 12 ffffff
0 7 12 ffffff
1 7 12 ffffff
0 8 12 ffffff
1 8 12 ffffff
0 9 12 ffffff
1 9 12 ffffff
0 10 12 ffffff
1 10 12 ffffff
0 11 12 ffffff
1 11 12 ffffff
0 12 12 ffffff
1 12 12 ffffff
0 13 12 ffffff
1 13 12 ffffff
0 14 12 ffffff
1 14 12 ffffff
0 15 12 ffffff
1 15 12 ffffff
0 0 13 ffffff
1 0 13 ffffff
2 0 13 ffffff
3 0 13 ffffff
4 0 13 ffffff
5 0 13 ffffff
6 0 13 ffffff
7 0 13 ffffff
8 0 13 ffffff
9 0 13 ffffff
10 0 13 ffffff
11 0 13 ffffff
12 0 13 ffffff
13 0 13 ffffff
14 0 13 ffffff
15 0 13 ffffff
0 1 13 ffffff
1 1 13 ffffff
2 1 13 ffffff
3 1 13 ffffff
4 1 13 ffffff
5 1 13 ffffff
6 1 13 ffffff
7 1 13 ffffff
8 1 13 ffffff
9 1 13 ffffff
10 1 13 ffffff
11 1 13 ffffff
12 1 13 ffffff
13 1 13 ffffff
14 1 13 ffffff
15 1 13 ffffff
0 2 13 ffffff
1 2 13 ffffff
0 3 13 ffffff
1 3 13 ffffff
0 4 13 ffffff
1 4 13 ffffff
0 5 13 ffffff
1 5 13 ffffff
0 6 13 ffffff
1 6 13 ffffff
0 7 13 ffffff
1 7 13 ffffff
0 8 13 ffffff
1 8 13 ffffff
0 9 13 ffffff
1 9 13 ffffff
0 10 13 ffffff
1 10 13 ffffff
0 11 13 ffffff
1 11 13 ffffff
0 12 13 ffffff
1 12 13 ffffff
0 13 13 ffffff
1 13 13 ffffff
0 14 13 ffffff
1 14 13 ffffff
0 15 13 ffffff
1 15 13 ffffff
0 0 14 ffffff
1 0 14 ffffff
2 0 14 ffffff
3 0 14 ffffff
4 0 14 ffffff
5 0 14 ffffff
6 0 14 ffffff
7 0 14 ffffff
8 0 14 ffffff
9 0 14 ffffff
10 0 14 ffffff
11 0 14 ffffff
12 0 14 ffffff
13 0 14 ffffff
14 0 14 ffffff
15 0 14 ffffff
0 1 14 ffffff
1 1 14 ffffff
2 1 14 ffffff
3 1 14 ffffff
4 1 14 ffffff
5 1 14 ffffff
6 1 14 ffffff
7 1 14 ffffff
8 1 14 ffffff
9 1 14 ffffff
10 1 14 ffffff
11 1 14 ffffff
12 1 14 ffffff
13 1 14 ffffff
14 1 14 ffffff
15 1 14 ffffff
0 2 14 ffffff
1 2 14 ffffff
0 3 14 ffffff
1 3 14 ffffff
0 4 14 ffffff
1 4 14 ffffff
0 5 14 ffffff
1 5 14 ffffff
0 6 14 ffffff
1 6 14 ffffff
0 7 14 ffffff
1 7 14 ffffff
0 8 14 ffffff
1 8 14 ffffff
0 9 14 ffffff
1 9 14 ffffff
0 10 14 ffffff
1 10 14 ffffff
0 11 14 ffffff
1 11 14 ffffff
0 12 14 ffffff
1 12 14 ffffff
0 13 14 ffffff
1 13 14 ffffff
0 14 14 ffffff
1 14 14 ffffff
0 15 14 ffffff
1 15 14 ffffff
0 0 15 ffffff
1 0 15 ffffff
2 0 15 ffffff
3 0 15 ffffff
4 0 15 ffffff
5 0 15 ffffff
6 0 15 ffffff
7 0 15 ffffff
8 0 15 ffffff
9 0 15 ffffff
10 0 15 ffffff
11 0 15 ffffff
12 0 15 ffffff
13 0 15 ffffff
14 0 15 ffffff
15 0 15 ffffff
0 1 15 ffffff
1 1 15 ffffff
2 1 15 ffffff
3 1 15 ffffff
4 1 15 ffffff
5 1 15 ffffff
6 1 15 ffffff
7 1 15 ffffff
8 1 15 ffffff
9 1 15 ffffff
10 1 15 ffffff
11 1 15 ffffff
12 1 15 ffffff
13 1 15 ffffff
14 1 15 ffffff
15 1 15 ffffff
0 2 15 ffffff
1 2 15 ffffff
0 3 15 ffffff
1 3 15 ffffff
0 4 15 ffffff
1 4 15 ffffff
0 5 15 ffffff
1 5 15 ffffff
0 6 15 ffffff
1 6 15 ffffff
0 7 15 ffffff
1 7 15 ffffff
0 8 15 ffffff
1 8 15 ffffff
0 9 15 ffffff
1 9 15 ffffff
0 10 15 ffffff
1 10 15 ffffff
0 11 15 ffffff
1 11 15 ffffff
0 12 15 ffffff
1 12 15 ffffff
0 13 15 ffffff
1 13 15 ffffff
0 14 15 ffffff
1 14 15 ffffff
0 15 15 ffffff
1 15 15 ffffff
16 0 0 ffffff
17 0 0 ffffff
18 0 0 ffffff
19 0 0 ffffff
20 0 0 ffffff
21 0 0 ffffff
22 0 0 ffffff
23 0 0 ffffff
24 0 0 ffffff
25 0 0 ffffff
26 0 0 ffffff
27 0 0 ffffff
28 0 0 ffffff
29 0 0 ffffff
30 0 0 ffffff
31 0 0 ffffff
16 1 0 ffffff
17 1 0 ffffff
18 1 0 ffffff
19 1 0 ffffff
20 1 0 ffffff
21 1 0 ffffff
22 1 0 ffffff
23 1 0 ffffff
24 1 0 ffffff
25 1 0 ffffff
26 1 0 ffffff
27 1 0 ffffff
28 1 0 ffffff
29 1 0 ffffff
30 1 0 ffffff
31 1 0 ffffff
16 2 0 ffffff
17 2 0 ffffff
18 2 0 ffffff
19 2 0 ffffff
20 2 0 ffffff
21 2 0 ffffff
22 2 0 ffffff
23 2 0 ffffff
24 2 0 ffffff
25 2 0 ffffff
26 2 0 ffffff
27 2 0 ffffff
28 2 0 ffffff
29 2 0 ffffff
30 2 0 ffffff
31 2 0 ffffff
16 3 0 ffffff
17 3 0 ffffff
18 3 0 ffffff
19 3 0 ffffff
20 3 0 ffffff
21 3 0 ffffff
22 3 0 ffffff
23 3 0 ffffff
24 3 0 ffffff
25 3 0 ffffff
26 3 0 ffffff
27 3 0 ffffff
28 3 0 ffffff
29 3 0 ffffff
30 3 0 ffffff
31 3 0 ffffff
16 4 0 ffffff
17 4 0 ffffff
18 4 0 ffffff
19 4 0 ffffff
20 4 0 ffffff
21 4 0 ffffff
22 4 0 ffffff
23 4 0 ffffff
24 4 0 ffffff
25 4 0 ffffff
26 4 0 ffffff
27 4 0 ffffff
28 4 0 ffffff
29 4 0 ffffff
30 4 0 ffffff
31 4 0 ffffff
16 5 0 ffffff
17 5 0 ffffff
18 5 0 ffffff
19 5 0 ffffff
20 5 0 ffffff
21 5 0 ffffff
22 5 0 ffffff
23 5 0 ffffff
24 5 0 ffffff
25 5 0 ffffff
26 5 0 ffffff
27 5 0 ffffff
28 5 0 ffffff
29 5 0 ffffff
30 5 0 ffffff
31 5 0 ffffff
16 6 0 ffffff
17 6 0 ffffff
18 6 0 ffffff
19 6 0 ffffff
20 6 0 ffffff
21 6 0 ffffff
22 6 0 ffffff
23 6 0 ffffff
24 6 0 ffffff
25 6 0 ffffff
26 6 0 ffffff
27 6 0 ffffff
28 6 0 ffffff
29 6 0 ffffff
30 6 0 ffffff
31 6 0 ffffff
16 7 0 ffffff
17 7 0 ffffff
18 7 0 ffffff
19 7 0 ffffff
20 7 0 ffffff
21 7 0 ffffff
22 7 0 ffffff
23 7 0 ffffff
24 7 0 ffffff
25 7 0 ffffff
26 7 0 ffffff
27 7 0 ffffff
28 7 0 ffffff
29 7 0 ffffff
30 7 0 ffffff
31 7 0 ffffff
16 8 0 ffffff
17 8 0 ffffff
18 8 0 ffffff
19 8 0 ffffff
20 8 0 ffffff
21 8 0 ffffff
22 8 0 ffffff
23 8 0 ffffff
24 8 0 ffffff
25 8 0 ffffff
26 8 0 ffffff
27 8 0 ffffff
28 8 0 ffffff
29 8 0 ffffff
30 8 0 ffffff
31 8 0 ffffff
16 9 0 ffffff
17 9 0 ffffff
18 9 0 ffffff
19 9 0 ffffff
20 9 0 ffffff
21 9 0 ffffff
22 9 0 ffffff
23 9 0 ffffff
24 9 0 ffffff
25 9 0 ffffff
26 9 0 ffffff
27 9 0 ffffff
28 9 0 ffffff
29 9 0 ffffff
30 9 0 ffffff
31 9 0 ffffff
16 10 0 ffffff
17 10 0 ffffff
18 10 0 ffffff
19 10 0 ffffff
20 10 0 ffffff
21 10 0 ffffff
22 10 0 ffffff
23 10 0 ffffff
24 10 0 ffffff
25 10 0 ffffff
26 10 0 ffffff
27 10 0 ffffff
28 10 0 ffffff
29 10 0 ffffff
30 10 0 ffffff
31 10 0 ffffff
16 11 0 ffffff
17 11 0 ffffff
18 11 0 ffffff
19 11 0 ffffff
20 11 0 ffffff
21 11 0 ffffff
22 11 0 ffffff
23 11 0 ffffff
24 11 0 ffffff
25 11 0 ffffff
26 11 0 ffffff
27 11 0 ffffff
28 11 0 ffffff
29 11 0 ffffff
30 11 0 ffffff
31 11 0 ffffff
16 12 0 ffffff
17 12 0 ffffff
18 12 0 ffffff
19 12 0 ffffff
20 12 0 ffffff
21 12 0 ffffff
22 12 0 ffffff
23 12 0 ffffff
24 12 0 ffffff
25 12 0 ffffff
26 12 0 ffffff
27 12 0 ffffff
28 12 0 ffffff
29 12 0 ffffff
30 12 0 ffffff
31 12 0 ffffff
16 13 0 ffffff
17 13 0 ffffff
18 13 0 ffffff
19 13 0 ffffff
20 13 0 ffffff
21 13 0 ffffff
22 13 0 ffffff
23 13 0 ffffff
24 13 0 ffffff
25 13 0 ffffff
26 13 0 ffffff
27 13 0 ffffff
28 13 0 ffffff
29 13 0 ffffff
30 13 0 ffffff
31 13 0 ffffff
16 14 0 ffffff
17 14 0 ffffff
18 14 0 ffffff
19 14 0 ffffff
20 14 0 ffffff
21 14 0 ffffff
22 14 0 ffffff
23 14 0 ffffff
24 14 0 ffffff
25 14 0 ffffff
26 14 0 ffffff
27 14 0 ffffff
28 14 0 ffffff
29 14 0 ffffff
30 14 0 ffffff
31 14 0 ffffff
16 15 0 ffffff
17 15 0 ffffff
18 15 0 ffffff
19 15 0 ffffff
20 15 0 ffffff
21 15 0 ffffff
22 15 0 ffffff
23 15 0 ffffff
24 15 0 ffffff
25 15 0 ffffff
26 15 0 ffffff
27 15 0 ffffff
28 15 0 ffffff
29 15 0 ffffff
30 15 0 ffffff
31 15 0 ffffff
16 0 1 ffffff
17 0 1 ffffff
18 0 1 ffffff
19 0 1 ffffff
20 0 1 ffffff
21 0 1 ffffff
22 0 1 ffffff
23 0 1 ffffff
24 0 1 ffffff
25 0 1 ffffff
26 0 1 ffffff
27 0 1 ffffff
28 0 1 ffffff
29 0 1 ffffff
30 0 1 ffffff
31 0 1 ffffff
16 1 1 ffffff
17 1 1 ffffff
18 1 1 ffffff
19 1 1 ffffff
20 1 1 ffffff
21 1 1 ffffff
22 1 1 ffffff
23 1 1 ffffff
24 1 1 ffffff
25 1 1 ffffff
26 1 1 ffffff
27 1 1 ffffff
28 1 1 ffffff
29 1 1 ffffff
30 1 1 ffffff
31 1 1 ffffff
16 2 1 ffffff
17 2 1 ffffff
18 2 1 ffffff
19 2 1 ffffff
20 2 1 ffffff
21 2 1 ffffff
22 2 1 ffffff
23 2 1 ffffff
24 2 1 ffffff
25 2 1 ffffff
26 2 1 ffffff
27 2 1 ffffff
28 2 1 ffffff
29 2 1 ffffff
30 2 1 ffffff
31 2 1 ffffff
16 3 1 ffffff
17 3 1 ffffff
18 3 1 ffffff
19 3 1 ffffff
20 3 1 ffffff
21 3 1 ffffff
22 3 1 ffffff
23 3 1 ffffff
24 3 1 ffffff
25 3 1 ffffff
26 3 1 ffffff
27 3 1 ffffff
28 3 1 ffffff
29 3 1 ffffff
30 3 1 ffffff
31 3 1 ffffff
16 4 1 ffffff
17 4 1 ffffff
18 4 1 ffffff
19 4 1 ffffff
20 4 1 ffffff
21 4 1 ffffff
22 4 1 ffffff
23 4 1 ffffff
24 4 1 ffffff
25 4 1 ffffff
26 4 1 ffffff
27 4 1 ffffff
28 4 1 ffffff
29 4 1 ffffff
30 4 1 ffffff
31 4 1 ffffff
16 5 1 ffffff
17 5 1 ffffff
18 5 1 ffffff
19 5 1 ffffff
20 5 1 ffffff
21 5 1 ffffff
22 5 1 ffffff
23 5 1 ffffff
24 5 1 ffffff
25 5 1 ffffff
26 5 1 ffffff
27 5 1 ffffff
28 5 1 ffffff
29 5 1 ffffff
30 5 1 ffffff
31 5 1 ffffff
16 6 1 ffffff
17 6 1 ffffff
18 6 1 ffffff
19 6 1 ffffff
20 6 1 ffffff
21 6 1 ffffff
22 6 1 ffffff
23 6 1 ffffff
24 6 1 ffffff
25 6 1 ffffff
26 6 1 ffffff
27 6 1 ffffff
28 6 1 ffffff
29 6 1 ffffff
30 6 1 ffffff
31 6 1 ffffff
16 7 1 ffffff
17 7 1 ffffff
18 7 1 ffffff
19 7 1 ffffff
20 7 1 ffffff
21 7 1 ffffff
22 7 1 ffffff
23 7 1 ffffff
24 7 1 ffffff
25 7 1 ffffff
26 7 1 ffffff
27 7 1 ffffff
28 7 1 ffffff
29 7 1 ffffff
30 7 1 ffffff
31 7 1 ffffff
16 8 1 ffffff
17 8 1 ffffff
18 8 1 ffffff
19 8 1 ffffff
20 8 1 ffffff
21 8 1 ffffff
22 8 1 ffffff
23 8 1 ffffff
24 8 1 ffffff
25 8 1 ffffff
26 8 1 ffffff
27 8 1 ffffff
28 8 1 ffffff
29 8 1 ffffff
30 8 1 ffffff
31 8 1 ffffff
16 9 1 ffffff
17 9 1 ffffff
18 9 1 ffffff
19 9 1 ffffff
20 9 1 ffffff
21 9 1 ffffff
22 9 1 ffffff
23 9 1 ffffff
24 9 1 ffffff
25 9 1 ffffff
26 9 1 ffffff
27 9 1 ffffff
28 9 1 ffffff
29 9 1 ffffff
30 9 1 ffffff
31 9 1 ffffff
16 10 1 ffffff
17 10 1 ffffff
18 10 1 ffffff
19 10 1 ffffff
20 10 1 ffffff
21 10 1 ffffff
22 10 1 ffffff
23 10 1 ffffff
24 10 1 ffffff
25 10 1 ffffff
26 10 1 ffffff
27 10 1 ffffff
28 10 1 ffffff
29 10 1 ffffff
30 10 1 ffffff
31 10 1 ffffff
16 11 1 ffffff
17 11 1 ffffff
18 11 1 ffffff
19 11 1 ffffff
20 11 1 ffffff
21 11 1 ffffff
22 11 1 ffffff
23 11 1 ffffff
24 11 1 ffffff
25 11 1 ffffff
26 11 1 ffffff
27 11 1 ffffff
28 11 1 ffffff
29 11 1 ffffff
30 11 1 ffffff
31 11 1 ffffff
16 12 1 ffffff
17 12 1 ffffff
18 12 1 ffffff
19 12 1 ffffff
20 12 1 ffffff
21 12 1 ffffff
22 12 1 ffffff
23 12 1 ffffff
24 12 1 ffffff
25 12 1 ffffff
26 12 1 ffffff
27 12 1 ffffff
28 12 1 ffffff
29 12 1 ffffff
30 12 1 ffffff
31 12 1 ffffff
16 13 1 ffffff
17 13 1 ffffff
18 13 1 ffffff
19 13 1 ffffff
20 13 1 ffffff
21 13 1 ffffff
22 13 1 ffffff
23 13 1 ffffff
24 13 1 ffffff
25 13 1 ffffff
26 13 1 ffffff
27 13 1 ffffff
28 13 1 ffffff
29 13 1 ffffff
30 13 1 ffffff
31 13 1 ffffff
16 14 1 ffffff
17 14 1 ffffff
18 14 1 ffffff
19 14 1 ffffff
20 14 1 ffffff
21 14 1 ffffff
22 14 1 ffffff
23 14 1 ffffff
24 14 1 ffffff
25 14 1 ffffff
26 14 1 ffffff
27 14 1 ffffff
28 14 1 ffffff
29 14 1 ffffff
30 14 1 ffffff
31 14 1 ffffff
16 15 1 ffffff
17 15 1 ffffff
18 15 1 ffffff
19 15 1 ffffff
20 15 1 ffffff
21 15 1 ffffff
22 15 1 ffffff
23 15 1 ffffff
24 15 1 ffffff
25 15 1 ffffff
26 15 1 ffffff
27 15 1 ffffff
28 15 1 ffffff
29 15 1 ffffff
30 15 1 ffffff
31 15 1 ffffff
16 0 2 ffffff
17 0 2 ffffff
18 0 2 ffffff
19 0 2 ffffff
20 0 2 ffffff
21 0 2 ffffff
22 0 2 ffffff
23 0 2 ffffff
24 0 2 ffffff
25 0 2 ffffff
26 0 2 ffffff
27 0 2 ffffff
28 0 2 ffffff
29 0 2 ffffff
30 0 2 ffffff
31 0 2 ffffff
16 1 2 ffffff
17 1 2 ffffff
18 1 2 ffffff
19 1 2 ffffff
20 1 2 ffffff
21 1 2 ffffff
22 1 2 ffffff
23 1 2 ffffff
24 1 2 ffffff
25 1 2 ffffff
26 1 2 ffffff
27 1 2 ffffff
28 1 2 ffffff
29 1 2 ffffff
30 1 2 ffffff
31 1 2 ffffff
16 2 2 ffffff
17 2 2 ffffff
18 2 2 ffffff
19 2 2 ffffff
20 2 2 ffffff
21 2 2 ffffff
22 2 2 ffffff
23 2 2 ffffff
24 2 2 ffffff
25 2 2 ffffff
26 2 2 ffffff
27 2 2 ffffff
28 2 2 ffffff
29 2 2 ffffff
30 2 2 ffffff
31 2 2 ffffff
16 3 2 ffffff
17 3 2 ffffff
18 3 2 ffffff
19 3 2 ffffff
20 3 2 ffffff
21 3 2 ffffff
22 3 2 ffffff
23 3 2 ffffff
24 3 2 ffffff
25 3 2 ffffff
26 3 2 ffffff
27 3 2 ffffff
28 3 2 ffffff
29 3 2 ffffff
30 3 2 ffffff
31 3 2 ffffff
16 4 2 ffffff
17 4 2 ffffff
18 4 2 ffffff
19 4 2 ffffff
20 4 2 ffffff
21 4 2 ffffff
22 4 2 ffffff
23 4 2 ffffff
24 4 2 ffffff
25 4 2 ffffff
26 4 2 ffffff
27 4 2 ffffff
28 4 2 ffffff
29 4 2 ffffff
30 4 2 ffffff
31 4 2 ffffff
16 5 2 ffffff
17 5 2 ffffff
18 5 2 ffffff
19 5 2 ffffff
20 5 2 ffffff
21 5 2 ffffff
22 5 2 ffffff
23 5 2 ffffff
24 5 2 ffffff
25 5 2 ffffff
26 5 2 ffffff
27 5 2 ffffff
28 5 2 ffffff
29 5 2 ffffff
30 5 2 ffffff
31 5 2 ffffff
16 6 2 ffffff
17 6 2 ffffff
18 6 2 ffffff
19 6 2 ffffff
20 6 2 ffffff
21 6 2 ffffff
22 6 2 ffffff
23 6 2 ffffff
24 6 2 ffffff
25 6 2 ffffff
26 6 2 ffffff
27 6 2 ffffff
28 6 2 ffffff
29 6 2 ffffff
30 6 2 ffffff
31 6 2 ffffff
16 7 2 ffffff
17 7 2 ffffff
18 7 2 ffffff
19 7 2 ffffff
20 7 2 ffffff
21 7 2 ffffff
22 7 2 ffffff
23 7 2 ffffff
24 7 2 ffffff
25 7 2 ffffff
26 7 2 ffffff
27 7 2 ffffff
28 7 2 ffffff
29 7 2 ffffff
30 7 2 ffffff
31 7 2 ffffff
16 8 2 ffffff
17 8 2 ffffff
18 8 2 ffffff
19 8 2 ffffff
20 8 2 ffffff
21 8 2 ffffff
22 8 2 ffffff
23 8 2 ffffff
24 8 2 ffffff
25 8 2 ffffff
26 8 2 ffffff
27 8 2 ffffff
28 8 2 ffffff
29 8 2 ffffff
30 8 2 ffffff
31 8 2 ffffff
16 9 2 ffffff
17 9 2 ffffff
18 9 2 ffffff
19 9 2 ffffff
20 9 2 ffffff
21 9 2 ffffff
22 9 2 ffffff
23 9 2 ffffff
24 9 2 ffffff
25 9 2 ffffff
26 9 2 ffffff
27 9 2 ffffff
28 9 2 ffffff
29 9 2 ffffff
30 9 2 ffffff
31 9 2 ffffff
16 10 2 ffffff
17 10 2 ffffff
18 10 2 ffffff
19 10 2 ffffff
20 10 2 ffffff
21 10 2 ffffff
22 10 2 ffffff
23 10 2 ffffff
24 10 2 ffffff
25 10 2 ffffff
26 10 2 ffffff
27 10 2 ffffff
28 10 2 ffffff
29 10 2 ffffff
30 10 2 ffffff
31 10 2 ffffff
16 11 2 ffffff
17 11 2 ffffff
18 11 2 ffffff
19 11 2 ffffff
20 11 2 ffffff
21 11 2 ffffff
22 11 2 ffffff
23 11 2 ffffff
24 11 2 ffffff
25 11 2 ffffff
26 11 2 ffffff
27 11 2 ffffff
28 11 2 ffffff
29 11 2 ffffff
30 11 2 ffffff
31 11 2 ffffff
16 12 2 ffffff
17 12 2 ffffff
18 12 2 ffffff
19 12 2 ffffff
20 12 2 ffffff
21 12 2 ffffff
22 12 2 ffffff
23 12 2 ffffff
24 12 2 ffffff
25 12 2 ffffff
26 12 2 ffffff
27 12 2 ffffff
28 12 2 ffffff
29 12 2 ffffff
30 12 2 ffffff
31 12 2 ffffff
16 13 2 ffffff
17 13 2 ffffff
18 13 2 ffffff
19 13 2 ffffff
20 13 2 ffffff
21 13 2 ffffff
22 13 2 ffffff
23 13 2 ffffff
24 13 2 ffffff
25 13 2 ffffff
26 13 2 ffffff
27 13 2 ffffff
28 13 2 ffffff
29 13 2 ffffff
30 13 2 ffffff
31 13 2 ffffff
16 14 2 ffffff
17 14 2 ffffff
18 14 2 ffffff
19 14 2 ffffff
20 14 2 ffffff
21 14 2 ffffff
22 14 2 ffffff
23 14 2 ffffff
24 14 2 ffffff
25 14 2 ffffff
26 14 2 ffffff
27 14 2 ffffff
28 14 2 ffffff
29 14 2 ffffff
30 14 2 ffffff
31 14 2 ffffff
16 15 2 ffffff
17 15 2 ffffff
18 15 2 ffffff
19 15 2 ffffff
20 15 2 ffffff
21 15 2 ffffff
22 15 2 ffffff
23 15 2 ffffff
24 15 2 ffffff
25 15 2 ffffff
26 15 2 ffffff
27 15 2 ffffff
28 15 2 ffffff
29 15 2 ffffff
30 15 2 ffffff
31 15 2 ffffff
16 0 3 ffffff
17 0 3 ffffff
18 0 3 ffffff
19 0 3 ffffff
20 0 3 ffffff
21 0 3 ffffff
22 0 3 ffffff
23 0 3 ffffff
24 0 3 ffffff
25 0 3 ffffff
26 0 3 ffffff
27 0 3 ffffff
28 0 3 ffffff
29 0 3 ffffff
30 0 3 ffffff
31 0 3 ffffff
16 1 3 ffffff
17 1 3 ffffff
18 1 3 ffffff
19 1 3 ffffff
20 1 3 ffffff
21 1 3 ffffff
22 1 3 ffffff
23 1 3 ffffff
24 1 3 ffffff
25 1 3 ffffff
26 1 3 ffffff
27 1 3 ffffff
28 1 3 ffffff
29 1 3 ffffff
30 1 3 ffffff
31 1 3 ffffff
16 2 3 ffffff
17 2 3 ffffff
18 2 3 ffffff
19 2 3 ffffff
20 2 3 ffffff
21 2 3 ffffff
22 2 3 ffffff
23 2 3 ffffff
24 2 3 ffffff
25 2 3 ffffff
26 2 3 ffffff
27 2 3 ffffff
28 2 3 ffffff
29 2 3 ffffff
30 2 3 ffffff
31 2 3 ffffff
16 3 3 ffffff
17 3 3 ffffff
18 3 3 ffffff
19 3 3 ffffff
20 3 3 ffffff
21 3 3 ffffff
22 3 3 ffffff
23 3 3 ffffff
24 3 3 ffffff
25 3 3 ffffff
26 3 3 ffffff
27 3 3 ffffff
28 3 3 ffffff
29 3 3 ffffff
30 3 3 ffffff
31 3 3 ffffff
16 4 3 ffffff
17 4 3 ffffff
18 4 3 ffffff
19 4 3 ffffff
20 4 3 ffffff
21 4 3 ffffff
22 4 3 ffffff
23 4 3 ffffff
24 4 3 ffffff
25 4 3 ffffff
26 4 3 ffffff
27 4 3 ffffff
28 4 3 ffffff
29 4 3 ffffff
30 4 3 ffffff
31 4 3 ffffff
16 5 3 ffffff
17 5 3 ffffff
18 5 3 ffffff
19 5 3 ffffff
20 5 3 ffffff
21 5 3 ffffff
22 5 3 ffffff
23 5 3 ffffff
24 5 3 ffffff
25 5 3 ffffff
26 5 3 ffffff
27 5 3 ffffff
28 5 3 ffffff
29 5 3 ffffff
30 5 3 ffffff
31 5 3 ffffff
16 6 3 ffffff
17 6 3 ffffff
18 6 3 ffffff
19 6 3 ffffff
20 6 3 ffffff
21 6 3 ffffff
22 6 3 ffffff
23 6 3 ffffff
24 6 3 ffffff
25 6 3 ffffff
26 6 3 ffffff
27 6 3 ffffff
28 6 3 ffffff
29 6 3 ffffff
30 6 3 ffffff
31 6 3 ffffff
16 7 3 ffffff
17 7 3 ffffff
18 7 3 ffffff
19 7 3 ffffff
20 7 3 ffffff
21 7 3 ffffff
22 7 3 ffffff
23 7 3 ffffff
24 7 3 ffffff
25 7 3 ffffff
26 7 3 ffffff
27 7 3 ffffff
28 7 3 ffffff
29 7 3 ffffff
30 7 3 ffffff
31 7 3 ffffff
16 8 3 ffffff
17 8 3 ffffff
18 8 3 ffffff
19 8 3 ffffff
20 8 3 ffffff
21 8 3 ffffff
22 8 3 ffffff
23 8 3 ffffff
24 8 3 ffffff
25 8 3 ffffff
26 8 3 ffffff
27 8 3 ffffff
28 8 3 ffffff
29 8 3 ffffff
30 8 3 ffffff
31 8 3 ffffff
16 9 3 ffffff
17 9 3 ffffff
18 9 3 ffffff
19 9 3 ffffff
20 9 3 ffffff
21 9 3 ffffff
22 9 3 ffffff
23 9 3 ffffff
24 9 3 ffffff
25 9 3 ffffff
26 9 3 ffffff
27 9 3 ffffff
28 9 3 ffffff
29 9 3 ffffff
30 9 3 ffffff
31 9 3 ffffff
16 10 3 ffffff
17 10 3 ffffff
18 10 3 ffffff
19 10 3 ffffff
20 10 3 ffffff
21 10 3 ffffff
22 10 3 ffffff
23 10 3 ffffff
24 10 3 ffffff
25 10 3 ffffff
26 10 3 ffffff
27 10 3 ffffff
28 10 3 ffffff
29 10 3 ffffff
30 10 3 ffffff
31 10 3 ffffff
16 11 3 ffffff
17 11 3 ffffff
18 11 3 ffffff
19 11 3 ffffff
20 11 3 ffffff
21 11 3 ffffff
22 11 3 ffffff
23 11 3 ffffff
24 11 3 ffffff
25 11 3 ffffff
26 11 3 ffffff
27 11 3 ffffff
28 11 3 ffffff
29 11 3 ffffff
30 11 3 ffffff
31 11 3 ffffff
16 12 3 ffffff
17 12 3 ffffff
18 12 3 ffffff
19 12 3 ffffff
20 12 3 ffffff
21 12 3 ffffff
22 12 3 ffffff
23 12 3 ffffff
24 12 3 ffffff
25 12 3 ffffff
26 12 3 ffffff
27 12 3 ffffff
28 12 3 ffffff
29 12 3 ffffff
30 12 3 ffffff
31 12 3 ffffff
16 13 3 ffffff
17 13 3 ffffff
18 13 3 ffffff
19 13 3 ffffff
20 13 3 ffffff
21 13 3 ffffff
22 13 3 ffffff
23 13 3 ffffff
24 13 3 ffffff
25 13 3 ffffff
26 13 3 ffffff
27 13 3 ffffff
28 13 3 ffffff
29 13 3 ffffff
30 13 3 ffffff
31 13 3 ffffff
16 14 3 ffffff
17 14 3 ffffff
18 14 3 ffffff
19 14 3 ffffff
20 14 3 ffffff
21 14 3 ffffff
22 14 3 ffffff
23 14 3 ffffff
24 14 3 ffffff
25 14 3 ffffff
26 14 3 ffffff
27 14 3 ffffff
28 14 3 ffffff
29 14 3 ffffff
30 14 3 ffffff
31 14 3 ffffff
16 15 3 ffffff
17 15 3 ffffff
18 15 3 ffffff
19 15 3 ffffff
20 15 3 ffffff
21 15 3 ffffff
22 15 3 ffffff
23 15 3 ffffff
24 15 3 ffffff
25 15 3 ffffff
26 15 3 ffffff
27 15 3 ffffff
28 15 3 ffffff
29 15 3 ffffff
30 15 3 ffffff
31 15 3 ffffff
16 0 4 ffffff
17 0 4 ffffff
18 0 4 ffffff
19 0 4 ffffff
20 0 4 ffffff
21 0 4 ffffff
22 0 4 ffffff
23 0 4 ffffff
24 0 4 ffffff
25 0 4 ffffff
26 0 4 ffffff
27 0 4 ffffff
28 0 4 ffffff
29 0 4 ffffff
30 0 4 ffffff
31 0 4 ffffff
16 1 4 ffffff
17 1 4 ffffff
18 1 4 ffffff
19 1 4 ffffff
20 1 4 ffffff
21 1 4 ffffff
22 1 4 ffffff
23 1 4 ffffff
24 1 4 ffffff
25 1 4 ffffff
26 1 4 ffffff
27 1 4 ffffff
28 1 4 ffffff
29 1 4 ffffff
30 1 4 ffffff
31 1 4 ffffff
16 2 4 ffffff
17 2 4 ffffff
18 2 4 ffffff
19 2 4 ffffff
20 2 4 ffffff
21 2 4 ffffff
22 2 4 ffffff
23 2 4 ffffff
24 2 4 ffffff
25 2 4 ffffff
26 2 4 ffffff
27 2 4 ffffff
28 2 4 ffffff
29 2 4 ffffff
30 2 4 ffffff
31 2 4 ffffff
16 3 4 ffffff
17 3 4 ffffff
18 3 4 ffffff
19 3 4 ffffff
20 3 4 ffffff
21 3 4 ffffff
22 3 4 ffffff
23 3 4 ffffff
24 3 4 ffffff
25 3 4 ffffff
26 3 4 ffffff
27 3 4 ffffff
28 3 4 ffffff
29 3 4 ffffff
30 3 4 ffffff
31 3 4 ffffff
16 4 4 ffffff
17 4 4 ffffff
18 4 4 ffffff
19 4 4 ffffff
20 4 4 ffffff
21 4 4 ffffff
22 4 4 ffffff
23 4 4 ffffff
24 4 4 ffffff
25 4 4 ffffff
26 4 4 ffffff
27 4 4 ffffff
28 4 4 ffffff
29 4 4 ffffff
30 4 4 ffffff
31 4 4 ffffff
16 5 4 ffffff
17 5 4 ffffff
18 5 4 ffffff
19 5 4 ffffff
20 5 4 ffffff
21 5 4 ffffff
22 5 4 ffffff
23 5 4 ffffff
24 5 4 ffffff
25 5 4 ffffff
26 5 4 ffffff
27 5 4 ffffff
28 5 4 ffffff
29 5 4 ffffff
30 5 4 ffffff
31 5 4 ffffff
16 6 4 ffffff
17 6 4 ffffff
18 6 4 ffffff
19 6 4 ffffff
20 6 4 ffffff
21 6 4 ffffff
22 6 4 ffffff
23 6 4 ffffff
24 6 4 ffffff
25 6 4 ffffff
26 6 4 ffffff
27 6 4 ffffff
28 6 4 ffffff
29 6 4 ffffff
30 6 4 ffffff
31 6 4 ffffff
16 7 4 ffffff
17 7 4 ffffff
18 7 4 ffffff
19 7 4 ffffff
20 7 4 ffffff
21 7 4 ffffff
22 7 4 ffffff
23 7 4 ffffff
24 7 4 ffffff
25 7 4 ffffff
26 7 4 ffffff
27 7 4 ffffff
28 7 4 ffffff
29 7 4 ffffff
30 7 4 ffffff
31 7 4 ffffff
16 8 4 ffffff
17 8 4 ffffff
18 8 4 ffffff
19 8 4 ffffff
20 8 4 ffffff
21 8 4 ffffff
22 8 4 ffffff
23 8 4 ffffff
24 8 4 ffffff
25 8 4 ffffff
26 8 4 ffffff
27 8 4 ffffff
28 8 4 ffffff
29 8 4 ffffff
30 8 4 ffffff
31 8 4 ffffff
16 9 4 ffffff
17 9 4 ffffff
18 9 4 ffffff
19 9 4 ffffff
20 9 4 ffffff
21 9 4 ffffff
22 9 4 ffffff
23 9 4 ffffff
24 9 4 ffffff
25 9 4 ffffff
26 9 4 ffffff
27 9 4 ffffff
28 9 4 ffffff
29 9 4 ffffff
30 9 4 ffffff
31 9 4 ffffff
16 10 4 ffffff
17 10 4 ffffff
18 10 4 ffffff
19 10 4 ffffff
20 10 4 ffffff
21 10 4 ffffff
22 10 4 ffffff
23 10 4 ffffff
24 10 4 ffffff
25 10 4 ffffff
26 10 4 ffffff
27 10 4 ffffff
28 10 4 ffffff
29 10 4 ffffff
30 10 4 ffffff
31 10 4 ffffff
16 11 4 ffffff
17 11 4 ffffff
18 11 4 ffffff
19 11 4 ffffff
20 11 4 ffffff
21 11 4 ffffff
22 11 4 ffffff
23 11 4 ffffff
24 11 4 ffffff
25 11 4 ffffff
26 11 4 ffffff
27 11 4 ffffff
28 11 4 ffffff
29 11 4 ffffff
30 11 4 ffffff
31 11 4 ffffff
16 12 4 ffffff
17 12 4 ffffff
18 12 4 ffffff
19 12 4 ffffff
20 12 4 ffffff
21 12 4 ffffff
22 12 4 ffffff
23 12 4 ffffff
24 12 4 ffffff
25 12 4 ffffff
26 12 4 ffffff
27 12 4 ffffff
28 12 4 ffffff
29 12 4 ffffff
30 12 4 ffffff
31 12 4 ffffff
16 13 4 ffffff
17 13 4 ffffff
18 13 4 ffffff
19 13 4 ffffff
20 13 4 ffffff
21 13 4 ffffff
22 13 4 ffffff
23 13 4 ffffff
24 13 4 ffffff
25 13 4 ffffff
26 13 4 ffffff
27 13 4 ffffff
28 13 4 ffffff
29 13 4 ffffff
30 13 4 ffffff
31 13 4 ffffff
16 14 4 ffffff
17 14 4 ffffff
18 14 4 ffffff
19 14 4 ffffff
20 14 4 ffffff
21 14 4 ffffff
22 14 4 ffffff
23 14 4 ffffff
24 14 4 ffffff
25 14 4 ffffff
26 14 4 ffffff
27 14 4 ffffff
28 14 4 ffffff
29 14 4 ffffff
30 14 4 ffffff
31 14 4 ffffff
16 15 4 ffffff
17 15 4 ffffff
18 15 4 ffffff
19 15 4 ffffff
20 15 4 ffffff
21 15 4 ffffff
22 15 4 ffffff
23 15 4 ffffff
24 15 4 ffffff
25 15 4 ffffff
26 15 4 ffffff
27 15 4 ffffff
28 15 4 ffffff
29 15 4 ffffff
30 15 4 ffffff
31 15 4 ffffff
16 0 5 ffffff
17 0 5 ffffff
18 0 5 ffffff
19 0 5 ffffff
20 0 5 ffffff
21 0 5 ffffff
22 0 5 ffffff
23 0 5 ffffff
24 0 5 ffffff
25 0 5 ffffff
26 0 5 ffffff
27 0 5 ffffff
28 0 5 ffffff
29 0 5 ffffff
30 0 5 ffffff
31 0 5 ffffff
16 1 5 ffffff
17 1 5 ffffff
18 1 5 ffffff
19 1 5 ffffff
20 1 5 ffffff
21 1 5 ffffff
22 1 5 ffffff
23 1 5 ffffff
24 1 5 ffffff
25 1 5 ffffff
26 1 5 ffffff
27 1 5 ffffff
28 1 5 ffffff
29 1 5 ffffff
30 1 5 ffffff
31 1 5 ffffff
16 2 5 ffffff
17 2 5 ffffff
18 2 5 ffffff
19 2 5 ffffff
20 2 5 ffffff
21 2 5 ffffff
22 2 5 ffffff
23 2 5 ffffff
24 2 5 ffffff
25 2 5 ffffff
26 2 5 ffffff
27 2 5 ffffff
28 2 5 ffffff
29 2 5 ffffff
30 2 5 ffffff
31 2 5 ffffff
16 3 5 ffffff
17 3 5 ffffff
18 3 5 ffffff
19 3 5 ffffff
20 3 5 ffffff
21 3 5 ffffff
22 3 5 ffffff
23 3 5 ffffff
24 3 5 ffffff
25 3 5 ffffff
26 3 5 ffffff
27 3 5 ffffff
28 3 5 ffffff
29 3 5 ffffff
30 3 5 ffffff
31 3 5 ffffff
16 4 5 ffffff
17 4 5 ffffff
18 4 5 ffffff
19 4 5 ffffff
20 4 5 ffffff
21 4 5 ffffff
22 4 5 ffffff
23 4 5 ffffff
24 4 5 ffffff
25 4 5 ffffff
26 4 5 ffffff
27 4 5 ffffff
28 4 5 ffffff
29 4 5 ffffff
30 4 5 ffffff
31 4 5 ffffff
16 5 5 ffffff
17 5 5 ffffff
18 5 5 ffffff
19 5 5 ffffff
20 5 5 ffffff
21 5 5 ffffff
22 5 5 ffffff
23 5 5 ffffff
24 5 5 ffffff
25 5 5 ffffff
26 5 5 ffffff
27 5 5 ffffff
28 5 5 ffffff
29 5 5 ffffff
30 5 5 ffffff
31 5 5 ffffff
16 6 5 ffffff
17 6 5 ffffff
18 6 5 ffffff
19 6 5 ffffff
20 6 5 ffffff
21 6 5 ffffff
22 6 5 ffffff
23 6 5 ffffff
24 6 5 ffffff
25 6 5 ffffff
26 6 5 ffffff
27 6 5 ffffff
28 6 5 ffffff
29 6 5 ffffff
30 6 5 ffffff
31 6 5 ffffff
16 7 5 ffffff
17 7 5 ffffff
18 7 5 ffffff
19 7 5 ffffff
20 7 5 ffffff
21 7 5 ffffff
22 7 5 ffffff
23 7 5 ffffff
24 7 5 ffffff
25 7 5 ffffff
26 7 5 ffffff
27 7 5 ffffff
28 7 5 ffffff
29 7 5 ffffff
30 7 5 ffffff
31 7 5 ffffff
16 8 5 ffffff
17 8 5 ffffff
18 8 5 ffffff
19 8 5 ffffff
20 8 5 ffffff
21 8 5 ffffff
22 8 5 ffffff
23 8 5 ffffff
24 8 5 ffffff
25 8 5 ffffff
26 8 5 ffffff
27 8 5 ffffff
28 8 5 ffffff
29 8 5 ffffff
30 8 5 ffffff
31 8 5 ffffff
16 9 5 ffffff
17 9 5 ffffff
18 9 5 ffffff
19 9 5 ffffff
20 9 5 ffffff
21 9 5 ffffff
22 9 5 ffffff
23 9 5 ffffff
24 9 5 ffffff
25 9 5 ffffff
26 9 5 ffffff
27 9 5 ffffff
28 9 5 ffffff
29 9 5 ffffff
30 9 5 ffffff
31 9 5 ffffff
16 10 5 ffffff
17 10 5 ffffff
18 10 5 ffffff
19 10 5 ffffff
20 10 5 ffffff
21 10 5 ffffff
22 10 5 ffffff
23 10 5 ffffff
24 10 5 ffffff
25 10 5 ffffff
26 10 5 ffffff
27 10 5 ffffff
28 10 5 ffffff
29 10 5 ffffff
30 10 5 ffffff
31 10 5 ffffff
16 11 5 ffffff
17 11 5 ffffff
18 11 5 ffffff
19 11 5 ffffff
20 11 5 ffffff
21 11 5 ffffff
22 11 5 ffffff
23 11 5 ffffff
24 11 5 ffffff
25 11 5 ffffff
26 11 5 ffffff
27 11 5 ffffff
28 11 5 ffffff
29 11 5 ffffff
30 11 5 ffffff
31 11 5 ffffff
16 12 5 ffffff
17 12 5 ffffff
18 12 5 ffffff
19 12 5 ffffff
20 12 5 ffffff
21 12 5 ffffff
22 12 5 ffffff
23 12 5 ffffff
24 12 5 ffffff
25 12 5 ffffff
26 12 5 ffffff
27 12 5 ffffff
28 12 5 ffffff
29 12 5 ffffff
30 12 5 ffffff
31 12 5 ffffff
16 13 5 ffffff
17 13 5 ffffff
18 13 5 ffffff
19 13 5 ffffff
20 13 5 ffffff
21 13 5 ffffff
22 13 5 ffffff
23 13 5 ffffff
24 13 5 ffffff
25 13 5 ffffff
26 13 5 ffffff
27 13 5 ffffff
28 13 5 ffffff
29 13 5 ffffff
30 13 5 ffffff
31 13 5 ffffff
16 14 5 ffffff
17 14 5 ffffff
18 14 5 ffffff
19 14 5 ffffff
20 14 5 ffffff
21 14 5 ffffff
22 14 5 ffffff
23 14 5 ffffff
24 14 5 ffffff
25 14 5 ffffff
26 14 5 ffffff
27 14 5 ffffff
28 14 5 ffffff
29 14 5 ffffff
30 14 5 ffffff
31 14 5 ffffff
16 15 5 ffffff
17 15 5 ffffff
18 15 5 ffffff
19 15 5 ffffff
20 15 5 ffffff
21 15 5 ffffff
22 15 5 ffffff
23 15 5 ffffff
24 15 5 ffffff
25 15 5 ffffff
26 15 5 ffffff
27 15 5 ffffff
28 15 5 ffffff
29 15 5 ffffff
30 15 5 ffffff
31 15 5 ffffff
16 0 6 ffffff
17 0 6 ffffff
18 0 6 ffffff
19 0 6 ffffff
20 0 6 ffffff
21 0 6 ffffff
22 0 6 ffffff
23 0 6 ffffff
24 0 6 ffffff
25 0 6 ffffff
26 0 6 ffffff
27 0 6 ffffff
28 0 6 ffffff
29 0 6 ffffff
30 0 6 ffffff
31 0 6 ffffff
16 1 6 ffffff
17 1 6 ffffff
18 1 6 ffffff
19 1 6 ffffff
20 1 6 ffffff
21 1 6 ffffff
22 1 6 ffffff
23 1 6 ffffff
24 1 6 ffffff
25 1 6 ffffff
26 1 6 ffffff
27 1 6 ffffff
28 1 6 ffffff
29 1 6 ffffff
30 1 6 ffffff
31 1 6 ffffff
16 2 6 ffffff
17 2 6 ffffff
18 2 6 ffffff
19 2 6 ffffff
20 2 6 ffffff
21 2 6 ffffff
22 2 6 ffffff
23 2 6 ffffff
24 2 6 ffffff
25 2 6 ffffff
26 2 6 ffffff
27 2 6 ffffff
28 2 6 ffffff
29 2 6 ffffff
30 2 6 ffffff
31 2 6 ffffff
16 3 6 ffffff
17 3 6 ffffff
18 3 6 ffffff
19 3 6 ffffff
20 3 6 ffffff
21 3 6 ffffff
22 3 6 ffffff
23 3 6 ffffff
24 3 6 ffffff
25 3 6 ffffff
26 3 6 ffffff
27 3 6 ffffff
28 3 6 ffffff
29 3 6 ffffff
30 3 6 ffffff
31 3 6 ffffff
16 4 6 ffffff
17 4 6 ffffff
18 4 6 ffffff
19 4 6 ffffff
20 4 6 ffffff
21 4 6 ffffff
22 4 6 ffffff
23 4 6 ffffff
24 4 6 ffffff
25 4 6 ffffff
26 4 6 ffffff
27 4 6 ffffff
28 4 6 ffffff
29 4 6 ffffff
30 4 6 ffffff
31 4 6 ffffff
16 5 6 ffffff
17 5 6 ffffff
18 5 6 ffffff
19 5 6 ffffff
20 5 6 ffffff
21 5 6 ffffff
22 5 6 ffffff
23 5 6 ffffff
24 5 6 ffffff
25 5 6 ffffff
26 5 6 ffffff
27 5 6 ffffff
28 5 6 ffffff
29 5 6 ffffff
30 5 6 ffffff
31 5 6 ffffff
16 6 6 ffffff
17 6 6 ffffff
18 6 6 ffffff
19 6 6 ffffff
20 6 6 ffffff
21 6 6 ffffff
22 6 6 ffffff
23 6 6 ffffff
24 6 6 ffffff
25 6 6 ffffff
26 6 6 ffffff
27 6 6 ffffff
28 6 6 ffffff
29 6 6 ffffff
30 6 6 ffffff
31 6 6 ffffff
16 7 6 ffffff
17 7 6 ffffff
18 7 6 ffffff
19 7 6 ffffff
20 7 6 ffffff
21 7 6 ffffff
22 7 6 ffffff
23 7 6 ffffff
24 7 6 ffffff
25 7 6 ffffff
26 7 6 ffffff
27 7 6 ffffff
28 7 6 ffffff
29 7 6 ffffff
30 7 6 ffffff
31 7 6 ffffff
16 8 6 ffffff
17 8 6 ffffff
18 8 6 ffffff
19 8 6 ffffff
20 8 6 ffffff
21 8 6 ffffff
22 8 6 ffffff
23 8 6 ffffff
24 8 6 ffffff
25 8 6 ffffff
26 8 6 ffffff
27 8 6 ffffff
28 8 6 ffffff
29 8 6 ffffff
30 8 6 ffffff
31 8 6 ffffff
16 9 6 ffffff
17 9 6 ffffff
18 9 6 ffffff
19 9 6 ffffff
20 9 6 ffffff
21 9 6 ffffff
22 9 6 ffffff
23 9 6 ffffff
24 9 6 ffffff
25 9 6 ffffff
26 9 6 ffffff
27 9 6 ffffff
28 9 6 ffffff
29 9 6 ffffff
30 9 6 ffffff
31 9 6 ffffff
16 10 6 ffffff
17 10 6 ffffff
18 10 6 ffffff
19 10 6 ffffff
20 10 6 ffffff
21 10 6 ffffff
22 10 6 ffffff
23 10 6 ffffff
24 10 6 ffffff
25 10 6 ffffff
26 10 6 ffffff
27 10 6 ffffff
28 10 6 ffffff
29 10 6 ffffff
30 10 6 ffffff
31 10 6 ffffff
16 11 6 ffffff
17 11 6 ffffff
18 11 6 ffffff
19 11 6 ffffff
20 11 6 ffffff
21 11 6 ffffff
22 11 6 ffffff
23 11 6 ffffff
24 11 6 ffffff
25 11 6 ffffff
26 11 6 ffffff
27 11 6 ffffff
28 11 6 ffffff
29 11 6 ffffff
30 11 6 ffffff
31 11 6 ffffff
16 12 6 ffffff
17 12 6 ffffff
18 12 6 ffffff
19 12 6 ffffff
20 12 6 ffffff
21 12 6 ffffff
22 12 6 ffffff
23 12 6 ffffff
24 12 6 ffffff
25 12 6 ffffff
26 12 6 ffffff
27 12 6 ffffff
28 12 6 ffffff
29 12 6 ffffff
30 12 6 ffffff
31 12 6 ffffff
16 13 6 ffffff
17 13 6 ffffff
18 13 6 ffffff
19 13 6 ffffff
20 13 6 ffffff
21 13 6 ffffff
22 13 6 ffffff
23 13 6 ffffff
24 13 6 ffffff
25 13 6 ffffff
26 13 6 ffffff
27 13 6 ffffff
28 13 6 ffffff
29 13 6 ffffff
30 13 6 ffffff
31 13 6 ffffff
16 14 6 ffffff
17 14 6 ffffff
18 14 6 ffffff
19 14 6 ffffff
20 14 6 ffffff
21 14 6 ffffff
22 14 6 ffffff
23 14 6 ffffff
24 14 6 ffffff
25 14 6 ffffff
26 14 6 ffffff
27 14 6 ffffff
28 14 6 ffffff
29 14 6 ffffff
30 14 6 ffffff
31 14 6 ffffff
16 15 6 ffffff
17 15 6 ffffff
18 15 6 ffffff
19 15 6 ffffff
20 15 6 ffffff
21 15 6 ffffff
22 15 6 ffffff
23 15 6 ffffff
24 15 6 ffffff
25 15 6 ffffff
26 15 6 ffffff
27 15 6 ffffff
28 15 6 ffffff
29 15 6 ffffff
30 15 6 ffffff
31 15 6 ffffff
16 0 7 ffffff
17 0 7 ffffff
18 0 7 ffffff
19 0 7 ffffff
20 0 7 ffffff
21 0 7 ffffff
22 0 7 ffffff
23 0 7 ffffff
24 0 7 ffffff
25 0 7 ffffff
26 0 7 ffffff
27 0 7 ffffff
28 0 7 ffffff
29 0 7 ffffff
30 0 7 ffffff
31 0 7 ffffff
16 1 7 ffffff
17 1 7 ffffff
18 1 7 ffffff
19 1 7 ffffff
20 1 7 ffffff
21 1 7 ffffff
22 1 7 ffffff
23 1 7 ffffff
24 1 7 ffffff
25 1 7 ffffff
26 1 7 ffffff
27 1 7 ffffff
28 1 7 ffffff
29 1 7 ffffff
30 1 7 ffffff
31 1 7 ffffff
16 0 8 ffffff
17 0 8 ffffff
18 0 8 ffffff
19 0 8 ffffff
20 0 8 ffffff
21 0 8 ffffff
22 0 8 ffffff
23 0 8 ffffff
24 0 8 ffffff
25 0 8 ffffff
26 0 8 ffffff
27 0 8 ffffff
28 0 8 ffffff
29 0 8 ffffff
30 0 8 ffffff
31 0 8 ffffff
16 1 8 ffffff
17 1 8 ffffff
18 1 8 ffffff
19 1 8 ffffff
20 1 8 ffffff
21 1 8 ffffff
22 1 8 ffffff
23 1 8 ffffff
24 1 8 ffffff
25 1 8 ffffff
26 1 8 ffffff
27 1 8 ffffff
28 1 8 ffffff
29 1 8 ffffff
30 1 8 ffffff
31 1 8 ffffff
16 0 9 ffffff
17 0 9 ffffff
18 0 9 ffffff
19 0 9 ffffff
20 0 9 ffffff
21 0 9 ffffff
22 0 9 ffffff
23 0 9 ffffff
24 0 9 ffffff
25 0 9 ffffff
26 0 9 ffffff
27 0 9 ffffff
28 0 9 ffffff
29 0 9 ffffff
30 0 9 ffffff
31 0 9 ffffff
16 1 9 ffffff
17 1 9 ffffff
18 1 9 ffffff
19 1 9 ffffff
20 1 9 ffffff
21 1 9 ffffff
22 1 9 ffffff
23 1 9 ffffff
24 1 9 ffffff
25 1 9 ffffff
26 1 9 ffffff
27 1 9 ffffff
28 1 9 ffffff
29 1 9 ffffff
30 1 9 ffffff
31 1 9 ffffff
16 0 10 ffffff
17 0 10 ffffff
18 0 10 ffffff
19 0 10 ffffff
20 0 10 ffffff
21 0 10 ffffff
22 0 10 ffffff
23 0 10 ffffff
24 0 10 ffffff
25 0 10 ffffff
26 0 10 ffffff
27 0 10 ffffff
28 0 10 ffffff
29 0 10 ffffff
30 0 10 ffffff
31 0 10 ffffff
16 1 10 ffffff
17 1 10 ffffff
18 1 10 ffffff
19 1 10 ffffff
20 1 10 ffffff
21 1 10 ffffff
22 1 10 ffffff
23 1 10 ffffff
24 1 10 ffffff
25 1 10 ffffff
26 1 10 ffffff
27 1 10 ffffff
28 1 10 ffffff
29 1 10 ffffff
30 1 10 ffffff
31 1 10 ffffff
16 0 11 ffffff
17 0 11 ffffff
18 0 11 ffffff
19 0 11 ffffff
20 0 11 ffffff
21 0 11 ffffff
22 0 11 ffffff
23 0 11 ffffff
24 0 11 ffffff
25 0 11 ffffff
26 0 11 ffffff
27 0 11 ffffff
28 0 11 ffffff
29 0 11 ffffff
30 0 11 ffffff
31 0 11 ffffff
16 1 11 ffffff
17 1 11 ffffff
18 1 11 ffffff
19 1 11 ffffff
20 1 11 ffffff
21 1 11 ffffff
22 1 11 ffffff
23 1 11 ffffff
24 1 11 ffffff
25 1 11 ffffff
26 1 11 ffffff
27 1 11 ffffff
28 1 11 ffffff
29 1 11 ffffff
30 1 11 ffffff
31 1 11 ffffff
16 0 12 ffffff
17 0 12 ffffff
18 0 12 ffffff
19 0 12 ffffff
20 0 12 ffffff
21 0 12 ffffff
22 0 12 ffffff
23 0 12 ffffff
24 0 12 ffffff
25 0 12 ffffff
26 0 12 ffffff
27 0 12 ffffff
28 0 12 ffffff
29 0 12 ffffff
30 0 12 ffffff
31 0 12 ffffff
16 1 12 ffffff
17 1 12 ffffff
18 1 12 ffffff
19 1 12 ffffff
20 1 12 ffffff
21 1 12 ffffff
22 1 12 ffffff
23 1 12 ffffff
24 1 12 ffffff
25 1 12 ffffff
26 1 12 ffffff
27 1 12 ffffff
28 1 12 ffffff
29 1 12 ffffff
30 1 12 ffffff
31 1 12 ffffff
16 0 13 ffffff
17 0 13 ffffff
18 0 13 ffffff
19 0 13 ffffff
20 0 13 ffffff
21 0 13 ffffff
22 0 13 ffffff
23 0 13 ffffff
24 0 13 ffffff
25 0 13 ffffff
26 0 13 ffffff
27 0 13 ffffff
28 0 13 ffffff
29 0 13 ffffff
30 0 13 ffffff
31 0 13 ffffff
16 1 13 ffffff
17 1 13 ffffff
18 1 13 ffffff
19 1 13 ffffff
20 1 13 ffffff
21 1 13 ffffff
22 1 13 ffffff
23 1 13 ffffff
24 1 13 ffffff
25 1 13 ffffff
26 1 13 ffffff
27 1 13 ffffff
28 1 13 ffffff
29 1 13 ffffff
30 1 13 ffffff
31 1 13 ffffff
16 0 14 ffffff
17 0 14 ffffff
18 0 14 ffffff
19 0 14 ffffff
20 0 14 ffffff
21 0 14 ffffff
22 0 14 ffffff
23 0 14 ffffff
24 0 14 ffffff
25 0 14 ffffff
26 0 14 ffffff
27 0 14 ffffff
28 0 14 ffffff
29 0 14 ffffff
30 0 14 ffffff
31 0 14 ffffff
16 1 14 ffffff
17 1 14 ffffff
18 1 14 ffffff
19 1 14 ffffff
20 1 14 ffffff
21 1 14 ffffff
22 1 14 ffffff
23 1 14 ffffff
24 1 14 ffffff
25 1 14 ffffff
26 1 14 ffffff
27 1 14 ffffff
28 1 14 ffffff
29 1 14 ffffff
30 1 14 ffffff
31 1 14 ffffff
16 0 15 ffffff
17 0 15 ffffff
18 0 15 ffffff
19 0 15 ffffff
20 0 15 ffffff
21 0 15 ffffff
22 0 15 ffffff
23 0 15 ffffff
24 0 15 ffffff
25 0 15 ffffff
26 0 15 ffffff
27 0 15 ffffff
28 0 15 ffffff
29 0 15 ffffff
30 0 15 ffffff
31 0 15 ffffff
16 1 15 ffffff
17 1 15 ffffff
18 1 15 ffffff
19 1 15 ffffff
20 1 15 ffffff
21 1 15 ffffff
22 1 15 ffffff
23 1 15 ffffff
24 1 15 ffffff
25 1 15 ffffff
26 1 15 ffffff
27 1 15 ffffff
28 1 15 ffffff
29 1 15 ffffff
30 1 15 ffffff
31 1 15 ffffff
0 16 0 ffffff
1 16 0 ffffff
2 16 0 ffffff
3 16 0 ffffff
4 16 0 ffffff
5 16 0 ffffff
6 16 0 ffffff
7 16 0 ffffff
8 16 0 ffffff
9 16 0 ffffff
10 16 0 ffffff
11 16 0 ffffff
12 16 0 ffffff
13 16 0 ffffff
14 16 0 ffffff
15 16 0 ffffff
0 17 0 ffffff
1 17 0 ffffff
2 17 0 ffffff
3 17 0 ffffff
4 17 0 ffffff
5 17 0 ffffff
6 17 0 ffffff
7 17 0 ffffff
8 17 0 ffffff
9 17 0 ffffff
10 17 0 ffffff
11 17 0 ffffff
12 17 0 ffffff
13 17 0 ffffff
14 17 0 ffffff
15 17 0 ffffff
0 18 0 ffffff
1 18 0 ffffff
2 18 0 ffffff
3 18 0 ffffff
4 18 0 ffffff
5 18 0 ffffff
6 18 0 ffffff
7 18 0 ffffff
8 18 0 ffffff
9 18 0 ffffff
10 18 0 ffffff
11 18 0 ffffff
12 18 0 ffffff
13 18 0 ffffff
14 18 0 ffffff
15 18 0 ffffff
0 19 0 ffffff
1 19 0 ffffff
2 19 0 ffffff
3 19 0 ffffff
4 19 0 ffffff
5 19 0 ffffff
6 19 0 ffffff
7 19 0 ffffff
8 19 0 ffffff
9 19 0 ffffff
10 19 0 ffffff
11 19 0 ffffff
12 19 0 ffffff
13 19 0 ffffff
14 19 0 ffffff
15 19 0 ffffff
0 20 0 ffffff
1 20 0 ffffff
2 20 0 ffffff
3 20 0 ffffff
4 20 0 ffffff
5 20 0 ffffff
6 20 0 ffffff
7 20 0 ffffff
8 20 0 ffffff
9 20 0 ffffff
10 20 0 ffffff
11 20 0 ffffff
12 20 0 ffffff
13 20 0 ffffff
14 20 0 ffffff
15 20 0 ffffff
0 21 0 ffffff
1 21 0 ffffff
2 21 0 ffffff
3 21 0 ffffff
4 21 0 ffffff
5 21 0 ffffff
6 21 0 ffffff
7 21 0 ffffff
8 21 0 ffffff
9 21 0 ffffff
10 21 0 ffffff
11 21 0 ffffff
12 21 0 ffffff
13 21 0 ffffff
14 21 0 ffffff
15 21 0 ffffff
0 22 0 ffffff
1 22 0 ffffff
2 22 0 ffffff
3 22 0 ffffff
4 22 0 ffffff
5 22 0 ffffff
6 22 0 ffffff
7 22 0 ffffff
8 22 0 ffffff
9 22 0 ffffff
10 22 0 ffffff
11 22 0 ffffff
12 22 0 ffffff
13 22 0 ffffff
14 22 0 ffffff
15 22 0 ffffff
0 23 0 ffffff
1 23 0 ffffff
2 23 0 ffffff
3 23 0 ffffff
4 23 0 ffffff
5 23 0 ffffff
6 23 0 ffffff
7 23 0 ffffff
8 23 0 ffffff
9 23 0 ffffff
10 23 0 ffffff
11 23 0 ffffff
12 23 0 ffffff
13 23 0 ffffff
14 23 0 ffffff
15 23 0 ffffff
0 24 0 ffffff
1 24 0 ffffff
2 24 0 ffffff
3 24 0 ffffff
4 24 0 ffffff
5 24 0 ffffff
6 24 0 ffffff
7 24 0 ffffff
8 24 0 ffffff
9 24 0 ffffff
10 24 0 ffffff
11 24 0 ffffff
12 24 0 ffffff
13 24 0 ffffff
14 24 0 ffffff
15 24 0 ffffff
0 25 0 ffffff
1 25 0 ffffff
2 25 0 ffffff
3 25 0 ffffff
4 25 0 ffffff
5 25 0 ffffff
6 25 0 ffffff
7 25 0 ffffff
8 25 0 ffffff
9 25 0 ffffff
10 25 0 ffffff
11 25 0 ffffff
12 25 0 ffffff
13 25 0 ffffff
14 25 0 ffffff
15 25 0 ffffff
0 26 0 ffffff
1 26 0 ffffff
2 26 0 ffffff
3 26 0 ffffff
4 26 0 ffffff
5 26 0 ffffff
6 26 0 ffffff
7 26 0 ffffff
8 26 0 ffffff
9 26 0 ffffff
10 26 0 ffffff
11 26 0 ffffff
12 26 0 ffffff
13 26 0 ffffff
14 26 0 ffffff
15 26 0 ffffff
0 27 0 ffffff
1 27 0 ffffff
2 27 0 ffffff
3 27 0 ffffff
4 27 0 ffffff
5 27 0 ffffff
6 27 0 ffffff
7 27 0 ffffff
8 27 0 ffffff
9 27 0 ffffff
10 27 0 ffffff
11 27 0 ffffff
12 27 0 ffffff
13 27 0 ffffff
14 27 0 ffffff
15 27 0 ffffff
0 28 0 ffffff
1 28 0 ffffff
2 28 0 ffffff
3 28 0 ffffff
4 28 0 ffffff
5 28 0 ffffff
6 28 0 ffffff
7 28 0 ffffff
8 28 0 ffffff
9 28 0 ffffff
10 28 0 ffffff
11 28 0 ffffff
12 28 0 ffffff
13 28 0 ffffff
14 28 0 ffffff
15 28 0 ffffff
0 29 0 ffffff
1 29 0 ffffff
2 29 0 ffffff
3 29 0 ffffff
4 29 0 ffffff
5 29 0 ffffff
6 29 0 ffffff
7 29 0 ffffff
8 29 0 ffffff
9 29 0 ffffff
10 29 0 ffffff
11 29 0 ffffff
12 29 0 ffffff
13 29 0 ffffff
14 29 0 ffffff
15 29 0 ffffff
0 30 0 ffffff
1 30 0 ffffff
2 30 0 ffffff
3 30 0 ffffff
4 30 0 ffffff
5 30 0 ffffff
6 30 0 ffffff
7 30 0 ffffff
8 30 0 ffffff
9 30 0 ffffff
10 30 0 ffffff
11 30 0 ffffff
12 30 0 ffffff
13 30 0 ffffff
14 30 0 ffffff
15 30 0 ffffff
0 31 0 ffffff
1 31 0 ffffff
2 31 0 ffffff
3 31 0 ffffff
4 31 0 ffffff
5 31 0 ffffff
6 31 0 ffffff
7 31 0 ffffff
8 31 0 ffffff
9 31 0 ffffff
10 31 0 ffffff
11 31 0 ffffff
12 31 0 ffffff
13 31 0 ffffff
14 31 0 ffffff
15 31 0 ffffff
0 16 1 ffffff
1 16 1 ffffff
2 16 1 ffffff
3 16 1 ffffff
4 16 1 ffffff
5 16 1 ffffff
6 16 1 ffffff
7 16 1 ffffff
8 16 1 ffffff
9 16 1 ffffff
10 16 1 ffffff
11 16 1 ffffff
12 16 1 ffffff
13 16 1 ffffff
14 16 1 ffffff
15 16 1 ffffff
0 17 1 ffffff
1 17 1 ffffff
2 17 1 ffffff
3 17 1 ffffff
4 17 1 ffffff
5 17 1 ffffff
6 17 1 ffffff
7 17 1 ffffff
8 17 1 ffffff
9 17 1 ffffff
10 17 1 ffffff
11 17 1 ffffff
12 17 1 ffffff
13 17 1 ffffff
14 17 1 ffffff
15 17 1 ffffff
0 18 1 ffffff
1 18 1 ffffff
2 18 1 ffffff
3 18 1 ffffff
4 18 1 ffffff
5 18 1 ffffff
6 18 1 ffffff
7 18 1 ffffff
8 18 1 ffffff
9 18 1 ffffff
10 18 1 ffffff
11 18 1 ffffff
12 18 1 ffffff
13 18 1 ffffff
14 18 1 ffffff
15 18 1 ffffff
0 19 1 ffffff
1 19 1 ffffff
2 19 1 ffffff
3 19 1 ffffff
4 19 1 ffffff
5 19 1 ffffff
6 19 1 ffffff
7 19 1 ffffff
8 19 1 ffffff
9 19 1 ffffff
10 19 1 ffffff
11 19 1 ffffff
12 19 1 ffffff
13 19 1 ffffff
14 19 1 ffffff
15 19 1 ffffff
0 20 1 ffffff
1 20 1 ffffff
2 20 1 ffffff
3 20 1 ffffff
4 20 1 ffffff
5 20 1 ffffff
6 20 1 ffffff
7 20 1 ffffff
8 20 1 ffffff
9 20 1 ffffff
10 20 1 ffffff
11 20 1 ffffff
12 20 1 ffffff
13 20 1 ffffff
14 20 1 ffffff
15 20 1 ffffff
0 21 1 ffffff
1 21 1 ffffff
2 21 1 ffffff
3 21 1 ffffff
4 21 1 ffffff
5 21 1 ffffff
6 21 1 ffffff
7 21 1 ffffff
8 21 1 ffffff
9 21 1 ffffff
10 21 1 ffffff
11 21 1 ffffff
12 21 1 ffffff
13 21 1 ffffff
14 21 1 ffffff
15 21 1 ffffff
0 22 1 ffffff
1 22 1 ffffff
2 22 1 ffffff
3 22 1 ffffff
4 22 1 ffffff
5 22 1 ffffff
6 22 1 ffffff
7 22 1 ffffff
8 22 1 ffffff
9 22 1 ffffff
10 22 1 ffffff
11 22 1 ffffff
12 22 1 ffffff
13 22 1 ffffff
14 22 1 ffffff
15 22 1 ffffff
0 23 1 ffffff
1 23 1 ffffff
2 23 1 ffffff
3 23 1 ffffff
4 23 1 ffffff
5 23 1 ffffff
6 23 1 ffffff
7 23 1 ffffff
8 23 1 ffffff
9 23 1 ffffff
10 23 1 ffffff
11 23 1 ffffff
12 23 1 ffffff
13 23 1 ffffff
14 23 1 ffffff
15 23 1 ffffff
0 24 1 ffffff
1 24 1 ffffff
2 24 1 ffffff
3 24 1 ffffff
4 24 1 ffffff
5 24 1 ffffff
6 24 1 ffffff
7 24 1 ffffff
8 24 1 ffffff
9 24 1 ffffff
10 24 1 ffffff
11 24 1 ffffff
12 24 1 ffffff
13 24 1 ffffff
14 24 1 ffffff
15 24 1 ffffff
0 25 1 ffffff
1 25 1 ffffff
2 25 1 ffffff
3 25 1 ffffff
4 25 1 ffffff
5 25 1 ffffff
6 25 1 ffffff
7 25 1 ffffff
8 25 1 ffffff
9 25 1 ffffff
10 25 1 ffffff
11 25 1 ffffff
12 25 1 ffffff
13 25 1 ffffff
14 25 1 ffffff
15 25 1 ffffff
0 26 1 ffffff
1 26 1 ffffff
2 26 1 ffffff
3 26 1 ffffff
4 26 1 ffffff
5 26 1 ffffff
6 26 1 ffffff
7 26 1 ffffff
8 26 1 ffffff
9 26 1 ffffff
10 26 1 ffffff
11 26 1 ffffff
12 26 1 ffffff
13 26 1 ffffff
14 26 1 ffffff
15 26 1 ffffff
0 27 1 ffffff
1 27 1 ffffff
2 27 1 ffffff
3 27 1 ffffff
4 27 1 ffffff
5 27 1 ffffff
6 27 1 ffffff
7 27 1 ffffff
8 27 1 ffffff
9 27 1 ffffff
10 27 1 ffffff
11 27 1 ffffff
12 27 1 ffffff
13 27 1 ffffff
14 27 1 ffffff
15 27 1 ffffff
0 28 1 ffffff
1 28 1 ffffff
2 28 1 ffffff
3 28 1 ffffff
4 28 1 ffffff
5 28 1 ffffff
6 28 1 ffffff
7 28 1 ffffff
8 28 1 ffffff
9 28 1 ffffff
10 28 1 ffffff
11 28 1 ffffff
12 28 1 ffffff
13 28 1 ffffff
14 28 1 ffffff
15 28 1 ffffff
0 29 1 ffffff
1 29 1 ffffff
2 29 1 ffffff
3 29 1 ffffff
4 29 1 ffffff
5 29 1 ffffff
6 29 1 ffffff
7 29 1 ffffff
8 29 1 ffffff
9 29 1 ffffff
10 29 1 ffffff
11 29 1 ffffff
12 29 1 ffffff
13 29 1 ffffff
14 29 1 ffffff
15 29 1 ffffff
0 30 1 ffffff
1 30 1 ffffff
2 30 1 ffffff
3 30 1 ffffff
4 30 1 ffffff
5 30 1 ffffff
6 30 1 ffffff
7 30 1 ffffff
8 30 1 ffffff
9 30 1 ffffff
10 30 1 ffffff
11 30 1 ffffff
12 30 1 ffffff
13 30 1 ffffff
14 30 1 ffffff
15 30 1 ffffff
0 31 1 ffffff
1 31 1 ffffff
2 31 1 ffffff
3 31 1 ffffff
4 31 1 ffffff
5 31 1 ffffff
6 31 1 ffffff
7 31 1 ffffff
8 31 1 ffffff
9 31 1 ffffff
10 31 1 ffffff
11 31 1 ffffff
12 31 1 ffffff
13 31 1 ffffff
14 31 1 ffffff
15 31 1 ffffff
0 16 2 ffffff
1 16 2 ffffff
2 16 2 ffffff
3 16 2 ffffff
4 16 2 ffffff
5 16 2 ffffff
6 16 2 ffffff
7 16 2 ffffff
8 16 2 ffffff
9 16 2 ffffff
10 16 2 ffffff
11 16 2 ffffff
12 16 2 ffffff
13 16 2 ffffff
14 16 2 ffffff
15 16 2 ffffff
0 17 2 ffffff
1 17 2 ffffff
2 17 2 ffffff
3 17 2 ffffff
4 17 2 ffffff
5 17 2 ffffff
6 17 2 ffffff
7 17 2 ffffff
8 17 2 ffffff
9 17 2 ffffff
10 17 2 ffffff
11 17 2 ffffff
12 17 2 ffffff
13 17 2 ffffff
14 17 2 ffffff
15 17 2 ffffff
0 18 2 ffffff
1 18 2 ffffff
2 18 2 ffffff
3 18 2 ffffff
4 18 2 ffffff
5 18 2 ffffff
6 18 2 ffffff
7 18 2 ffffff
8 18 2 ffffff
9 18 2 ffffff
10 18 2 ffffff
11 18 2 ffffff
12 18 2 ffffff
13 18 2 ffffff
14 18 2 ffffff
15 18 2 ffffff
0 19 2 ffffff
1 19 2 ffffff
2 19 2 ffffff
3 19 2 ffffff
4 19 2 ffffff
5 19 2 ffffff
6 19 2 ffffff
7 19 2 ffffff
8 19 2 ffffff
9 19 2 ffffff
10 19 2 ffffff
11 19 2 ffffff
12 19 2 ffffff
13 19 2 ffffff
14 19 2 ffffff
15 19 2 ffffff
0 20 2 ffffff
1 20 2 ffffff
2 20 2 ffffff
3 20 2 ffffff
4 20 2 ffffff
5 20 2 ffffff
6 20 2 ffffff
7 20 2 ffffff
8 20 2 ffffff
9 20 2 ffffff
10 20 2 ffffff
11 20 2 ffffff
12 20 2 ffffff
13 20 2 ffffff
14 20 2 ffffff
15 20 2 ffffff
0 21 2 ffffff
1 21 2 ffffff
2 21 2 ffffff
3 21 2 ffffff
4 21 2 ffffff
5 21 2 ffffff
6 21 2 ffffff
7 21 2 ffffff
8 21 2 ffffff
9 21 2 ffffff
10 21 2 ffffff
11 21 2 ffffff
12 21 2 ffffff
13 21 2 ffffff
14 21 2 ffffff
15 21 2 ffffff
0 22 2 ffffff
1 22 2 ffffff
2 22 2 ffffff
3 22 2 ffffff
4 22 2 ffffff
5 22 2 ffffff
6 22 2 ffffff
7 22 2 ffffff
8 22 2 ffffff
9 22 2 ffffff
10 22 2 ffffff
11 22 2 ffffff
12 22 2 ffffff
13 22 2 ffffff
14 22 2 ffffff
15 22 2 ffffff
0 23 2 ffffff
1 23 2 ffffff
2 23 2 ffffff
3 23 2 ffffff
4 23 2 ffffff
5 23 2 ffffff
6 23 2 ffffff
7 23 2 ffffff
8 23 2 ffffff
9 23 2 ffffff
10 23 2 ffffff
11 23 2 ffffff
12 23 2 ffffff
13 23 2 ffffff
14 23 2 ffffff
15 23 2 ffffff
0 24 2 ffffff
1 24 2 ffffff
2 24 2 ffffff
3 24 2 ffffff
4 24 2 ffffff
5 24 2 ffffff
6 24 2 ffffff
7 24 2 ffffff
8 24 2 ffffff
9 24 2 ffffff
10 24 2 ffffff
11 24 2 ffffff
12 24 2 ffffff
13 24 2 ffffff
14 24 2 ffffff
15 24 2 ffffff
0 25 2 ffffff
1 25 2 ffffff
2 25 2 ffffff
3 25 2 ffffff
4 25 2 ffffff
5 25 2 ffffff
6 25 2 ffffff
7 25 2 ffffff
8 25 2 ffffff
9 25 2 ffffff
10 25 2 ffffff
11 25 2 ffffff
12 25 2 ffffff
13 25 2 ffffff
14 25 2 ffffff
15 25 2 ffffff
0 26 2 ffffff
1 26 2 ffffff
2 26 2 ffffff
3 26 2 ffffff
4 26 2 ffffff
5 26 2 ffffff
6 26 2 ffffff
7 26 2 ffffff
8 26 2 ffffff
9 26 2 ffffff
10 26 2 ffffff
11 26 2 ffffff
12 26 2 ffffff
13 26 2 ffffff
14 26 2 ffffff
15 26 2 ffffff
0 27 2 ffffff
1 27 2 ffffff
2 27 2 ffffff
3 27 2 ffffff
4 27 2 ffffff
5 27 2 ffffff
6 27 2 ffffff
7 27 2 ffffff
8 27 2 ffffff
9 27 2 ffffff
10 27 2 ffffff
11 27 2 ffffff
12 27 2 ffffff
13 27 2 ffffff
14 27 2 ffffff
15 27 2 ffffff
0 28 2 ffffff
1 28 2 ffffff
2 28 2 ffffff
3 28 2 ffffff
4 28 2 ffffff
5 28 2 ffffff
6 28 2 ffffff
7 28 2 ffffff
8 28 2 ffffff
9 28 2 ffffff
10 28 2 ffffff
11 28 2 ffffff
12 28 2 ffffff
13 28 2 ffffff
14 28 2 ffffff
15 28 2 ffffff
0 29 2 ffffff
1 29 2 ffffff
2 29 2 ffffff
3 29 2 ffffff
4 29 2 ffffff
5 29 2 ffffff
6 29 2 ffffff
7 29 2 ffffff
8 29 2 ffffff
9 29 2 ffffff
10 29 2 ffffff
11 29 2 ffffff
12 29 2 ffffff
13 29 2 ffffff
14 29 2 ffffff
15 29 2 ffffff
0 30 2 ffffff
1 30 2 ffffff
2 30 2 ffffff
3 30 2 ffffff
4 30 2 ffffff
5 30 2 ffffff
6 30 2 ffffff
7 30 2 ffffff
8 30 2 ffffff
9 30 2 ffffff
10 30 2 ffffff
11 30 2 ffffff
12 30 2 ffffff
13 30 2 ffffff
14 30 2 ffffff
15 30 2 ffffff
0 31 2 ffffff
1 31 2 ffffff
2 31 2 ffffff
3 31 2 ffffff
4 31 2 ffffff
5 31 2 ffffff
6 31 2 ffffff
7 31 2 ffffff
8 31 2 ffffff
9 31 2 ffffff
10 31 2 ffffff
11 31 2 ffffff
12 31 2 ffffff
13 31 2 ffffff
14 31 2 ffffff
15 31 2 ffffff
0 16 3 ffffff
1 16 3 ffffff
2 16 3 ffffff
3 16 3 ffffff
4 16 3 ffffff
5 16 3 ffffff
6 16 3 ffffff
7 16 3 ffffff
8 16 3 ffffff
9 16 3 ffffff
10 16 3 ffffff
11 16 3 ffffff
12 16 3 ffffff
13 16 3 ffffff
14 16 3 ffffff
15 16 3 ffffff
0 17 3 ffffff
1 17 3 ffffff
2 17 3 ffffff
3 17 3 ffffff
4 17 3 ffffff
5 17 3 ffffff
6 17 3 ffffff
7 17 3 ffffff
8 17 3 ffffff
9 17 3 ffffff
10 17 3 ffffff
11 17 3 ffffff
12 17 3 ffffff
13 17 3 ffffff
14 17 3 ffffff
15 17 3 ffffff
0 18 3 ffffff
1 18 3 ffffff
2 18 3 ffffff
3 18 3 ffffff
4 18 3 ffffff
5 18 3 ffffff
6 18 3 ffffff
7 18 3 ffffff
8 18 3 ffffff
9 18 3 ffffff
10 18 3 ffffff
11 18 3 ffffff
12 18 3 ffffff
13 18 3 ffffff
14 18 3 ffffff
15 18 3 ffffff
0 19 3 ffffff
1 19 3 ffffff
2 19 3 ffffff
3 19 3 ffffff
4 19 3 ffffff
5 19 3 ffffff
6 19 3 ffffff
7 19 3 ffffff
8 19 3 ffffff
9 19 3 ffffff
10 19 3 ffffff
11 19 3 ffffff
12 19 3 ffffff
13 19 3 ffffff
14 19 3 ffffff
15 19 3 ffffff
0 20 3 ffffff
1 20 3 ffffff
2 20 3 ffffff
3 20 3 ffffff
4 20 3 ffffff
5 20 3 ffffff
6 20 3 ffffff
7 20 3 ffffff
8 20 3 ffffff
9 20 3 ffffff
10 20 3 ffffff
11 20 3 ffffff
12 20 3 ffffff
13 20 3 ffffff
14 20 3 ffffff
15 20 3 ffffff
0 21 3 ffffff
1 21 3 ffffff
2 21 3 ffffff
3 21 3 ffffff
4 21 3 ffffff
5 21 3 ffffff
6 21 3 ffffff
7 21 3 ffffff
8 21 3 ffffff
9 21 3 ffffff
10 21 3 ffffff
11 21 3 ffffff
12 21 3 ffffff
13 21 3 ffffff
14 21 3 ffffff
15 21 3 ffffff
0 22 3 ffffff
1 22 3 ffffff
2 22 3 ffffff
3 22 3 ffffff
4 22 3 ffffff
5 22 3 ffffff
6 22 3 ffffff
7 22 3 ffffff
8 22 3 ffffff
9 22 3 ffffff
10 22 3 ffffff
11 22 3 ffffff
12 22 3 ffffff
13 22 3 ffffff
14 22 3 ffffff
15 22 3 ffffff
0 23 3 ffffff
1 23 3 ffffff
2 23 3 ffffff
3 23 3 ffffff
4 23 3 ffffff
5 23 3 ffffff
6 23 3 ffffff
7 23 3 ffffff
8 23 3 ffffff
9 23 3 ffffff
10 23 3 ffffff
11 23 3 ffffff
12 23 3 ffffff
13 23 3 ffffff
14 23 3 ffffff
15 23 3 ffffff
0 24 3 ffffff
1 24 3 ffffff
2 24 3 ffffff
3 24 3 ffffff
4 24 3 ffffff
5 24 3 ffffff
6 24 3 ffffff
7 24 3 ffffff
8 24 3 ffffff
9 24 3 ffffff
10 24 3 ffffff
11 24 3 ffffff
12 24 3 ffffff
13 24 3 ffffff
14 24 3 ffffff
15 24 3 ffffff
0 25 3 ffffff
1 25 3 ffffff
2 25 3 ffffff
3 25 3 ffffff
4 25 3 ffffff
5 25 3 ffffff
6 25 3 ffffff
7 25 3 ffffff
8 25 3 ffffff
9 25 3 ffffff
10 25 3 ffffff
11 25 3 ffffff
12 25 3 ffffff
13 25 3 ffffff
14 25 3 ffffff
15 25 3 ffffff
0 26 3 ffffff
1 26 3 ffffff
2 26 3 ffffff
3 26 3 ffffff
4 26 3 ffffff
5 26 3 ffffff
6 26 3 ffffff
7 26 3 ffffff
8 26 3 ffffff
9 26 3 ffffff
10 26 3 ffffff
11 26 3 ffffff
12 26 3 ffffff
13 26 3 ffffff
14 26 3 ffffff
15 26 3 ffffff
0 27 3 ffffff
1 27 3 ffffff
2 27 3 ffffff
3 27 3 ffffff
4 27 3 ffffff
5 27 3 ffffff
6 27 3 ffffff
7 27 3 ffffff
8 27 3 ffffff
9 27 3 ffffff
10 27 3 ffffff
11 27 3 ffffff
12 27 3 ffffff
13 27 3 ffffff
14 27 3 ffffff
15 27 3 ffffff
0 28 3 ffffff
1 28 3 ffffff
2 28 3 ffffff
3 28 3 ffffff
4 28 3 ffffff
5 28 3 ffffff
6 28 3 ffffff
7 28 3 ffffff
8 28 3 ffffff
9 28 3 ffffff
10 28 3 ffffff
11 28 3 ffffff
12 28 3 ffffff
13 28 3 ffffff
14 28 3 ffffff
15 28 3 ffffff
0 29 3 ffffff
1 29 3 ffffff
2 29 3 ffffff
3 29 3 ffffff
4 29 3 ffffff
5 29 3 ffffff
6 29 3 ffffff
7 29 3 ffffff
8 29 3 ffffff
9 29 3 ffffff
10 29 3 ffffff
11 29 3 ffffff
12 29 3 ffffff
13 29 3 ffffff
14 29 3 ffffff
15 29 3 ffffff
0 30 3 ffffff
1 30 3 ffffff
2 30 3 ffffff
3 30 3 ffffff
4 30 3 ffffff
5 30 3 ffffff
6 30 3 ffffff
7 30 3 ffffff
8 30 3 ffffff
9 30 3 ffffff
10 30 3 ffffff
11 30 3 ffffff
12 30 3 ffffff
13 30 3 ffffff
14 30 3 ffffff
15 30 3 ffffff
0 31 3 ffffff
1 31 3 ffffff
2 31 3 ffffff
3 31 3 ffffff
4 31 3 ffffff
5 31 3 ffffff
6 31 3 ffffff
7 31 3 ffffff
8 31 3 ffffff
9 31 3 ffffff
10 31 3 ffffff
11 31 3 ffffff
12 31 3 ffffff
13 31 3 ffffff
14 31 3 ffffff
15 31 3 ffffff
0 16 4 ffffff
1 16 4 ffffff
2 16 4 ffffff
3 16 4 ffffff
4 16 4 ffffff
5 16 4 ffffff
6 16 4 ffffff
7 16 4 ffffff
8 16 4 ffffff
9 16 4 ffffff
10 16 4 ffffff
11 16 4 ffffff
12 16 4 ffffff
13 16 4 ffffff
14 16 4 ffffff
15 16 4 ffffff
0 17 4 ffffff
1 17 4 ffffff
2 17 4 ffffff
3 17 4 ffffff
4 17 4 ffffff
5 17 4 ffffff
6 17 4 ffffff
7 17 4 ffffff
8 17 4 ffffff
9 17 4 ffffff
10 17 4 ffffff
11 17 4 ffffff
12 17 4 ffffff
13 17 4 ffffff
14 17 4 ffffff
15 17 4 ffffff
0 18 4 ffffff
1 18 4 ffffff
2 18 4 ffffff
3 18 4 ffffff
4 18 4 ffffff
5 18 4 ffffff
6 18 4 ffffff
7 18 4 ffffff
8 18 4 ffffff
9 18 4 ffffff
10 18 4 ffffff
11 18 4 ffffff
12 18 4 ffffff
13 18 4 ffffff
14 18 4 ffffff
15 18 4 ffffff
0 19 4 ffffff
1 19 4 ffffff
2 19 4 ffffff
3 19 4 ffffff
4 19 4 ffffff
5 19 4 ffffff
6 19 4 ffffff
7 19 4 ffffff
8 19 4 ffffff
9 19 4 ffffff
10 19 4 ffffff
11 19 4 ffffff
12 19 4 ffffff
13 19 4 ffffff
14 19 4 ffffff
15 19 4 ffffff
0 20 4 ffffff
1 20 4 ffffff
2 20 4 ffffff
3 20 4 ffffff
4 20 4 ffffff
5 20 4 ffffff
6 20 4 ffffff
7 20 4 ffffff
8 20 4 ffffff
9 20 4 ffffff
10 20 4 ffffff
11 20 4 ffffff
12 20 4 ffffff
13 20 4 ffffff
14 20 4 ffffff
15 20 4 ffffff
0 21 4 ffffff
1 21 4 ffffff
2 21 4 ffffff
3 21 4 ffffff
4 21 4 ffffff
5 21 4 ffffff
6 21 4 ffffff
7 21 4 ffffff
8 21 4 ffffff
9 21 4 ffffff
10 21 4 ffffff
11 21 4 ffffff
12 21 4 ffffff
13 21 4 ffffff
14 21 4 ffffff
15 21 4 ffffff
0 22 4 ffffff
1 22 4 ffffff
2 22 4 ffffff
3 22 4 ffffff
4 22 4 ffffff
5 22 4 ffffff
6 22 4 ffffff
7 22 4 ffffff
8 22 4 ffffff
9 22 4 ffffff
10 22 4 ffffff
11 22 4 ffffff
12 22 4 ffffff
13 22 4 ffffff
14 22 4 ffffff
15 22 4 ffffff
0 23 4 ffffff
1 23 4 ffffff
2 23 4 ffffff
3 23 4 ffffff
4 23 4 ffffff
5 23 4 ffffff
6 23 4 ffffff
7 23 4 ffffff
8 23 4 ffffff
9 23 4 ffffff
10 23 4 ffffff
11 23 4 ffffff
12 23 4 ffffff
13 23 4 ffffff
14 23 4 ffffff
15 23 4 ffffff
0 24 4 ffffff
1 24 4 ffffff
2 24 4 ffffff
3 24 4 ffffff
4 24 4 ffffff
5 24 4 ffffff
6 24 4 ffffff
7 24 4 ffffff
8 24 4 ffffff
9 24 4 ffffff
10 24 4 ffffff
11 24 4 ffffff
12 24 4 ffffff
13 24 4 ffffff
14 24 4 ffffff
15 24 4 ffffff
0 25 4 ffffff
1 25 4 ffffff
2 25 4 ffffff
3 25 4 ffffff
4 25 4 ffffff
5 25 4 ffffff
6 25 4 ffffff
7 25 4 ffffff
8 25 4 ffffff
9 25 4 ffffff
10 25 4 ffffff
11 25 4 ffffff
12 25 4 ffffff
13 25 4 ffffff
14 25 4 ffffff
15 25 4 ffffff
0 26 4 ffffff
1 26 4 ffffff
2 26 4 ffffff
3 26 4 ffffff
4 26 4 ffffff
5 26 4 ffffff
6 26 4 ffffff
7 26 4 ffffff
8 26 4 ffffff
9 26 4 ffffff
10 26 4 ffffff
11 26 4 ffffff
12 26 4 ffffff
13 26 4 ffffff
14 26 4 ffffff
15 26 4 ffffff
0 27 4 ffffff
1 27 4 ffffff
2 27 4 ffffff
3 27 4 ffffff
4 27 4 ffffff
5 27 4 ffffff
6 27 4 ffffff
7 27 4 ffffff
8 27 4 ffffff
9 27 4 ffffff
10 27 4 ffffff
11 27 4 ffffff
12 27 4 ffffff
13 27 4 ffffff
14 27 4 ffffff
15 27 4 ffffff
0 28 4 ffffff
1 28 4 ffffff
2 28 4 ffffff
3 28 4 ffffff
4 28 4 ffffff
5 28 4 ffffff
6 28 4 ffffff
7 28 4 ffffff
8 28 4 ffffff
9 28 4 ffffff
10 28 4 ffffff
11 28 4 ffffff
12 28 4 ffffff
13 28 4 ffffff
14 28 4 ffffff
15 28 4 ffffff
0 29 4 ffffff
1 29 4 ffffff
2 29 4 ffffff
3 29 4 ffffff
4 29 4 ffffff
5 29 4 ffffff
6 29 4 ffffff
7 29 4 ffffff
8 29 4 ffffff
9 29 4 ffffff
10 29 4 ffffff
11 29 4 ffffff
12 29 4 ffffff
13 29 4 ffffff
14 29 4 ffffff
15 29 4 ffffff
0 30 4 ffffff
1 30 4 ffffff
2 30 4 ffffff
3 30 4 ffffff
4 30 4 ffffff
5 30 4 ffffff
6 30 4 ffffff
7 30 4 ffffff
8 30 4 ffffff
9 30 4 ffffff
10 30 4 ffffff
11 30 4 ffffff
12 30 4 ffffff
13 30 4 ffffff
14 30 4 ffffff
15 30 4 ffffff
0 31 4 ffffff
1 31 4 ffffff
2 31 4 ffffff
3 31 4 ffffff
4 31 4 ffffff
5 31 4 ffffff
6 31 4 ffffff
7 31 4 ffffff
8 31 4 ffffff
9 31 4 ffffff
10 31 4 ffffff
11 31 4 ffffff
12 31 4 ffffff
13 31 4 ffffff
14 31 4 ffffff
15 31 4 ffffff
0 16 5 ffffff
1 16 5 ffffff
2 16 5 ffffff
3 16 5 ffffff
4 16 5 ffffff
5 16 5 ffffff
6 16 5 ffffff
7 16 5 ffffff
8 16 5 ffffff
9 16 5 ffffff
10 16 5 ffffff
11 16 5 ffffff
12 16 5 ffffff
13 16 5 ffffff
14 16 5 ffffff
15 16 5 ffffff
0 17 5 ffffff
1 17 5 ffffff
2 17 5 ffffff
3 17 5 ffffff
4 17 5 ffffff
5 17 5 ffffff
6 17 5 ffffff
7 17 5 ffffff
8 17 5 ffffff
9 17 5 ffffff
10 17 5 ffffff
11 17 5 ffffff
12 17 5 ffffff
13 17 5 ffffff
14 17 5 ffffff
15 17 5 ffffff
0 18 5 ffffff
1 18 5 ffffff
2 18 5 ffffff
3 18 5 ffffff
4 18 5 ffffff
5 18 5 ffffff
6 18 5 ffffff
7 18 5 ffffff
8 18 5 ffffff
9 18 5 ffffff
10 18 5 ffffff
11 18 5 ffffff
12 18 5 ffffff
13 18 5 ffffff
14 18 5 ffffff
15 18 5 ffffff
0 19 5 ffffff
1 19 5 ffffff
2 19 5 ffffff
3 19 5 ffffff
4 19 5 ffffff
5 19 5 ffffff
6 19 5 ffffff
7 19 5 ffffff
8 19 5 ffffff
9 19 5 ffffff
10 19 5 ffffff
11 19 5 ffffff
12 19 5 ffffff
13 19 5 ffffff
14 19 5 ffffff
15 19 5 ffffff
0 20 5 ffffff
1 20 5 ffffff
2 20 5 ffffff
3 20 5 ffffff
4 20 5 ffffff
5 20 5 ffffff
6 20 5 ffffff
7 20 5 ffffff
8 20 5 ffffff
9 20 5 ffffff
10 20 5 ffffff
11 20 5 ffffff
12 20 5 ffffff
13 20 5 ffffff
14 20 5 ffffff
15 20 5 ffffff
0 21 5 ffffff
1 21 5 ffffff
2 21 5 ffffff
3 21 5 ffffff
4 21 5 ffffff
5 21 5 ffffff
6 21 5 ffffff
7 21 5 ffffff
8 21 5 ffffff
9 21 5 ffffff
10 21 5 ffffff
11 21 5 ffffff
12 21 5 ffffff
13 21 5 ffffff
14 21 5 ffffff
15 21 5 ffffff
0 22 5 ffffff
1 22 5 ffffff
2 22 5 ffffff
3 22 5 ffffff
4 22 5 ffffff
5 22 5 ffffff
6 22 5 ffffff
7 22 5 ffffff
8 22 5 ffffff
9 22 5 ffffff
10 22 5 ffffff
11 22 5 ffffff
12 22 5 ffffff
13 22 5 ffffff
14 22 5 ffffff
15 22 5 ffffff
0 23 5 ffffff
1 23 5 ffffff
2 23 5 ffffff
3 23 5 ffffff
4 23 5 ffffff
5 23 5 ffffff
6 23 5 ffffff
7 23 5 ffffff
8 23 5 ffffff
9 23 5 ffffff
10 23 5 ffffff
11 23 5 ffffff
12 23 5 ffffff
13 23 5 ffffff
14 23 5 ffffff
15 23 5 ffffff
0 24 5 ffffff
1 24 5 ffffff
2 24 5 ffffff
3 24 5 ffffff
4 24 5 ffffff
5 24 5 ffffff
6 24 5 ffffff
7 24 5 ffffff
8 24 5 ffffff
9 24 5 ffffff
10 24 5 ffffff
11 24 5 ffffff
12 24 5 ffffff
13 24 5 ffffff
14 24 5 ffffff
15 24 5 ffffff
0 25 5 ffffff
1 25 5 ffffff
2 25 5 ffffff
3 25 5 ffffff
4 25 5 ffffff
5 25 5 ffffff
6 25 5 ffffff
7 25 5 ffffff
8 25 5 ffffff
9 25 5 ffffff
10 25 5 ffffff
11 25 5 ffffff
12 25 5 ffffff
13 25 5 ffffff
14 25 5 ffffff
15 25 5 ffffff
0 26 5 ffffff
1 26 5 ffffff
2 26 5 ffffff
3 26 5 ffffff
4 26 5 ffffff
5 26 5 ffffff
6 26 5 ffffff
7 26 5 ffffff
8 26 5 ffffff
9 26 5 ffffff
10 26 5 ffffff
11 26 5 ffffff
12 26 5 ffffff
13 26 5 ffffff
14 26 5 ffffff
15 26 5 ffffff
0 27 5 ffffff
1 27 5 ffffff
2 27 5 ffffff
3 27 5 ffffff
4 27 5 ffffff
5 27 5 ffffff
6 27 5 ffffff
7 27 5 ffffff
8 27 5 ffffff
9 27 5 ffffff
10 27 5 ffffff
11 27 5 ffffff
12 27 5 ffffff
13 27 5 ffffff
14 27 5 ffffff
15 27 5 ffffff
0 28 5 ffffff
1 28 5 ffffff
2 28 5 ffffff
3 28 5 ffffff
4 28 5 ffffff
5 28 5 ffffff
6 28 5 ffffff
7 28 5 ffffff
8 28 5 ffffff
9 28 5 ffffff
10 28 5 ffffff
11 28 5 ffffff
12 28 5 ffffff
13 28 5 ffffff
14 28 5 ffffff
15 28 5 ffffff
0 29 5 ffffff
1 29 5 ffffff
2 29 5 ffffff
3 29 5 ffffff
4 29 5 ffffff
5 29 5 ffffff
6 29 5 ffffff
7 29 5 ffffff
8 29 5 ffffff
9 29 5 ffffff
10 29 5 ffffff
11 29 5 ffffff
12 29 5 ffffff
13 29 5 ffffff
14 29 5 ffffff
15 29 5 ffffff
0 30 5 ffffff
1 30 5 ffffff
2 30 5 ffffff
3 30 5 ffffff
4 30 5 ffffff
5 30 5 ffffff
6 30 5 ffffff
7 30 5 ffffff
8 30 5 ffffff
9 30 5 ffffff
10 30 5 ffffff
11 30 5 ffffff
12 30 5 ffffff
13 30 5 ffffff
14 30 5 ffffff
15 30 5 ffffff
0 31 5 ffffff
1 31 5 ffffff
2 31 5 ffffff
3 31 5 ffffff
4 31 5 ffffff
5 31 5 ffffff
6 31 5 ffffff
7 31 5 ffffff
8 31 5 ffffff
9 31 5 ffffff
10 31 5 ffffff
11 31 5 ffffff
12 31 5 ffffff
13 31 5 ffffff
14 31 5 ffffff
15 31 5 ffffff
0 16 6 ffffff
1 16 6 ffffff
2 16 6 ffffff
3 16 6 ffffff
4 16 6 ffffff
5 16 6 ffffff
6 16 6 ffffff
7 16 6 ffffff
8 16 6 ffffff
9 16 6 ffffff
10 16 6 ffffff
11 16 6 ffffff
12 16 6 ffffff
13 16 6 ffffff
14 16 6 ffffff
15 16 6 ffffff
0 17 6 ffffff
1 17 6 ffffff
2 17 6 ffffff
3 17 6 ffffff
4 17 6 ffffff
5 17 6 ffffff
6 17 6 ffffff
7 17 6 ffffff
8 17 6 ffffff
9 17 6 ffffff
10 17 6 ffffff
11 17 6 ffffff
12 17 6 ffffff
13 17 6 ffffff
14 17 6 ffffff
15 17 6 ffffff
0 18 6 ffffff
1 18 6 ffffff
2 18 6 ffffff
3 18 6 ffffff
4 18 6 ffffff
5 18 6 ffffff
6 18 6 ffffff
7 18 6 ffffff
8 18 6 ffffff
9 18 6 ffffff
10 18 6 ffffff
11 18 6 ffffff
12 18 6 ffffff
13 18 6 ffffff
14 18 6 ffffff
15 18 6 ffffff
0 19 6 ffffff
1 19 6 ffffff
2 19 6 ffffff
3 19 6 ffffff
4 19 6 ffffff
5 19 6 ffffff
6 19 6 ffffff
7 19 6 ffffff
8 19 6 ffffff
9 19 6 ffffff
10 19 6 ffffff
11 19 6 ffffff
12 19 6 ffffff
13 19 6 ffffff
14 19 6 ffffff
15 19 6 ffffff
0 20 6 ffffff
1 20 6 ffffff
2 20 6 ffffff
3 20 6 ffffff
4 20 6 ffffff
5 20 6 ffffff
6 20 6 ffffff
7 20 6 ffffff
8 20 6 ffffff
9 20 6 ffffff
10 20 6 ffffff
11 20 6 ffffff
12 20 6 ffffff
13 20 6 ffffff
14 20 6 ffffff
15 20 6 ffffff
0 21 6 ffffff
1 21 6 ffffff
2 21 6 ffffff
3 21 6 ffffff
4 21 6 ffffff
5 21 6 ffffff
6 21 6 ffffff
7 21 6 ffffff
8 21 6 ffffff
9 21 6 ffffff
10 21 6 ffffff
11 21 6 ffffff
12 21 6 ffffff
13 21 6 ffffff
14 21 6 ffffff
15 21 6 ffffff
0 22 6 ffffff
1 22 6 ffffff
2 22 6 ffffff
3 22 6 ffffff
4 22 6 ffffff
5 22 6 ffffff
6 22 6 ffffff
7 22 6 ffffff
8 22 6 ffffff
9 22 6 ffffff
10 22 6 ffffff
11 22 6 ffffff
12 22 6 ffffff
13 22 6 ffffff
14 22 6 ffffff
15 22 6 ffffff
0 23 6 ffffff
1 23 6 ffffff
2 23 6 ffffff
3 23 6 ffffff
4 23 6 ffffff
5 23 6 ffffff
6 23 6 ffffff
7 23 6 ffffff
8 23 6 ffffff
9 23 6 ffffff
10 23 6 ffffff
11 23 6 ffffff
12 23 6 ffffff
13 23 6 ffffff
14 23 6 ffffff
15 23 6 ffffff
0 24 6 ffffff
1 24 6 ffffff
2 24 6 ffffff
3 24 6 ffffff
4 24 6 ffffff
5 24 6 ffffff
6 24 6 ffffff
7 24 6 ffffff
8 24 6 ffffff
9 24 6 ffffff
10 24 6 ffffff
11 24 6 ffffff
12 24 6 ffffff
13 24 6 ffffff
14 24 6 ffffff
15 24 6 ffffff
0 25 6 ffffff
1 25 6 ffffff
2 25 6 ffffff
3 25 6 ffffff
4 25 6 ffffff
5 25 6 ffffff
6 25 6 ffffff
7 25 6 ffffff
8 25 6 ffffff
9 25 6 ffffff
10 25 6 ffffff
11 25 6 ffffff
12 25 6 ffffff
13 25 6 ffffff
14 25 6 ffffff
15 25 6 ffffff
0 26 6 ffffff
1 26 6 ffffff
2 26 6 ffffff
3 26 6 ffffff
4 26 6 ffffff
5 26 6 ffffff
6 26 6 ffffff
7 26 6 ffffff
8 26 6 ffffff
9 26 6 ffffff
10 26 6 ffffff
11 26 6 ffffff
12 26 6 ffffff
13 26 6 ffffff
14 26 6 ffffff
15 26 6 ffffff
0 27 6 ffffff
1 27 6 ffffff
2 27 6 ffffff
3 27 6 ffffff
4 27 6 ffffff
5 27 6 ffffff
6 27 6 ffffff
7 27 6 ffffff
8 27 6 ffffff
9 27 6 ffffff
10 27 6 ffffff
11 27 6 ffffff
12 27 6 ffffff
13 27 6 ffffff
14 27 6 ffffff
15 27 6 ffffff
0 28 6 ffffff
1 28 6 ffffff
2 28 6 ffffff
3 28 6 ffffff
4 28 6 ffffff
5 28 6 ffffff
6 28 6 ffffff
7 28 6 ffffff
8 28 6 ffffff
9 28 6 ffffff
10 28 6 ffffff
11 28 6 ffffff
12 28 6 ffffff
13 28 6 ffffff
14 28 6 ffffff
15 28 6 ffffff
0 29 6 ffffff
1 29 6 ffffff
2 29 6 ffffff
3 29 6 ffffff
4 29 6 ffffff
5 29 6 ffffff
6 29 6 ffffff
7 29 6 ffffff
8 29 6 ffffff
9 29 6 ffffff
10 29 6 ffffff
11 29 6 ffffff
12 29 6 ffffff
13 29 6 ffffff
14 29 6 ffffff
15 29 6 ffffff
0 30 6 ffffff
1 30 6 ffffff
2 30 6 ffffff
3 30 6 ffffff
4 30 6 ffffff
5 30 6 ffffff
6 30 6 ffffff
7 30 6 ffffff
8 30 6 ffffff
9 30 6 ffffff
10 30 6 ffffff
11 30 6 ffffff
12 30 6 ffffff
13 30 6 ffffff
14 30 6 ffffff
15 30 6 ffffff
0 31 6 ffffff
1 31 6 ffffff
2 31 6 ffffff
3 31 6 ffffff
4 31 6 ffffff
5 31 6 ffffff
6 31 6 ffffff
7 31 6 ffffff
8 31 6 ffffff
9 31 6 ffffff
10 31 6 ffffff
11 31 6 ffffff
12 31 6 ffffff
13 31 6 ffffff
14 31 6 ffffff
15 31 6 ffffff
0 16 7 ffffff
1 16 7 ffffff
0 17 7 ffffff
1 17 7 ffffff
0 18 7 ffffff
1 18 7 ffffff
0 19 7 ffffff
1 19 7 ffffff
0 20 7 ffffff
1 20 7 ffffff
0 21 7 ffffff
1 21 7 ffffff
0 22 7 ffffff
1 22 7 ffffff
0 23 7 ffffff
1 23 7 ffffff
0 24 7 ffffff
1 24 7 ffffff
0 25 7 ffffff
1 25 7 ffffff
0 26 7 ffffff
1 26 7 ffffff
0 27 7 ffffff
1 27 7 ffffff
0 28 7 ffffff
1 28 7 ffffff
0 29 7 ffffff
1 29 7 ffffff
0 30 7 ffffff
1 30 7 ffffff
0 31 7 ffffff
1 31 7 ffffff
0 16 8 ffffff
1 16 8 ffffff
0 17 8 ffffff
1 17 8 ffffff
0 18 8 ffffff
1 18 8 ffffff
0 19 8 ffffff
1 19 8 ffffff
0 20 8 ffffff
1 20 8 ffffff
0 21 8 ffffff
1 21 8 ffffff
0 22 8 ffffff
1 22 8 ffffff
0 23 8 ffffff
1 23 8 ffffff
0 24 8 ffffff
1 24 8 ffffff
0 25 8 ffffff
1 25 8 ffffff
0 26 8 ffffff
1 26 8 ffffff
0 27 8 ffffff
1 27 8 ffffff
0 28 8 ffffff
1 28 8 ffffff
0 29 8 ffffff
1 29 8 ffffff
0 30 8 ffffff
1 30 8 ffffff
0 31 8 ffffff
1 31 8 ffffff
0 16 9 ffffff
1 16 9 ffffff
0 17 9 ffffff
1 17 9 ffffff
0 18 9 ffffff
1 18 9 ffffff
0 19 9 ffffff
1 19 9 ffffff
0 20 9 ffffff
1 20 9 ffffff
0 21 9 ffffff
1 21 9 ffffff
0 22 9 ffffff
1 22 9 ffffff
0 23 9 ffffff
1 23 9 ffffff
0 24 9 ffffff
1 24 9 ffffff
0 25 9 ffffff
1 25 9 ffffff
0 26 9 ffffff
1 26 9 ffffff
0 27 9 ffffff
1 27 9 ffffff
0 28 9 ffffff
1 28 9 ffffff
0 29 9 ffffff
1 29 9 ffffff
0 30 9 ffffff
1 30 9 ffffff
0 31 9 ffffff
1 31 9 ffffff
0 16 10 ffffff
1 16 10 ffffff
0 17 10 ffffff
1 17 10 ffffff
0 18 10 ffffff
1 18 10 ffffff
0 19 10 ffffff
1 19 10 ffffff
0 20 10 ffffff
1 20 10 ffffff
0 21 10 ffffff
1 21 10 ffffff
0 22 10 ffffff
1 22 10 ffffff
0 23 10 ffffff
1 23 10 ffffff
0 24 10 ffffff
1 24 10 ffffff
0 25 10 ffffff
1 25 10 ffffff
0 26 10 ffffff
1 26 10 ffffff
0 27 10 ffffff
1 27 10 ffffff
0 28 10 ffffff
1 28 10 ffffff
0 29 10 ffffff
1 29 10 ffffff
0 30 10 ffffff
1 30 10 ffffff
0 31 10 ffffff
1 31 10 ffffff
0 16 11 ffffff
1 16 11 ffffff
0 17 11 ffffff
1 17 11 ffffff
0 18 11 ffffff
1 18 11 ffffff
0 19 11 ffffff
1 19 11 ffffff
0 20 11 ffffff
1 20 11 ffffff
0 21 11 ffffff
1 21 11 ffffff
0 22 11 ffffff
1 22 11 ffffff
0 23 11 ffffff
1 23 11 ffffff
0 24 11 ffffff
1 24 11 ffffff
0 25 11 ffffff
1 25 11 ffffff
0 26 11 ffffff
1 26 11 ffffff
0 27 11 ffffff
1 27 11 ffffff
0 28 11 ffffff
1 28 11 ffffff
0 29 11 ffffff
1 29 11 ffffff
0 30 11 ffffff
1 30 11 ffffff
0 31 11 ffffff
1 31 11 ffffff
0 16 12 ffffff
1 16 12 ffffff
0 17 12 ffffff
1 17 12 ffffff
0 18 12 ffffff
1 18 12 ffffff
0 19 12 ffffff
1 19 12 ffffff
0 20 12 ffffff
1 20 12 ffffff
0 21 12 ffffff
1 21 12 ffffff
0 22 12 ffffff
1 22 12 ffffff
0 23 12 ffffff
1 23 12 ffffff
0 24 12 ffffff
1 24 12 ffffff
0 25 12 ffffff
1 25 12 ffffff
0 26 12 ffffff
1 26 12 ffffff
0 27 12 ffffff
1 27 12 ffffff
0 28 12 ffffff
1 28 12 ffffff
0 29 12 ffffff
1 29 12 ffffff
0 30 12 ffffff
1 30 12 ffffff
0 31 12 ffffff
1 31 12 ffffff
0 16 13 ffffff
1 16 13 ffffff
0 17 13 ffffff
1 17 13 ffffff
0 18 13 ffffff
1 18 13 ffffff
0 19 13 ffffff
1 19 13 ffffff
0 20 13 ffffff
1 20 13 ffffff
0 21 13 ffffff
1 21 13 ffffff
0 22 13 ffffff
1 22 13 ffffff
0 23 13 ffffff
1 23 13 ffffff
0 24 13 ffffff
1 24 13 ffffff
0 25 13 ffffff
1 25 13 ffffff
0 26 13 ffffff
1 26 13 ffffff
0 27 13 ffffff
1 27 13 ffffff
0 28 13 ffffff
1 28 13 ffffff
0 29 13 ffffff
1 29 13 ffffff
0 30 13 ffffff
1 30 13 ffffff
0 31 13 ffffff
1 31 13 ffffff
0 16 14 ffffff
1 16 14 ffffff
0 17 14 ffffff
1 17 14 ffffff
0 18 14 ffffff
1 18 14 ffffff
0 19 14 ffffff
1 19 14 ffffff
0 20 14 ffffff
1 20 14 ffffff
0 21 14 ffffff
1 21 14 ffffff
0 22 14 ffffff
1 22 14 ffffff
0 23 14 ffffff
1 23 14 ffffff
0 24 14 ffffff
1 24 14 ffffff
0 25 14 ffffff
1 25 14 ffffff
0 26 14 ffffff
1 26 14 ffffff
0 27 14 ffffff
1 27 14 ffffff
0 28 14 ffffff
1 28 14 ffffff
0 29 14 ffffff
1 29 14 ffffff
0 30 14 ffffff
1 30 14 ffffff
0 31 14 ffffff
1 31 14 ffffff
0 16 15 ffffff
1 16 15 ffffff
0 17 15 ffffff
1 17 15 ffffff
0 18 15 ffffff
1 18 15 ffffff
0 19 15 ffffff
1 19 15 ffffff
0 20 15 ffffff
1 20 15 ffffff
0 21 15 ffffff
1 21 15 ffffff
0 22 15 ffffff
1 22 15 ffffff
0 23 15 ffffff
1 23 15 ffffff
0 24 15 ffffff
1 24 15 ffffff
0 25 15 ffffff
1 25 15 ffffff
0 26 15 ffffff
1 26 15 ffffff
0 27 15 ffffff
1 27 15 ffffff
0 28 15 ffffff
1 28 15 ffffff
0 29 15 ffffff
1 29 15 ffffff
0 30 15 ffffff
1 30 15 ffffff
0 31 15 ffffff
1 31 15 ffffff
16 16 0 ffffff
17 16 0 ffffff
18 16 0 ffffff
19 16 0 ffffff
20 16 0 ffffff
21 16 0 ffffff
22 16 0 ffffff
23 16 0 ffffff
24 16 0 ffffff
25 16 0 ffffff
26 16 0 ffffff
27 16 0 ffffff
28 16 0 ffffff
29 16 0 ffffff
30 16 0 ffffff
31 16 0 ffffff
16 17 0 ffffff
17 17 0 ffffff
18 17 0 ffffff
19 17 0 ffffff
20 17 0 ffffff
21 17 0 ffffff
22 17 0 ffffff
23 17 0 ffffff
24 17 0 ffffff
25 17 0 ffffff
26 17 0 ffffff
27 17 0 ffffff
28 17 0 ffffff
29 17 0 ffffff
30 17 0 ffffff
31 17 0 ffffff
16 18 0 ffffff
17 18 0 ffffff
18 18 0 ffffff
19 18 0 ffffff
20 18 0 ffffff
21 18 0 ffffff
22 18 0 ffffff
23 18 0 ffffff
24 18 0 ffffff
25 18 0 ffffff
26 18 0 ffffff
27 18 0 ffffff
28 18 0 ffffff
29 18 0 ffffff
30 18 0 ffffff
31 18 0 ffffff
16 19 0 ffffff
17 19 0 ffffff
18 19 0 ffffff
19 19 0 ffffff
20 19 0 ffffff
21 19 0 ffffff
22 19 0 ffffff
23 19 0 ffffff
24 19 0 ffffff
25 19 0 ffffff
26 19 0 ffffff
27 19 0 ffffff
28 19 0 ffffff
29 19 0 ffffff
30 19 0 ffffff
31 19 0 ffffff
16 20 0 ffffff
17 20 0 ffffff
18 20 0 ffffff
19 20 0 ffffff
20 20 0 ffffff
21 20 0 ffffff
22 20 0 ffffff
23 20 0 ffffff
24 20 0 ffffff
25 20 0 ffffff
26 20 0 ffffff
27 20 0 ffffff
28 20 0 ffffff
29 20 0 ffffff
30 20 0 ffffff
31 20 0 ffffff
16 21 0 ffffff
17 21 0 ffffff
18 21 0 ffffff
19 21 0 ffffff
20 21 0 ffffff
21 21 0 ffffff
22 21 0 ffffff
23 21 0 ffffff
24 21 0 ffffff
25 21 0 ffffff
26 21 0 ffffff
27 21 0 ffffff
28 21 0 ffffff
29 21 0 ffffff
30 21 0 ffffff
31 21 0 ffffff
16 22 0 ffffff
17 22 0 ffffff
18 22 0 ffffff
19 22 0 ffffff
20 22 0 ffffff
21 22 0 ffffff
22 22 0 ffffff
23 22 0 ffffff
24 22 0 ffffff
25 22 0 ffffff
26 22 0 ffffff
27 22 0 ffffff
28 22 0 ffffff
29 22 0 ffffff
30 22 0 ffffff
31 22 0 ffffff
16 23 0 ffffff
17 23 0 ffffff
18 23 0 ffffff
19 23 0 ffffff
20 23 0 ffffff
21 23 0 ffffff
22 23 0 ffffff
23 23 0 ffffff
24 23 0 ffffff
25 23 0 ffffff
26 23 0 ffffff
27 23 0 ffffff
28 23 0 ffffff
29 23 0 ffffff
30 23 0 ffffff
31 23 0 ffffff
16 24 0 ffffff
17 24 0 ffffff
18 24 0 ffffff
19 24 0 ffffff
20 24 0 ffffff
21 24 0 ffffff
22 24 0 ffffff
23 24 0 ffffff
24 24 0 ffffff
25 24 0 ffffff
26 24 0 ffffff
27 24 0 ffffff
28 24 0 ffffff
29 24 0 ffffff
30 24 0 ffffff
31 24 0 ffffff
16 25 0 ffffff
17 25 0 ffffff
18 25 0 ffffff
19 25 0 ffffff
20 25 0 ffffff
21 25 0 ffffff
22 25 0 ffffff
23 25 0 ffffff
24 25 0 ffffff
25 25 0 ffffff
26 25 0 ffffff
27 25 0 ffffff
28 25 0 ffffff
29 25 0 ffffff
30 25 0 ffffff
31 25 0 ffffff
16 26 0 ffffff
17 26 0 ffffff
18 26 0 ffffff
19 26 0 ffffff
20 26 0 ffffff
21 26 0 ffffff
22 26 0 ffffff
23 26 0 ffffff
24 26 0 ffffff
25 26 0 ffffff
26 26 0 ffffff
27 26 0 ffffff
28 26 0 ffffff
29 26 0 ffffff
30 26 0 ffffff
31 26 0 ffffff
16 27 0 ffffff
17 27 0 ffffff
18 27 0 ffffff
19 27 0 ffffff
20 27 0 ffffff
21 27 0 ffffff
22 27 0 ffffff
23 27 0 ffffff
24 27 0 ffffff
25 27 0 ffffff
26 27 0 ffffff
27 27 0 ffffff
28 27 0 ffffff
29 27 0 ffffff
30 27 0 ffffff
31 27 0 ffffff
16 28 0 ffffff
17 28 0 ffffff
18 28 0 ffffff
19 28 0 ffffff
20 28 0 ffffff
21 28 0 ffffff
22 28 0 ffffff
23 28 0 ffffff
24 28 0 ffffff
25 28 0 ffffff
26 28 0 ffffff
27 28 0 ffffff
28 28 0 ffffff
29 28 0 ffffff
30 28 0 ffffff
31 28 0 ffffff
16 29 0 ffffff
17 29 0 ffffff
18 29 0 ffffff
19 29 0 ffffff
20 29 0 ffffff
21 29 0 ffffff
22 29 0 ffffff
23 29 0 ffffff
24 29 0 ffffff
25 29 0 ffffff
26 29 0 ffffff
27 29 0 ffffff
28 29 0 ffffff
29 29 0 ffffff
30 29 0 ffffff
31 29 0 ffffff
16 30 0 ffffff
17 30 0 ffffff
18 30 0 ffffff
19 30 0 ffffff
20 30 0 ffffff
21 30 0 ffffff
22 30 0 ffffff
23 30 0 ffffff
24 30 0 ffffff
25 30 0 ffffff
26 30 0 ffffff
27 30 0 ffffff
28 30 0 ffffff
29 30 0 ffffff
30 30 0 ffffff
31 30 0 ffffff
16 31 0 ffffff
17 31 0 ffffff
18 31 0 ffffff
19 31 0 ffffff
20 31 0 ffffff
21 31 0 ffffff
22 31 0 ffffff
23 31 0 ffffff
24 31 0 ffffff
25 31 0 ffffff
26 31 0 ffffff
27 31 0 ffffff
28 31 0 ffffff
29 31 0 ffffff
30 31 0 ffffff
31 31 0 ffffff
16 16 1 ffffff
17 16 1 ffffff
18 16 1 ffffff
19 16 1 ffffff
20 16 1 ffffff
21 16 1 ffffff
22 16 1 ffffff
23 16 1 ffffff
24 16 1 ffffff
25 16 1 ffffff
26 16 1 ffffff
27 16 1 ffffff
28 16 1 ffffff
29 16 1 ffffff
30 16 1 ffffff
31 16 1 ffffff
16 17 1 ffffff
17 17 1 ffffff
18 17 1 ffffff
19 17 1 ffffff
20 17 1 ffffff
21 17 1 ffffff
22 17 1 ffffff
23 17 1 ffffff
24 17 1 ffffff
25 17 1 ffffff
26 17 1 ffffff
27 17 1 ffffff
28 17 1 ffffff
29 17 1 ffffff
30 17 1 ffffff
31 17 1 ffffff
16 18 1 ffffff
17 18 1 ffffff
18 18 1 ffffff
19 18 1 ffffff
20 18 1 ffffff
21 18 1 ffffff
22 18 1 ffffff
23 18 1 ffffff
24 18 1 ffffff
25 18 1 ffffff
26 18 1 ffffff
27 18 1 ffffff
28 18 1 ffffff
29 18 1 ffffff
30 18 1 ffffff
31 18 1 ffffff
16 19 1 ffffff
17 19 1 ffffff
18 19 1 ffffff
19 19 1 ffffff
20 19 1 ffffff
21 19 1 ffffff
22 19 1 ffffff
23 19 1 ffffff
24 19 1 ffffff
25 19 1 ffffff
26 19 1 ffffff
27 19 1 ffffff
28 19 1 ffffff
29 19 1 ffffff
30 19 1 ffffff
31 19 1 ffffff
16 20 1 ffffff
17 20 1 ffffff
18 20 1 ffffff
19 20 1 ffffff
20 20 1 ffffff
21 20 1 ffffff
22 20 1 ffffff
23 20 1 ffffff
24 20 1 ffffff
25 20 1 ffffff
26 20 1 ffffff
27 20 1 ffffff
28 20 1 ffffff
29 20 1 ffffff
30 20 1 ffffff
31 20 1 ffffff
16 21 1 ffffff
17 21 1 ffffff
18 21 1 ffffff
19 21 1 ffffff
20 21 1 ffffff
21 21 1 ffffff
22 21 1 ffffff
23 21 1 ffffff
24 21 1 ffffff
25 21 1 ffffff
26 21 1 ffffff
27 21 1 ffffff
28 21 1 ffffff
29 21 1 ffffff
30 21 1 ffffff
31 21 1 ffffff
16 22 1 ffffff
17 22 1 ffffff
18 22 1 ffffff
19 22 1 ffffff
20 22 1 ffffff
21 22 1 ffffff
22 22 1 ffffff
23 22 1 ffffff
24 22 1 ffffff
25 22 1 ffffff
26 22 1 ffffff
27 22 1 ffffff
28 22 1 ffffff
29 22 1 ffffff
30 22 1 ffffff
31 22 1 ffffff
16 23 1 ffffff
17 23 1 ffffff
18 23 1 ffffff
19 23 1 ffffff
20 23 1 ffffff
21 23 1 ffffff
22 23 1 ffffff
23 23 1 ffffff
24 23 1 ffffff
25 23 1 ffffff
26 23 1 ffffff
27 23 1 ffffff
28 23 1 ffffff
29 23 1 ffffff
30 23 1 ffffff
31 23 1 ffffff
16 24 1 ffffff
17 24 1 ffffff
18 24 1 ffffff
19 24 1 ffffff
20 24 1 ffffff
21 24 1 ffffff
22 24 1 ffffff
23 24 1 ffffff
24 24 1 ffffff
25 24 1 ffffff
26 24 1 ffffff
27 24 1 ffffff
28 24 1 ffffff
29 24 1 ffffff
30 24 1 ffffff
31 24 1 ffffff
16 25 1 ffffff
17 25 1 ffffff
18 25 1 ffffff
19 25 1 ffffff
20 25 1 ffffff
21 25 1 ffffff
22 25 1 ffffff
23 25 1 ffffff
24 25 1 ffffff
25 25 1 ffffff
26 25 1 ffffff
27 25 1 ffffff
28 25 1 ffffff
29 25 1 ffffff
30 25 1 ffffff
31 25 1 ffffff
16 26 1 ffffff
17 26 1 ffffff
18 26 1 ffffff
19 26 1 ffffff
20 26 1 ffffff
21 26 1 ffffff
22 26 1 ffffff
23 26 1 ffffff
24 26 1 ffffff
25 26 1 ffffff
26 26 1 ffffff
27 26 1 ffffff
28 26 1 ffffff
29 26 1 ffffff
30 26 1 ffffff
31 26 1 ffffff
16 27 1 ffffff
17 27 1 ffffff
18 27 1 ffffff
19 27 1 ffffff
20 27 1 ffffff
21 27 1 ffffff
22 27 1 ffffff
23 27 1 ffffff
24 27 1 ffffff
25 27 1 ffffff
26 27 1 ffffff
27 27 1 ffffff
28 27 1 ffffff
29 27 1 ffffff
30 27 1 ffffff
31 27 1 ffffff
16 28 1 ffffff
17 28 1 ffffff
18 28 1 ffffff
19 28 1 ffffff
20 28 1 ffffff
21 28 1 ffffff
22 28 1 ffffff
23 28 1 ffffff
24 28 1 ffffff
25 28 1 ffffff
26 28 1 ffffff
27 28 1 ffffff
28 28 1 ffffff
29 28 1 ffffff
30 28 1 ffffff
31 28 1 ffffff
16 29 1 ffffff
17 29 1 ffffff
18 29 1 ffffff
19 29 1 ffffff
20 29 1 ffffff
21 29 1 ffffff
22 29 1 ffffff
23 29 1 ffffff
24 29 1 ffffff
25 29 1 ffffff
26 29 1 ffffff
27 29 1 ffffff
28 29 1 ffffff
29 29 1 ffffff
30 29 1 ffffff
31 29 1 ffffff
16 30 1 ffffff
17 30 1 ffffff
18 30 1 ffffff
19 30 1 ffffff
20 30 1 ffffff
21 30 1 ffffff
22 30 1 ffffff
23 30 1 ffffff
24 30 1 ffffff
25 30 1 ffffff
26 30 1 ffffff
27 30 1 ffffff
28 30 1 ffffff
29 30 1 ffffff
30 30 1 ffffff
31 30 1 ffffff
16 31 1 ffffff
17 31 1 ffffff
18 31 1 ffffff
19 31 1 ffffff
20 31 1 ffffff
21 31 1 ffffff
22 31 1 ffffff
23 31 1 ffffff
24 31 1 ffffff
25 31 1 ffffff
26 31 1 ffffff
27 31 1 ffffff
28 31 1 ffffff
29 31 1 ffffff
30 31 1 ffffff
31 31 1 ffffff
16 16 2 ffffff
17 16 2 ffffff
18 16 2 ffffff
19 16 2 ffffff
